# Ancient Warfare Structure Template File
# auto-generated structure file. created on: 6/7/2013 at: 20:22:42
# Lines beginning with # denote comments

survival=false
validTargetblocks=1,2,3,12,13

underground=false
undergroundMinLevel=1
undergroundMaxLevel=247
undergroundMaxAirAbove=0
minSubmergedDepth=0
maxWaterDepth=0
maxLavaDepth=0

xSize=26
ySize=8
zSize=16

verticalOffset=1
xOffset=9
zOffset=0

maxOverhang=0
maxLeveling=0
levelingBuffer=0
maxVerticalClear=0
clearingBuffer=0
preserveWater=false
preserveLava=false
preservePlants=false
preserveBlocks=false

####BLOCK RULES####
rule:
number=0
order=0
conditional=0
percent=100
blocks=0-0
:endrule

rule:
number=2
order=0
conditional=0
percent=100
blocks=2-0
inventory=0
:endrule

rule:
number=3
order=0
conditional=0
percent=100
blocks=53-2
inventory=0
:endrule

rule:
number=4
order=0
conditional=0
percent=100
blocks=85-0
inventory=0
:endrule

rule:
number=5
order=0
conditional=0
percent=100
blocks=35-14
inventory=0
:endrule

rule:
number=6
order=0
conditional=0
percent=100
blocks=3-0
inventory=0
:endrule

rule:
number=7
order=0
conditional=0
percent=100
blocks=53-1
inventory=0
:endrule

rule:
number=8
order=0
conditional=0
percent=100
blocks=43-3
inventory=0
:endrule

rule:
number=9
order=0
conditional=0
percent=100
blocks=67-3
inventory=0
:endrule

rule:
number=10
order=0
conditional=0
percent=100
blocks=87-0
inventory=0
:endrule

rule:
number=11
order=0
conditional=0
percent=100
blocks=44-3
inventory=0
:endrule

rule:
number=12
order=0
conditional=0
percent=100
blocks=51-15
inventory=0
:endrule

rule:
number=13
order=0
conditional=0
percent=100
blocks=61-4
inventory=0
:endrule

rule:
number=14
order=0
conditional=0
percent=100
blocks=118-3
inventory=0
:endrule

rule:
number=15
order=0
conditional=0
percent=100
blocks=67-2
inventory=0
:endrule

rule:
number=17
order=1
conditional=0
percent=100
blocks=50-3
inventory=0
:endrule

rule:
number=16
order=1
conditional=0
percent=100
blocks=50-4
inventory=0
:endrule

rule:
number=19
order=0
conditional=0
percent=100
blocks=26-2
inventory=0
:endrule

rule:
number=18
order=0
conditional=0
percent=100
blocks=54-3
inventory=0
:endrule

rule:
number=21
order=1
conditional=0
percent=100
blocks=50-2
inventory=0
:endrule

rule:
number=20
order=1
conditional=0
percent=100
blocks=50-1
inventory=0
:endrule

rule:
number=22
order=0
conditional=0
percent=100
blocks=26-10
inventory=0
:endrule


####SWAP RULESS####

####VEHICLE RULES####

####NPC RULES####
####CIVIC RULES####

####GATE RULES####

####ENTITY RULES####

####RESOURCE LIST####
resources:
3-0,415
35-14,207
53-0,6
44-3,6
50-0,6
87-0,1
85-0,31
355-0,2
51-0,1
67-0,2
118-0,1
54-0,2
61-0,2
:endresources

####LAYERS####

layer:
6,6,6,6,6,6,6,2,6,6,6,6,6,6,6,2,2,2,2,2,2,2,2,2,2,2
6,2,2,2,2,2,6,2,6,2,2,2,2,2,6,2,2,2,2,2,2,2,2,2,2,2
6,2,2,2,2,2,6,2,6,2,2,2,2,2,6,2,2,2,2,2,2,2,2,2,2,2
6,2,2,2,2,2,6,2,6,2,2,2,2,2,6,2,2,2,2,2,2,2,2,2,2,2
6,2,2,2,2,2,6,2,6,2,2,2,2,2,6,2,2,2,2,2,2,2,2,2,2,2
6,2,2,2,2,2,6,2,6,2,2,2,2,2,6,2,2,2,2,2,2,2,2,2,2,2
2,2,2,2,2,2,2,2,2,2,2,2,2,2,2,2,2,6,6,6,6,6,6,6,6,6
2,2,2,2,2,2,2,2,2,2,2,2,2,2,2,2,2,6,2,2,2,2,2,2,2,6
2,2,2,2,2,2,2,2,2,2,2,2,2,2,2,2,2,6,2,2,2,2,2,2,2,6
2,2,2,2,2,2,2,2,2,2,2,2,2,2,2,2,2,2,2,2,2,2,2,2,2,6
2,2,2,2,2,2,2,2,2,2,2,2,2,2,2,2,2,2,2,2,2,2,2,2,2,6
2,2,2,2,2,2,2,2,2,2,2,2,2,2,2,2,2,2,2,2,2,2,2,2,6,6
2,2,2,10,2,2,2,2,2,2,2,2,2,2,2,2,2,6,2,2,2,2,2,2,6,6
2,2,2,2,2,2,2,2,2,2,2,2,2,2,2,2,2,6,2,2,2,2,2,2,2,6
2,2,2,2,2,2,2,2,2,2,2,2,2,2,2,2,2,6,6,6,6,6,6,6,6,6
2,2,2,2,2,2,2,2,2,2,2,2,2,2,2,2,2,2,2,2,2,2,2,2,2,2
:endlayer

layer:
5,5,5,5,5,5,5,0,5,5,5,5,5,5,5,0,0,0,0,0,0,0,0,0,0,0
5,0,0,4,0,0,5,0,5,0,0,4,0,0,5,0,0,0,0,0,0,0,0,0,0,0
5,0,0,22,0,0,5,0,5,0,0,22,0,0,5,0,0,0,0,0,0,0,0,0,0,0
5,0,0,19,0,0,5,0,5,0,0,19,0,0,5,0,0,0,0,0,0,0,0,0,0,0
5,0,0,0,0,0,5,0,5,0,0,0,0,0,5,0,0,0,0,0,0,0,0,0,0,0
5,0,0,4,0,0,5,0,5,0,0,4,0,0,5,0,0,0,0,0,0,0,0,0,0,0
0,0,0,0,0,0,0,0,0,0,0,0,0,0,0,0,0,5,5,5,5,5,5,5,5,5
0,0,0,0,0,0,0,0,0,0,0,0,0,0,0,0,0,5,0,0,0,0,0,0,0,5
0,0,0,0,0,0,0,0,0,0,0,0,0,0,0,0,0,5,0,0,0,0,0,18,18,5
0,0,0,0,0,0,0,0,0,0,0,0,0,0,0,0,0,4,0,0,0,0,0,0,0,5
0,0,0,0,0,0,0,0,0,0,0,0,0,0,0,0,0,0,0,0,0,0,0,0,4,5
7,0,0,8,0,0,0,0,0,0,0,0,0,0,0,0,0,4,0,0,0,0,0,0,13,5
7,0,11,12,11,0,0,0,0,0,0,0,0,0,0,0,0,5,0,0,0,0,0,0,13,5
7,0,0,8,0,0,0,0,0,0,0,0,0,0,0,0,0,5,0,0,0,0,0,0,0,5
0,0,0,0,0,0,0,0,0,0,0,0,0,0,0,0,0,5,5,5,5,5,5,5,5,5
0,0,3,3,3,0,0,0,0,4,0,0,0,0,0,0,0,0,0,0,0,0,0,0,0,0
:endlayer

layer:
0,5,5,5,5,5,0,0,0,5,5,5,5,5,0,0,0,0,0,0,0,0,0,0,0,0
0,5,0,4,0,5,0,0,0,5,0,4,0,5,0,0,0,0,0,0,0,0,0,0,0,0
0,5,0,0,0,5,0,0,0,5,0,0,0,5,0,0,0,0,0,0,0,0,0,0,0,0
0,5,20,0,21,5,0,0,0,5,20,0,21,5,0,0,0,0,0,0,0,0,0,0,0,0
0,5,0,0,0,5,0,0,0,5,0,0,0,5,0,0,0,0,0,0,0,0,0,0,0,0
0,5,0,4,0,5,0,0,0,5,0,4,0,5,0,0,0,0,0,0,0,0,0,0,0,0
0,0,0,0,0,0,0,0,0,0,0,0,0,0,0,0,0,0,0,0,0,0,0,0,0,0
0,0,0,0,0,0,0,0,0,0,0,0,0,0,0,0,0,5,5,5,5,5,5,5,5,5
0,0,0,0,0,0,0,0,0,0,0,0,0,0,0,0,0,5,0,0,0,0,0,0,0,5
0,0,0,0,0,0,0,0,0,0,0,0,0,0,0,0,0,4,0,0,0,0,0,0,0,5
0,0,0,0,0,0,0,0,0,0,0,0,0,0,0,0,0,0,0,0,0,0,0,0,4,5
0,0,0,15,0,0,0,0,0,0,0,0,0,0,0,0,0,4,0,0,0,0,0,0,0,5
0,0,0,14,0,0,0,0,0,0,0,0,0,0,0,0,0,5,0,0,0,0,0,0,0,5
0,0,0,9,0,0,0,0,0,0,0,0,0,0,0,0,0,5,5,5,5,5,5,5,5,5
0,0,0,0,0,0,0,0,0,0,0,0,0,0,0,0,0,0,0,0,0,0,0,0,0,0
0,0,0,0,0,0,0,0,0,4,0,0,0,0,0,0,0,0,0,0,0,0,0,0,0,0
:endlayer

layer:
0,0,5,5,5,0,0,0,0,0,5,5,5,0,0,0,0,0,0,0,0,0,0,0,0,0
0,0,5,4,5,0,0,0,0,0,5,4,5,0,0,0,0,0,0,0,0,0,0,0,0,0
0,0,5,0,5,0,0,0,0,0,5,0,5,0,0,0,0,0,0,0,0,0,0,0,0,0
0,0,5,0,5,0,0,0,0,0,5,0,5,0,0,0,0,0,0,0,0,0,0,0,0,0
0,0,5,0,5,0,0,0,0,0,5,0,5,0,0,0,0,0,0,0,0,0,0,0,0,0
0,0,5,4,5,0,0,0,0,0,5,4,5,0,0,0,0,0,0,0,0,0,0,0,0,0
0,0,0,0,0,0,0,0,0,0,0,0,0,0,0,0,0,0,0,0,0,0,0,0,0,0
0,0,0,0,0,0,0,0,0,0,0,0,0,0,0,0,0,0,0,0,0,0,0,0,0,0
0,0,0,0,0,0,0,0,0,0,0,0,0,0,0,0,0,5,5,5,5,5,5,5,5,5
0,0,0,0,0,0,0,0,0,0,0,0,0,0,0,0,0,4,0,0,0,17,0,0,0,5
0,0,0,0,0,0,0,0,0,0,0,0,0,0,0,0,0,4,0,0,0,0,0,0,4,5
0,0,0,0,0,0,0,0,0,0,0,0,0,0,0,0,0,4,0,0,0,16,0,0,0,5
0,0,0,0,0,0,0,0,0,0,0,0,0,0,0,0,0,5,5,5,5,5,5,5,5,5
0,0,0,0,0,0,0,0,0,0,0,0,0,0,0,0,0,0,0,0,0,0,0,0,0,0
0,0,0,0,0,0,0,0,0,0,0,0,0,0,0,0,0,0,0,0,0,0,0,0,0,0
0,0,0,0,0,0,0,0,0,4,0,0,0,0,0,0,0,0,0,0,0,0,0,0,0,0
:endlayer

layer:
0,0,0,5,0,0,0,0,0,0,0,5,0,0,0,0,0,0,0,0,0,0,0,0,0,0
0,0,0,5,0,0,0,0,0,0,0,5,0,0,0,0,0,0,0,0,0,0,0,0,0,0
0,0,0,5,0,0,0,0,0,0,0,5,0,0,0,0,0,0,0,0,0,0,0,0,0,0
0,0,0,5,0,0,0,0,0,0,0,5,0,0,0,0,0,0,0,0,0,0,0,0,0,0
0,0,0,5,0,0,0,0,0,0,0,5,0,0,0,0,0,0,0,0,0,0,0,0,0,0
0,0,0,5,0,0,0,0,0,0,0,5,0,0,0,0,0,0,0,0,0,0,0,0,0,0
0,0,0,0,0,0,0,0,0,0,0,0,0,0,0,0,0,0,0,0,0,0,0,0,0,0
0,0,0,0,0,0,0,0,0,0,0,0,0,0,0,0,0,0,0,0,0,0,0,0,0,0
0,0,0,0,0,0,0,0,0,0,0,0,0,0,0,0,0,0,0,0,0,0,0,0,0,0
0,0,0,0,0,0,0,0,0,0,0,0,0,0,0,0,0,5,5,5,5,5,5,5,5,5
0,0,0,0,0,0,0,0,0,0,0,0,0,0,0,0,0,4,0,0,0,0,0,0,4,5
0,0,0,0,0,0,0,0,0,0,0,0,0,0,0,0,0,5,5,5,5,5,5,5,5,5
0,0,0,0,0,0,0,0,0,0,0,0,0,0,0,0,0,0,0,0,0,0,0,0,0,0
0,0,0,0,0,0,0,0,0,0,0,0,0,0,0,0,0,0,0,0,0,0,0,0,0,0
0,0,0,0,0,0,0,0,0,0,0,0,0,0,0,0,0,0,0,0,0,0,0,0,0,0
0,0,0,0,0,0,0,0,0,4,0,0,0,0,0,0,0,0,0,0,0,0,0,0,0,0
:endlayer

layer:
0,0,0,0,0,0,0,0,0,0,0,0,0,0,0,0,0,0,0,0,0,0,0,0,0,0
0,0,0,0,0,0,0,0,0,0,0,0,0,0,0,0,0,0,0,0,0,0,0,0,0,0
0,0,0,0,0,0,0,0,0,0,0,0,0,0,0,0,0,0,0,0,0,0,0,0,0,0
0,0,0,0,0,0,0,0,0,0,0,0,0,0,0,0,0,0,0,0,0,0,0,0,0,0
0,0,0,0,0,0,0,0,0,0,0,0,0,0,0,0,0,0,0,0,0,0,0,0,0,0
0,0,0,0,0,0,0,0,0,0,0,0,0,0,0,0,0,0,0,0,0,0,0,0,0,0
0,0,0,0,0,0,0,0,0,0,0,0,0,0,0,0,0,0,0,0,0,0,0,0,0,0
0,0,0,0,0,0,0,0,0,0,0,0,0,0,0,0,0,0,0,0,0,0,0,0,0,0
0,0,0,0,0,0,0,0,0,0,0,0,0,0,0,0,0,0,0,0,0,0,0,0,0,0
0,0,0,0,0,0,0,0,0,0,0,0,0,0,0,0,0,0,0,0,0,0,0,0,0,0
0,0,0,0,0,0,0,0,0,0,0,0,0,0,0,0,0,5,5,5,5,5,5,5,5,5
0,0,0,0,0,0,0,0,0,0,0,0,0,0,0,0,0,0,0,0,0,0,0,0,0,0
0,0,0,0,0,0,0,0,0,0,0,0,0,0,0,0,0,0,0,0,0,0,0,0,0,0
0,0,0,0,0,0,0,0,0,0,0,0,0,0,0,0,0,0,0,0,0,0,0,0,0,0
0,0,0,0,0,0,0,0,0,0,0,0,0,0,0,0,0,0,0,0,0,0,0,0,0,0
0,0,0,0,0,0,0,0,0,4,0,0,0,0,0,0,0,0,0,0,0,0,0,0,0,0
:endlayer

layer:
0,0,0,0,0,0,0,0,0,0,0,0,0,0,0,0,0,0,0,0,0,0,0,0,0,0
0,0,0,0,0,0,0,0,0,0,0,0,0,0,0,0,0,0,0,0,0,0,0,0,0,0
0,0,0,0,0,0,0,0,0,0,0,0,0,0,0,0,0,0,0,0,0,0,0,0,0,0
0,0,0,0,0,0,0,0,0,0,0,0,0,0,0,0,0,0,0,0,0,0,0,0,0,0
0,0,0,0,0,0,0,0,0,0,0,0,0,0,0,0,0,0,0,0,0,0,0,0,0,0
0,0,0,0,0,0,0,0,0,0,0,0,0,0,0,0,0,0,0,0,0,0,0,0,0,0
0,0,0,0,0,0,0,0,0,0,0,0,0,0,0,0,0,0,0,0,0,0,0,0,0,0
0,0,0,0,0,0,0,0,0,0,0,0,0,0,0,0,0,0,0,0,0,0,0,0,0,0
0,0,0,0,0,0,0,0,0,0,0,0,0,0,0,0,0,0,0,0,0,0,0,0,0,0
0,0,0,0,0,0,0,0,0,0,0,0,0,0,0,0,0,0,0,0,0,0,0,0,0,0
0,0,0,0,0,0,0,0,0,0,0,0,0,0,0,0,0,0,0,0,0,0,0,0,0,0
0,0,0,0,0,0,0,0,0,0,0,0,0,0,0,0,0,0,0,0,0,0,0,0,0,0
0,0,0,0,0,0,0,0,0,0,0,0,0,0,0,0,0,0,0,0,0,0,0,0,0,0
0,0,0,0,0,0,0,0,0,0,0,0,0,0,0,0,0,0,0,0,0,0,0,0,0,0
0,0,0,0,0,0,0,0,0,0,0,0,0,0,0,0,0,0,0,0,0,0,0,0,0,0
0,0,0,0,0,0,0,0,0,4,0,0,0,0,0,0,0,0,0,0,0,0,0,0,0,0
:endlayer

layer:
0,0,0,0,0,0,0,0,0,0,0,0,0,0,0,0,0,0,0,0,0,0,0,0,0,0
0,0,0,0,0,0,0,0,0,0,0,0,0,0,0,0,0,0,0,0,0,0,0,0,0,0
0,0,0,0,0,0,0,0,0,0,0,0,0,0,0,0,0,0,0,0,0,0,0,0,0,0
0,0,0,0,0,0,0,0,0,0,0,0,0,0,0,0,0,0,0,0,0,0,0,0,0,0
0,0,0,0,0,0,0,0,0,0,0,0,0,0,0,0,0,0,0,0,0,0,0,0,0,0
0,0,0,0,0,0,0,0,0,0,0,0,0,0,0,0,0,0,0,0,0,0,0,0,0,0
0,0,0,0,0,0,0,0,0,0,0,0,0,0,0,0,0,0,0,0,0,0,0,0,0,0
0,0,0,0,0,0,0,0,0,0,0,0,0,0,0,0,0,0,0,0,0,0,0,0,0,0
0,0,0,0,0,0,0,0,0,0,0,0,0,0,0,0,0,0,0,0,0,0,0,0,0,0
0,0,0,0,0,0,0,0,0,0,0,0,0,0,0,0,0,0,0,0,0,0,0,0,0,0
0,0,0,0,0,0,0,0,0,0,0,0,0,0,0,0,0,0,0,0,0,0,0,0,0,0
0,0,0,0,0,0,0,0,0,0,0,0,0,0,0,0,0,0,0,0,0,0,0,0,0,0
0,0,0,0,0,0,0,0,0,0,0,0,0,0,0,0,0,0,0,0,0,0,0,0,0,0
0,0,0,0,0,0,0,0,0,0,0,0,0,0,0,0,0,0,0,0,0,0,0,0,0,0
0,0,0,0,0,0,0,0,0,0,0,0,0,0,0,0,0,0,0,0,0,0,0,0,0,0
0,0,0,0,0,0,0,0,0,4,5,5,0,0,0,0,0,0,0,0,0,0,0,0,0,0
:endlayer


####INVENTORIES####


