# Ancient Warfare Structure Template File
# auto-generated structure file. created on: 7/19/2013 at: 19:41:16
# Lines beginning with # denote comments
# Original design by Me2005, slightly modified to accomodate NPC archers + add chests/gates

survival=false
validTargetblocks=1,2,3,12,13

underground=false
undergroundMinLevel=1
undergroundMaxLevel=239
undergroundMaxAirAbove=0
minSubmergedDepth=0
maxWaterDepth=0
maxLavaDepth=0
fillType=4

xSize=27
ySize=16
zSize=27

verticalOffset=1
xOffset=13
zOffset=0

maxOverhang=0
maxLeveling=0
levelingBuffer=0
maxVerticalClear=1
clearingBuffer=0
preserveWater=false
preserveLava=false
preservePlants=false
preserveBlocks=false

####BLOCK RULES####
rule:
number=0
order=0
conditional=0
percent=100
blocks=0-0
:endrule

rule:
number=2
order=0
conditional=0
percent=100
blocks=2-0
inventory=0
:endrule

rule:
number=3
order=0
conditional=0
percent=100
blocks=109-6
inventory=0
:endrule

rule:
number=4
order=0
conditional=0
percent=100
blocks=44-13
inventory=0
:endrule

rule:
number=5
order=0
conditional=0
percent=100
blocks=98-0
inventory=0
:endrule

rule:
number=6
order=0
conditional=0
percent=100
blocks=44-5
inventory=0
:endrule

rule:
number=7
order=0
conditional=0
percent=100
blocks=109-7
inventory=0
:endrule

rule:
number=8
order=0
conditional=0
percent=100
blocks=109-5
inventory=0
:endrule

rule:
number=9
order=0
conditional=0
percent=100
blocks=43-0
inventory=0
:endrule

rule:
number=10
order=0
conditional=0
percent=100
blocks=109-4
inventory=0
:endrule

rule:
number=11
order=0
conditional=0
percent=100
blocks=126-8
inventory=0
:endrule

rule:
number=12
order=0
conditional=0
percent=100
blocks=125-0
inventory=0
:endrule

rule:
number=13
order=0
conditional=0
percent=100
blocks=77-4
inventory=0
:endrule

rule:
number=14
order=0
conditional=0
percent=100
blocks=126-0
inventory=0
:endrule

rule:
number=15
order=0
conditional=0
percent=100
blocks=43-5
inventory=0
:endrule

rule:
number=17
order=1
conditional=0
percent=100
blocks=71-8
inventory=0
:endrule

rule:
number=16
order=1
conditional=0
percent=100
blocks=71-1
inventory=0
:endrule

rule:
number=19
order=1
conditional=0
percent=100
blocks=50-5
inventory=0
:endrule

rule:
number=18
order=1
conditional=0
percent=100
blocks=50-3
inventory=0
:endrule

rule:
number=21
order=0
conditional=0
percent=100
blocks=77-3
inventory=0
:endrule

rule:
number=20
order=0
conditional=0
percent=100
blocks=1-0
inventory=0
:endrule

rule:
number=23
order=0
conditional=0
percent=100
blocks=53-7
inventory=0
:endrule

rule:
number=22
order=1
conditional=0
percent=100
blocks=50-4
inventory=0
:endrule

rule:
number=25
order=0
conditional=0
percent=100
blocks=53-1
inventory=0
:endrule

rule:
number=24
order=0
conditional=0
percent=100
blocks=53-0
inventory=0
:endrule

rule:
number=27
order=1
conditional=0
percent=100
blocks=50-2
inventory=0
:endrule

rule:
number=26
order=0
conditional=0
percent=100
blocks=17-8
inventory=0
:endrule

rule:
number=29
order=0
conditional=0
percent=100
blocks=53-5
inventory=0
:endrule

rule:
number=28
order=1
conditional=0
percent=100
blocks=50-1
inventory=0
:endrule

rule:
number=31
order=0
conditional=0
percent=100
blocks=53-6
inventory=0
:endrule

rule:
number=30
order=0
conditional=0
percent=100
blocks=53-4
inventory=0
:endrule

rule:
number=34
order=0
conditional=0
percent=100
blocks=109-0
inventory=0
:endrule

rule:
number=35
order=0
conditional=0
percent=100
blocks=109-1
inventory=0
:endrule

rule:
number=32
order=0
conditional=0
percent=100
blocks=44-8
inventory=0
:endrule

rule:
number=33
order=0
conditional=0
percent=100
blocks=53-3
inventory=0
:endrule

rule:
number=38
order=0
conditional=0
percent=100
blocks=54-4
inventory=0
lootlevel=1
:endrule

rule:
number=39
order=0
conditional=0
percent=100
blocks=54-5
inventory=0
lootlevel=1
:endrule

rule:
number=36
order=0
conditional=0
percent=100
blocks=17-4
inventory=0
:endrule

rule:
number=37
order=0
conditional=0
percent=100
blocks=85-0
inventory=0
:endrule

rule:
number=42
order=0
conditional=0
percent=100
blocks=109-2
inventory=0
:endrule

rule:
number=40
order=1
conditional=0
percent=100
blocks=69-2
inventory=0
:endrule

rule:
number=41
order=0
conditional=0
percent=100
blocks=77-2
inventory=0
:endrule


####SWAP RULESS####

####VEHICLE RULES####

####NPC RULES####

npc:
type=7
rank=1
team=17
bx=13
by=1
bz=10
ox=0.24662018
oy=0.0
oz=0.45270061
rotation=25.501709
pitch=0.0
:endnpc


npc:
type=3
rank=0
team=17
bx=20
by=6
bz=7
ox=0.17928934
oy=0.0
oz=0.048939705
rotation=-0.150177
pitch=0.0
:endnpc


npc:
type=3
rank=0
team=17
bx=23
by=11
bz=7
ox=0.5
oy=0.0
oz=0.5
rotation=82.349594
pitch=0.0
:endnpc


npc:
type=3
rank=0
team=17
bx=19
by=11
bz=3
ox=0.5
oy=0.0
oz=0.5
rotation=30.450623
pitch=0.0
:endnpc


npc:
type=3
rank=0
team=17
bx=6
by=6
bz=7
ox=0.6831913
oy=0.0
oz=0.37710524
rotation=235.65024
pitch=0.0
:endnpc


npc:
type=3
rank=0
team=17
bx=3
by=11
bz=7
ox=0.5
oy=0.0
oz=0.5
rotation=-80.84961
pitch=0.0
:endnpc


npc:
type=3
rank=0
team=17
bx=7
by=11
bz=3
ox=0.5
oy=0.0
oz=0.5
rotation=-22.199219
pitch=0.0
:endnpc


npc:
type=2
rank=0
team=17
bx=16
by=1
bz=19
ox=0.75551414
oy=0.0
oz=0.7883358
rotation=146.5521
pitch=0.0
:endnpc


npc:
type=2
rank=0
team=17
bx=11
by=1
bz=19
ox=0.5
oy=0.0
oz=0.5
rotation=205.20215
pitch=0.0
:endnpc


npc:
type=2
rank=0
team=17
bx=17
by=1
bz=25
ox=0.5
oy=0.0
oz=0.5
rotation=69.150696
pitch=0.0
:endnpc


npc:
type=2
rank=0
team=17
bx=10
by=1
bz=25
ox=0.5
oy=0.0
oz=0.5
rotation=-63.59973
pitch=0.0
:endnpc


npc:
type=3
rank=0
team=17
bx=20
by=6
bz=19
ox=0.5
oy=0.0
oz=0.5
rotation=175.04968
pitch=0.0
:endnpc


npc:
type=3
rank=0
team=17
bx=9
by=11
bz=23
ox=0.5
oy=0.0
oz=0.5
rotation=186.89957
pitch=0.0
:endnpc


npc:
type=3
rank=0
team=17
bx=17
by=11
bz=23
ox=0.5
oy=0.0
oz=0.5
rotation=173.84955
pitch=0.0
:endnpc


npc:
type=3
rank=0
team=17
bx=23
by=11
bz=19
ox=0.5
oy=0.0
oz=0.5
rotation=85.94966
pitch=0.0
:endnpc


npc:
type=3
rank=0
team=17
bx=6
by=6
bz=20
ox=0.5
oy=0.0
oz=0.5
rotation=181.35052
pitch=0.0
:endnpc


npc:
type=3
rank=0
team=17
bx=3
by=11
bz=19
ox=0.5
oy=0.0
oz=0.5
rotation=254.7002
pitch=0.0
:endnpc

####CIVIC RULES####

####GATE RULES####

gate:
pos1=15,1,22
pos2=11,4,22
team=17
type=1
facing=0
:endgate


####ENTITY RULES####

####RESOURCE LIST####
resources:
3-0,224
109-0,178
44-5,344
98-0,2032
44-0,907
126-0,426
50-0,141
1-0,166
17-0,58
54-0,2
85-0,26
53-0,56
77-0,3
330-0,1
69-0,1
:endresources

####LAYERS####

layer:
2,2,2,2,2,2,2,2,2,2,2,2,2,2,2,2,2,2,2,2,2,2,2,2,2,2,2
2,5,5,5,5,5,2,2,2,2,2,2,2,2,2,2,2,2,2,2,2,5,5,5,5,5,2
2,5,5,5,5,5,2,2,2,2,2,2,2,2,2,2,2,2,2,2,2,5,5,5,5,5,2
2,5,5,5,5,5,5,5,5,5,5,5,5,5,5,5,5,5,5,5,5,5,5,5,5,5,2
2,5,5,5,5,5,20,20,20,20,20,20,20,20,20,20,20,20,20,20,20,5,5,5,5,5,2
2,5,5,5,5,5,9,9,9,20,20,9,9,9,9,9,20,20,9,9,9,5,5,5,5,5,2
2,2,2,5,20,9,9,9,9,20,20,9,9,9,9,9,20,20,9,9,9,9,20,5,2,2,2
2,2,2,5,20,9,9,9,9,20,20,9,9,9,9,9,20,20,9,9,9,9,20,5,2,2,2
2,2,2,5,20,9,9,9,9,20,20,9,9,9,9,9,20,20,9,9,9,9,20,5,2,2,2
2,2,2,5,20,20,20,20,20,5,5,20,20,20,20,20,5,5,20,20,20,20,20,5,2,2,2
2,2,2,5,20,20,20,20,20,5,5,20,20,20,20,20,5,5,20,20,20,20,20,5,2,2,2
2,2,2,5,20,9,9,9,9,20,20,9,9,9,9,9,20,20,9,9,9,9,20,5,2,2,2
2,2,2,5,20,9,9,9,9,20,20,9,9,9,9,9,20,20,9,9,9,9,20,5,2,2,2
2,2,2,5,20,9,9,9,9,20,20,9,9,9,9,9,20,20,9,9,9,9,20,5,2,2,2
2,2,2,5,20,9,9,9,9,20,20,9,9,9,9,9,20,20,9,9,9,9,20,5,2,2,2
2,2,2,5,20,9,9,9,9,20,20,9,9,9,9,9,20,20,9,9,9,9,20,5,2,2,2
2,2,2,5,20,20,20,20,20,5,5,20,20,20,20,20,5,5,20,20,20,20,20,5,2,2,2
2,2,2,5,20,20,20,20,20,5,5,20,20,20,20,20,5,5,20,20,20,20,20,5,2,2,2
2,2,2,5,20,9,9,9,9,20,20,9,9,9,9,9,20,20,9,9,9,9,20,5,2,2,2
2,2,2,5,20,9,9,9,9,20,20,9,9,9,9,9,20,20,9,9,9,9,20,5,2,2,2
2,2,2,5,20,9,9,9,9,20,20,9,9,9,9,9,20,20,9,9,9,9,20,5,2,2,2
2,5,5,5,5,5,9,9,9,5,5,20,20,20,20,20,5,5,9,9,9,5,5,5,5,5,2
2,5,5,5,5,5,20,20,20,5,5,20,20,20,20,20,5,5,20,20,20,5,5,5,5,5,2
2,5,5,5,5,5,5,5,5,5,5,20,20,20,20,20,5,5,5,5,5,5,5,5,5,5,2
2,5,5,5,5,5,2,2,2,2,2,2,2,2,2,2,2,2,2,2,2,5,5,5,5,5,2
2,5,5,5,5,5,2,2,2,2,2,2,2,2,2,2,2,2,2,2,2,5,5,5,5,5,2
2,2,2,2,2,2,2,2,2,2,2,2,2,2,2,2,2,2,2,2,2,2,2,2,2,2,2
:endlayer

layer:
0,0,0,0,0,0,0,0,0,0,0,0,0,0,0,0,0,0,0,0,0,0,0,0,0,0,0
0,5,5,5,5,5,0,0,0,0,0,0,0,0,0,0,0,0,0,0,0,5,5,5,5,5,0
0,5,0,0,0,5,0,0,0,0,0,0,0,0,0,0,0,0,0,0,0,5,0,0,0,5,0
0,5,0,0,11,5,5,5,5,5,5,5,5,16,5,5,5,5,5,5,5,5,11,0,0,5,0
0,5,0,14,12,14,0,0,0,0,0,0,0,0,0,0,0,0,0,0,0,14,12,14,0,5,0
0,5,5,5,14,5,0,0,0,0,0,0,0,0,0,0,0,0,0,0,0,5,14,5,5,5,0
0,0,0,5,0,0,0,0,0,0,0,0,0,0,0,0,0,0,0,0,0,0,0,5,0,0,0
0,0,0,5,0,0,0,0,0,0,0,0,0,0,0,0,0,0,0,0,0,0,0,5,0,0,0
0,0,0,5,0,0,0,0,0,0,0,0,31,31,31,0,0,0,0,0,0,0,0,5,0,0,0
0,0,0,5,14,0,0,0,0,5,5,0,33,33,33,0,5,5,0,0,0,0,0,5,0,0,0
0,0,0,5,0,0,0,0,0,5,5,0,0,0,0,0,5,5,0,0,0,0,0,5,0,0,0
0,0,0,5,0,0,0,0,0,0,0,0,0,0,0,0,0,0,0,0,0,0,0,5,0,0,0
0,0,0,5,0,0,0,0,0,0,0,0,0,0,0,0,0,0,0,0,0,0,0,5,0,0,0
0,0,0,5,0,0,0,0,0,0,0,0,0,0,0,0,0,0,0,0,0,0,0,5,0,0,0
0,0,0,5,0,0,0,0,0,0,0,0,0,0,0,0,0,0,0,0,0,0,0,5,0,0,0
0,0,0,5,0,0,0,0,0,0,0,0,0,0,0,0,0,0,0,0,0,0,0,5,0,0,0
0,0,0,5,0,0,0,0,0,5,5,0,0,0,0,0,5,5,0,0,0,0,0,5,0,0,0
0,0,0,5,14,0,0,0,0,5,5,0,0,0,0,0,5,5,0,0,0,0,14,5,0,0,0
0,0,0,5,0,0,0,0,0,0,0,0,0,0,0,0,0,0,0,0,0,0,0,5,0,0,0
0,0,0,5,0,0,0,0,0,0,0,0,0,0,0,0,0,0,0,0,0,0,0,5,0,0,0
0,0,0,5,0,0,0,0,0,0,0,0,0,0,0,0,0,0,0,0,0,0,0,5,0,0,0
0,5,5,5,14,5,0,0,0,5,5,0,0,0,0,40,5,5,0,0,0,5,14,5,5,5,0
0,5,0,14,12,14,0,14,0,5,5,0,0,0,0,0,5,5,0,14,0,14,12,14,0,5,0
0,5,0,0,11,5,5,5,5,5,5,0,0,0,0,41,5,5,5,5,5,5,11,0,0,5,0
0,5,0,0,0,5,0,0,0,0,0,0,0,0,0,0,0,0,0,0,0,5,0,0,0,5,0
0,5,5,5,5,5,0,0,0,0,0,0,0,0,0,0,0,0,0,0,0,5,5,5,5,5,0
0,0,0,0,0,0,0,0,0,0,0,0,0,0,0,0,0,0,0,0,0,0,0,0,0,0,0
:endlayer

layer:
0,0,0,0,0,0,0,0,0,0,0,0,0,0,0,0,0,0,0,0,0,0,0,0,0,0,0
0,5,5,5,5,5,0,0,0,0,0,0,0,0,0,0,0,0,0,0,0,5,5,5,5,5,0
0,5,0,11,12,5,0,0,0,0,0,0,13,0,0,0,0,0,0,0,0,5,12,11,0,5,0
0,5,0,0,14,5,5,5,5,5,5,5,5,17,5,5,5,5,5,5,5,5,14,0,0,5,0
0,5,0,0,0,0,0,0,0,0,0,0,0,0,21,0,0,0,0,0,0,0,0,0,0,5,0
0,5,5,5,0,5,0,0,0,0,0,0,0,0,0,0,0,0,0,0,0,5,0,5,5,5,0
0,0,0,5,0,0,0,0,0,0,0,0,0,0,0,0,0,0,0,0,0,0,0,5,0,0,0
0,0,0,5,0,0,0,0,0,0,0,0,31,31,31,0,0,0,0,0,0,0,0,5,0,0,0
0,0,0,5,0,0,0,0,0,0,0,0,33,33,33,0,0,0,0,0,0,0,0,5,0,0,0
0,0,0,35,0,0,0,0,0,5,5,0,0,0,0,0,5,5,0,0,0,0,0,34,0,0,0
0,0,0,5,0,0,0,0,0,5,5,0,0,0,0,0,5,5,0,0,0,0,0,5,0,0,0
0,0,0,5,0,0,0,0,0,0,0,0,0,0,0,0,0,0,0,0,0,0,0,5,0,0,0
0,0,0,5,0,0,0,0,0,0,0,0,0,0,0,0,0,0,0,0,0,0,0,5,0,0,0
0,0,0,5,0,0,0,0,0,0,0,0,0,0,0,0,0,0,0,0,0,0,0,5,0,0,0
0,0,0,5,0,0,0,0,0,0,0,0,0,0,0,0,0,0,0,0,0,0,0,5,0,0,0
0,0,0,5,0,0,0,0,0,0,0,0,0,0,0,0,0,0,0,0,0,0,0,5,0,0,0
0,0,0,5,0,0,0,0,0,5,5,0,0,0,0,0,5,5,0,0,0,0,0,5,0,0,0
0,0,0,35,0,0,0,0,0,5,5,0,0,0,0,0,5,5,0,0,0,0,0,34,0,0,0
0,0,0,5,0,0,0,0,0,0,0,0,0,0,0,0,0,0,0,0,0,0,0,5,0,0,0
0,0,0,5,0,0,0,0,0,0,0,0,0,0,0,0,0,0,0,0,0,0,0,5,0,0,0
0,0,0,5,0,0,0,0,0,0,0,0,0,0,0,0,0,0,0,0,0,0,0,5,0,0,0
0,5,5,5,0,5,0,0,0,5,5,0,0,0,0,0,5,5,0,0,0,5,0,5,5,5,0
0,5,0,0,0,0,0,0,0,5,5,0,0,0,0,0,5,5,0,0,0,0,0,0,0,5,0
0,5,0,0,14,5,5,42,5,5,5,0,0,0,0,0,5,5,5,42,5,5,14,0,0,5,0
0,5,0,11,12,5,0,0,0,0,0,0,0,0,0,0,0,0,0,0,0,5,12,11,0,5,0
0,5,5,5,5,5,0,0,0,0,0,0,0,0,0,0,0,0,0,0,0,5,5,5,5,5,0
0,0,0,0,0,0,0,0,0,0,0,0,0,0,0,0,0,0,0,0,0,0,0,0,0,0,0
:endlayer

layer:
0,0,0,0,0,0,0,0,0,0,0,0,0,0,0,0,0,0,0,0,0,0,0,0,0,0,0
0,5,5,5,5,5,0,0,0,0,0,0,0,0,0,0,0,0,0,0,0,5,5,5,5,5,0
0,5,12,14,0,5,0,0,0,0,0,0,0,0,0,0,0,0,0,0,0,5,0,14,12,5,0
0,5,11,0,0,5,5,5,5,5,5,5,5,5,5,5,5,5,5,5,5,5,0,0,11,5,0
0,5,0,22,0,0,0,0,0,18,0,23,0,18,0,23,0,18,0,0,0,0,0,22,0,5,0
0,5,5,5,0,5,28,0,0,0,0,11,0,0,0,11,0,0,0,0,27,5,0,5,5,5,0
0,0,0,5,0,18,0,0,0,0,0,11,31,31,31,11,0,0,0,0,0,18,0,5,0,0,0
0,0,0,5,0,0,0,0,0,0,0,0,33,33,33,0,0,0,0,0,0,0,0,5,0,0,0
0,0,0,5,0,0,0,0,0,22,22,0,0,0,0,0,0,22,0,0,0,0,0,5,0,0,0
0,0,0,0,0,0,0,0,27,5,5,0,0,0,0,0,5,5,0,0,0,0,0,0,0,0,0
0,0,0,5,28,0,0,0,27,5,5,0,0,0,0,0,5,5,28,0,0,0,27,5,0,0,0
0,0,0,5,0,0,0,0,0,0,0,0,0,0,0,0,0,18,0,0,0,0,0,5,0,0,0
0,0,0,5,0,0,0,0,0,0,0,0,0,0,0,0,0,0,0,0,0,0,0,5,0,0,0
0,0,0,5,0,0,0,0,0,0,0,0,0,0,0,0,0,0,0,0,0,0,0,5,0,0,0
0,0,0,5,0,0,0,0,0,0,0,0,0,0,0,0,0,0,0,0,0,0,0,5,0,0,0
0,0,0,5,0,0,0,0,0,22,0,0,0,0,0,0,0,22,0,0,0,0,0,5,0,0,0
0,0,0,5,28,0,0,0,27,5,5,0,0,0,0,0,5,5,28,0,0,0,27,5,0,0,0
0,0,0,0,0,0,0,0,0,5,5,0,0,0,0,0,5,5,0,0,0,0,0,0,0,0,0
0,0,0,5,0,0,0,0,0,18,0,0,0,0,0,0,0,18,0,0,0,0,0,5,0,0,0
0,0,0,5,0,0,0,0,0,0,0,0,0,0,0,0,0,0,0,0,0,0,0,5,0,0,0
0,0,0,5,0,22,0,0,0,22,0,0,0,0,0,0,0,22,0,0,0,22,0,5,0,0,0
0,5,5,5,0,5,28,0,27,5,5,28,0,0,0,27,5,5,28,0,27,5,0,5,5,5,0
0,5,0,18,0,0,0,0,0,5,5,0,0,0,0,0,5,5,22,0,0,0,0,18,0,5,0
0,5,11,0,0,5,5,0,5,5,5,28,0,0,0,27,5,5,5,0,5,5,0,0,11,5,0
0,5,12,14,0,5,0,0,0,0,0,0,0,0,0,0,0,0,0,0,0,5,0,14,12,5,0
0,5,5,5,5,5,0,0,0,0,0,0,0,0,0,0,0,0,0,0,0,5,5,5,5,5,0
0,0,0,0,0,0,0,0,0,0,0,0,0,0,0,0,0,0,0,0,0,0,0,0,0,0,0
:endlayer

layer:
0,0,0,0,0,0,0,0,0,0,0,0,0,0,0,0,0,0,0,0,0,0,0,0,0,0,0
0,5,5,6,5,5,0,0,0,0,0,0,0,0,0,0,0,0,0,0,0,5,5,6,5,5,0
0,5,0,0,0,5,0,0,0,0,0,0,0,0,0,0,0,0,0,0,0,5,0,0,0,5,0
0,6,14,0,0,5,5,5,5,5,5,5,5,5,5,5,5,5,5,5,5,5,0,0,14,6,0
0,5,12,11,0,5,0,0,0,7,12,25,14,14,14,24,12,7,0,0,0,5,0,11,12,5,0
0,5,5,5,5,5,0,0,0,0,30,25,14,14,14,24,29,0,0,0,0,5,5,5,5,5,0
0,0,0,5,0,0,0,0,0,0,30,25,14,14,14,24,29,0,0,0,0,0,0,5,0,0,0
0,0,0,5,0,0,0,0,0,0,0,0,0,0,0,0,0,0,0,0,0,0,0,5,0,0,0
0,0,0,5,0,0,0,0,0,3,0,0,0,0,0,0,0,3,0,0,0,0,0,5,0,0,0
0,0,0,4,0,0,0,0,0,5,5,0,0,0,0,0,5,5,0,0,0,0,0,4,0,0,0
0,0,0,5,8,0,0,0,10,5,5,0,0,0,0,0,5,5,8,0,0,0,10,5,0,0,0
0,0,0,5,0,0,0,0,0,7,0,0,0,0,0,0,0,7,0,0,0,0,0,5,0,0,0
0,0,0,5,0,0,0,0,0,0,0,0,0,0,0,0,0,0,0,0,0,0,0,5,0,0,0
0,0,0,5,0,0,0,0,0,0,0,0,0,0,0,0,0,0,0,0,0,0,0,5,0,0,0
0,0,0,5,0,0,0,0,0,0,0,0,0,0,0,0,0,0,0,0,0,0,0,5,0,0,0
0,0,0,5,0,0,0,0,0,3,0,0,0,0,0,0,0,3,0,0,0,0,0,5,0,0,0
0,0,0,5,8,0,0,0,10,5,5,0,0,0,0,0,5,5,8,0,0,0,10,5,0,0,0
0,0,0,4,0,0,0,0,0,5,5,0,0,0,0,0,5,5,0,0,0,0,0,4,0,0,0
0,0,0,5,0,0,0,0,0,7,0,0,0,0,0,0,0,7,0,0,0,0,0,5,0,0,0
0,0,0,5,0,0,0,0,0,0,0,0,0,0,0,0,0,0,0,0,0,0,0,5,0,0,0
0,0,0,5,0,0,0,0,0,3,0,0,0,0,0,0,0,3,0,0,0,0,0,5,0,0,0
0,5,5,5,5,5,0,0,10,5,5,0,0,0,0,0,5,5,8,0,0,5,5,5,5,5,0
0,5,12,11,0,5,0,0,10,5,5,0,0,0,0,0,5,5,8,0,0,5,0,11,12,5,0
0,6,14,0,0,5,5,4,5,5,5,0,0,0,0,0,5,5,5,4,5,5,0,0,14,6,0
0,5,0,0,0,5,0,0,0,0,0,0,0,0,0,0,0,0,0,0,0,5,0,0,0,5,0
0,5,5,6,5,5,0,0,0,0,0,0,0,0,0,0,0,0,0,0,0,5,5,6,5,5,0
0,0,0,0,0,0,0,0,0,0,0,0,0,0,0,0,0,0,0,0,0,0,0,0,0,0,0
:endlayer

layer:
0,0,0,0,0,0,0,0,0,0,0,0,0,0,0,0,0,0,0,0,0,0,0,0,0,0,0
0,5,5,0,5,5,0,0,0,0,0,0,0,0,0,0,0,0,0,0,0,5,5,0,5,5,0
0,5,0,0,0,5,0,0,0,0,0,0,0,0,0,0,0,0,0,0,0,5,0,0,0,5,0
0,0,0,0,11,5,5,5,5,5,5,5,5,5,5,5,5,5,5,5,5,5,11,0,0,0,0
0,5,0,14,12,5,11,11,11,26,25,0,0,0,0,0,24,26,11,11,11,5,12,14,0,5,0
0,5,5,5,5,5,11,11,11,26,25,0,0,0,0,0,24,26,11,11,11,5,5,5,5,5,0
0,0,0,5,11,11,11,11,11,26,25,0,0,0,0,0,24,26,11,11,11,11,11,5,0,0,0
0,0,0,5,11,11,11,11,11,26,29,0,0,0,0,0,30,26,11,11,11,11,11,5,0,0,0
0,0,0,5,11,11,11,11,11,26,29,0,0,0,0,0,30,26,11,11,11,11,11,5,0,0,0
0,0,0,5,11,11,11,11,11,5,5,0,0,0,0,0,5,5,11,11,11,11,11,5,0,0,0
0,0,0,5,36,36,36,36,36,5,5,36,36,36,36,36,5,5,36,36,36,36,36,5,0,0,0
0,0,0,5,11,11,11,11,11,26,11,11,11,11,11,11,11,26,11,11,11,11,11,5,0,0,0
0,0,0,5,11,11,11,11,11,26,36,36,36,36,36,36,36,26,11,11,11,11,11,5,0,0,0
0,0,0,5,11,11,11,11,11,26,0,0,0,0,0,0,0,26,11,11,11,11,11,5,0,0,0
0,0,0,5,11,11,11,11,11,26,0,0,0,0,0,0,0,26,11,11,11,11,11,5,0,0,0
0,0,0,5,11,11,11,11,11,26,0,0,0,0,0,0,0,26,11,11,11,11,11,5,0,0,0
0,0,0,5,36,36,36,36,36,5,5,0,0,0,0,0,5,5,36,36,36,36,36,5,0,0,0
0,0,0,5,11,11,11,11,11,5,5,0,0,0,0,0,5,5,11,11,11,11,11,5,0,0,0
0,0,0,5,11,11,11,11,11,26,0,0,0,0,0,0,0,26,11,11,11,11,11,5,0,0,0
0,0,0,5,11,11,11,11,11,26,0,0,0,0,0,0,0,26,11,11,11,11,11,5,0,0,0
0,0,0,5,11,11,11,11,11,26,0,0,0,0,0,0,0,26,11,11,11,11,11,5,0,0,0
0,5,5,5,5,5,11,11,12,5,5,5,5,5,5,5,5,5,12,11,11,5,5,5,5,5,0
0,5,0,14,12,5,11,11,12,5,5,5,5,5,5,5,5,5,12,11,11,5,12,14,0,5,0
0,0,0,0,11,5,5,5,5,5,5,5,5,5,5,5,5,5,5,15,5,5,11,0,0,0,0
0,5,0,0,0,5,0,0,0,0,0,0,0,0,0,0,0,0,0,0,0,5,0,0,0,5,0
0,5,5,0,5,5,0,0,0,0,0,0,0,0,0,0,0,0,0,0,0,5,5,0,5,5,0
0,0,0,0,0,0,0,0,0,0,0,0,0,0,0,0,0,0,0,0,0,0,0,0,0,0,0
:endlayer

layer:
0,0,0,0,0,0,0,0,0,0,0,0,0,0,0,0,0,0,0,0,0,0,0,0,0,0,0
0,5,5,7,5,5,0,0,0,0,0,0,0,0,0,0,0,0,0,0,0,5,5,7,5,5,0
0,5,0,11,12,5,0,0,0,0,0,0,0,0,0,0,0,0,0,0,0,5,12,11,0,5,0
0,8,0,0,14,5,5,6,5,5,5,6,5,5,5,6,5,5,5,6,5,5,14,0,0,10,0
0,5,0,0,0,0,0,0,0,0,0,0,0,0,0,0,0,0,0,0,0,0,0,0,0,5,0
0,5,5,5,0,5,0,0,0,0,0,0,0,0,0,0,0,0,0,0,0,5,0,5,5,5,0
0,0,0,5,0,0,0,0,0,0,0,0,0,0,0,0,0,0,0,0,0,0,0,5,0,0,0
0,0,0,6,0,0,0,0,0,0,24,29,0,0,0,30,25,0,0,0,0,0,0,6,0,0,0
0,0,0,5,0,0,0,0,0,0,24,29,0,0,0,30,25,0,0,0,0,0,0,5,0,0,0
0,0,0,5,0,0,0,0,0,5,5,0,0,0,0,0,5,5,0,0,0,0,0,5,0,0,0
0,0,0,5,0,0,0,0,0,5,5,37,37,37,37,37,5,5,0,0,0,0,0,5,0,0,0
0,0,0,6,0,0,0,0,0,0,0,0,0,0,0,0,0,0,0,0,0,0,0,6,0,0,0
0,0,0,5,0,0,0,0,0,37,37,37,37,37,37,37,37,37,0,0,0,0,0,5,0,0,0
0,0,0,15,39,0,0,0,0,37,0,0,0,0,0,0,0,37,0,0,0,0,38,5,0,0,0
0,0,0,5,0,0,0,0,0,37,0,0,0,0,0,0,0,37,0,0,0,0,0,5,0,0,0
0,0,0,6,0,0,0,0,0,37,0,0,0,0,0,0,0,37,0,0,0,0,0,6,0,0,0
0,0,0,5,0,0,0,0,0,5,5,0,0,0,0,0,5,5,0,0,0,0,0,5,0,0,0
0,0,0,5,0,0,0,0,0,5,5,0,0,0,0,0,5,5,0,0,0,0,0,5,0,0,0
0,0,0,5,0,0,0,0,0,37,0,0,0,0,0,0,0,37,0,0,0,0,0,5,0,0,0
0,0,0,6,0,0,0,0,0,37,0,0,0,0,0,0,0,37,0,0,0,0,0,6,0,0,0
0,0,0,5,0,0,0,0,0,37,0,0,0,0,0,0,0,37,0,0,0,0,0,5,0,0,0
0,5,5,5,0,5,0,0,0,5,5,15,6,15,6,15,5,5,0,0,0,5,0,5,5,5,0
0,5,0,0,0,0,0,0,0,6,0,0,0,0,0,0,0,6,0,0,0,0,0,0,0,5,0
0,8,0,0,14,5,5,6,5,5,5,6,5,5,5,6,5,5,5,6,5,5,14,0,0,10,0
0,5,0,11,12,5,0,0,0,0,0,0,0,0,0,0,0,0,0,0,0,5,12,11,0,5,0
0,5,5,3,5,5,0,0,0,0,0,0,0,0,0,0,0,0,0,0,0,5,5,3,5,5,0
0,0,0,0,0,0,0,0,0,0,0,0,0,0,0,0,0,0,0,0,0,0,0,0,0,0,0
:endlayer

layer:
0,0,0,0,0,0,0,0,0,0,0,0,0,0,0,0,0,0,0,0,0,0,0,0,0,0,0
0,5,5,5,5,5,0,0,0,0,0,0,0,0,0,0,0,0,0,0,0,5,5,5,5,5,0
0,5,12,14,0,5,0,0,0,0,0,0,0,0,0,0,0,0,0,0,0,5,0,14,12,5,0
0,5,11,0,0,5,5,4,5,5,5,4,5,5,5,4,5,5,5,4,5,5,0,0,11,5,0
0,5,0,22,0,0,0,0,0,18,18,0,0,0,0,0,18,18,0,0,0,0,0,22,0,5,0
0,5,5,5,0,5,28,0,0,0,0,0,0,0,0,0,0,0,0,0,27,5,0,5,5,5,0
0,0,0,5,0,18,0,0,0,0,0,0,0,0,0,0,0,0,0,0,0,18,0,5,0,0,0
0,0,0,4,0,0,0,0,0,0,0,24,29,0,30,25,0,0,0,0,0,0,0,4,0,0,0
0,0,0,5,0,0,0,0,0,22,22,24,29,0,30,25,22,22,0,0,0,0,0,5,0,0,0
0,0,0,5,28,0,0,0,27,5,5,28,0,0,0,27,5,5,28,0,0,0,27,5,0,0,0
0,0,0,5,28,0,0,0,27,5,5,28,0,0,0,27,5,5,28,0,0,0,27,5,0,0,0
0,0,0,4,0,0,0,0,0,18,18,0,0,0,0,0,18,18,0,0,0,0,0,4,0,0,0
0,0,0,5,0,0,0,0,0,0,0,0,0,0,0,0,0,0,0,0,0,0,0,5,0,0,0
0,0,0,5,0,0,0,0,0,0,0,0,0,0,0,0,0,0,0,0,0,0,0,5,0,0,0
0,0,0,5,0,0,0,0,0,0,0,0,0,0,0,0,0,0,0,0,0,0,0,5,0,0,0
0,0,0,4,0,0,0,0,0,22,22,0,0,0,0,0,22,22,0,0,0,0,0,4,0,0,0
0,0,0,5,28,0,0,0,27,5,5,28,0,0,0,27,5,5,28,0,0,0,27,5,0,0,0
0,0,0,5,28,0,0,0,27,5,5,28,0,0,0,27,5,5,28,0,0,0,27,5,0,0,0
0,0,0,5,0,0,0,0,0,18,18,0,0,0,0,0,18,18,0,0,0,0,0,5,0,0,0
0,0,0,4,0,0,0,0,0,0,0,0,0,0,0,0,0,0,0,0,0,0,0,4,0,0,0
0,0,0,5,0,22,0,0,0,22,22,0,0,0,0,0,22,22,0,0,0,0,0,5,0,0,0
0,5,5,5,0,5,28,0,27,5,5,15,0,15,0,15,5,5,28,0,0,5,0,5,5,5,0
0,5,0,18,0,0,0,0,0,0,0,0,0,0,0,0,0,0,0,0,0,0,0,18,0,5,0
0,5,11,0,0,5,5,4,5,5,5,4,5,5,5,4,5,5,5,4,5,5,0,0,11,5,0
0,5,12,14,0,5,0,0,0,0,0,0,0,0,0,0,0,0,0,0,0,5,0,14,12,5,0
0,5,5,5,5,5,0,0,0,0,0,0,0,0,0,0,0,0,0,0,0,5,5,5,5,5,0
0,0,0,0,0,0,0,0,0,0,0,0,0,0,0,0,0,0,0,0,0,0,0,0,0,0,0
:endlayer

layer:
0,0,0,0,0,0,0,0,0,0,0,0,0,0,0,0,0,0,0,0,0,0,0,0,0,0,0
0,5,5,5,5,5,0,0,0,0,0,0,0,0,0,0,0,0,0,0,0,5,5,5,5,5,0
0,5,0,0,0,5,3,0,3,0,3,0,3,0,3,0,3,0,3,0,3,5,0,0,0,5,0
0,5,14,0,0,5,9,9,9,9,9,9,9,9,9,9,9,9,9,9,9,5,0,0,14,5,0
0,5,12,11,0,5,0,0,0,7,7,0,0,0,0,0,7,7,0,0,0,5,0,11,12,5,0
0,5,5,5,5,5,8,4,4,4,4,4,4,4,4,4,4,4,4,4,10,5,5,5,5,5,0
0,0,10,9,0,7,0,0,0,0,0,0,12,12,12,0,0,0,0,0,0,7,0,9,8,0,0
0,0,0,9,0,4,0,0,0,0,0,0,14,14,14,0,0,0,0,0,0,4,0,9,0,0,0
0,0,10,9,0,4,0,0,0,0,0,0,14,14,14,0,0,0,0,0,0,4,0,9,8,0,0
0,0,0,9,8,4,0,0,10,5,5,8,0,0,0,10,5,5,8,0,0,4,10,9,0,0,0
0,0,10,9,8,4,0,0,10,5,5,8,0,0,0,10,5,5,8,0,0,4,10,9,8,0,0
0,0,0,9,0,4,0,0,0,7,7,0,0,0,0,0,7,7,0,0,0,4,0,9,0,0,0
0,0,10,9,0,4,0,0,0,0,0,0,0,0,0,0,0,0,0,0,0,4,0,9,8,0,0
0,0,0,9,0,4,0,0,0,0,0,0,0,0,0,0,0,0,0,0,0,4,0,9,0,0,0
0,0,10,9,0,4,0,0,0,0,0,0,0,0,0,0,0,0,0,0,0,4,0,9,8,0,0
0,0,0,9,0,4,0,0,0,3,3,0,0,0,0,0,3,3,0,0,0,4,0,9,0,0,0
0,0,10,9,8,4,0,0,10,5,5,8,0,0,0,10,5,5,8,0,0,4,10,9,8,0,0
0,0,0,9,8,4,0,0,10,5,5,8,0,0,0,10,5,5,8,0,0,4,10,9,0,0,0
0,0,10,9,0,4,0,0,0,7,7,0,0,0,0,0,7,7,0,0,0,4,0,9,8,0,0
0,0,0,9,0,4,0,0,0,0,0,0,0,0,0,0,0,0,0,0,0,4,0,9,0,0,0
0,0,10,9,0,3,0,0,0,3,3,0,0,0,0,0,3,3,0,0,0,3,0,9,8,0,0
0,5,5,5,5,5,8,4,10,5,5,5,5,5,5,5,5,5,8,4,10,5,5,5,5,5,0
0,5,12,11,0,5,0,0,0,4,0,0,0,0,0,0,0,4,0,0,0,5,0,11,12,5,0
0,5,14,0,0,5,9,9,9,9,9,9,9,9,9,9,9,9,9,9,9,5,0,0,14,5,0
0,5,0,0,0,5,7,0,7,0,7,0,7,0,7,0,7,0,7,0,7,5,0,0,0,5,0
0,5,5,5,5,5,0,0,0,0,0,0,0,0,0,0,0,0,0,0,0,5,5,5,5,5,0
0,0,0,0,0,0,0,0,0,0,0,0,0,0,0,0,0,0,0,0,0,0,0,0,0,0,0
:endlayer

layer:
0,0,0,0,0,0,0,0,0,0,0,0,0,0,0,0,0,0,0,0,0,0,0,0,0,0,0
0,5,5,5,5,5,0,0,0,0,0,0,0,0,0,0,0,0,0,0,0,5,5,5,5,5,0
0,5,0,0,0,5,5,5,5,5,5,5,5,5,5,5,5,5,5,5,5,5,0,0,0,5,0
0,5,0,0,11,5,9,9,9,5,9,9,9,9,9,9,9,5,9,9,9,5,11,0,0,5,0
0,5,0,14,12,5,9,9,9,5,5,5,5,5,5,5,5,5,9,9,9,5,12,14,0,5,0
0,5,5,5,5,5,9,9,9,5,5,5,14,14,14,5,5,5,9,9,9,5,5,5,5,5,0
0,0,5,9,9,9,32,32,9,5,7,5,0,0,0,5,7,5,9,32,32,9,9,9,5,0,0
0,0,5,9,9,9,32,32,9,8,0,0,0,0,0,0,0,10,9,32,32,9,9,9,5,0,0
0,0,5,9,9,9,32,32,9,8,0,0,0,0,0,0,0,10,9,32,32,9,9,9,5,0,0
0,0,5,5,5,5,5,5,5,5,5,5,5,5,5,5,5,5,5,5,5,5,5,5,5,0,0
0,0,5,5,5,5,5,5,5,5,5,5,5,5,5,5,5,5,5,5,5,5,5,5,5,0,0
0,0,5,9,9,9,32,32,32,5,5,0,0,0,0,0,5,5,32,32,32,9,9,9,5,0,0
0,0,5,9,9,9,32,32,32,5,5,0,0,0,0,0,5,5,32,32,32,9,9,9,5,0,0
0,0,5,9,9,9,32,32,32,5,5,0,0,0,0,0,5,5,32,32,32,9,9,9,5,0,0
0,0,5,9,9,9,32,32,32,5,5,0,0,0,0,0,5,5,32,32,32,9,9,9,5,0,0
0,0,5,9,9,9,32,32,32,5,5,0,0,0,0,0,5,5,32,32,32,9,9,9,5,0,0
0,0,5,5,5,5,5,5,5,5,5,5,5,5,5,5,5,5,5,5,5,5,5,5,5,0,0
0,0,5,5,5,5,5,5,5,5,5,5,5,5,5,5,5,5,5,5,5,5,5,5,5,0,0
0,0,5,9,9,9,32,32,32,5,5,32,32,32,32,32,5,5,32,32,32,9,9,9,5,0,0
0,0,5,9,9,9,32,32,32,5,5,32,32,32,32,32,5,5,32,32,32,9,9,9,5,0,0
0,0,5,9,9,9,32,32,32,5,5,32,32,32,32,32,5,5,32,32,32,9,9,9,5,0,0
0,5,5,5,5,9,9,9,9,5,5,9,9,9,9,9,5,5,9,9,9,9,5,5,5,5,0
0,5,0,14,12,5,9,9,9,5,5,9,9,9,9,9,5,5,9,9,9,5,12,14,0,5,0
0,5,0,0,11,5,9,9,9,5,5,9,9,9,9,9,5,5,9,9,9,5,11,0,0,5,0
0,5,0,0,0,5,5,5,5,5,5,5,5,5,5,5,5,5,5,5,5,5,0,0,0,5,0
0,5,5,5,5,5,0,0,0,0,0,0,0,0,0,0,0,0,0,0,0,5,5,5,5,5,0
0,0,0,0,0,0,0,0,0,0,0,0,0,0,0,0,0,0,0,0,0,0,0,0,0,0,0
:endlayer

layer:
0,0,0,0,0,0,0,0,0,0,0,0,0,0,0,0,0,0,0,0,0,0,0,0,0,0,0
0,5,5,5,5,5,0,0,0,0,0,0,0,0,0,0,0,0,0,0,0,5,5,5,5,5,0
0,5,0,11,12,5,5,5,5,5,5,5,5,5,5,5,5,5,5,5,5,5,12,11,0,5,0
0,5,0,0,14,5,5,5,5,5,5,5,5,5,5,5,5,5,5,5,5,5,14,0,0,5,0
0,5,0,0,0,0,0,6,6,6,6,6,0,0,0,6,6,6,6,6,0,0,0,0,0,5,0
0,5,5,5,0,5,0,0,0,0,0,0,0,0,0,0,0,0,0,0,0,5,0,5,5,5,0
0,0,5,5,0,0,0,0,0,0,0,0,0,0,0,0,0,0,0,0,0,0,0,5,5,0,0
0,0,5,5,6,0,0,0,0,0,0,0,0,0,0,0,0,0,0,0,0,0,6,5,5,0,0
0,0,5,5,6,0,0,0,0,0,0,0,0,0,0,0,0,0,0,0,0,0,6,5,5,0,0
0,0,5,5,6,0,0,0,0,6,6,6,6,6,6,6,6,6,0,0,0,0,6,5,5,0,0
0,0,5,5,6,0,0,0,0,6,5,5,5,5,5,5,5,6,0,0,0,0,6,5,5,0,0
0,0,5,5,6,0,0,0,0,6,5,0,0,0,0,0,5,6,0,0,0,0,6,5,5,0,0
0,0,5,5,6,0,0,0,0,6,5,0,0,0,0,0,5,6,0,0,0,0,6,5,5,0,0
0,0,5,5,6,0,0,0,0,6,5,0,0,0,0,0,5,6,0,0,0,0,6,5,5,0,0
0,0,5,5,6,0,0,0,0,6,5,0,0,0,0,0,5,6,0,0,0,0,6,5,5,0,0
0,0,5,5,6,0,0,0,0,6,5,0,0,0,0,0,5,6,0,0,0,0,6,5,5,0,0
0,0,5,5,6,0,0,0,0,6,5,5,5,5,5,5,5,6,0,0,0,0,6,5,5,0,0
0,0,15,5,6,0,0,0,0,6,6,6,6,6,6,6,6,6,0,0,0,0,6,5,5,0,0
0,0,5,5,6,0,0,0,0,0,0,0,0,0,0,0,0,0,0,0,0,0,6,5,5,0,0
0,0,5,5,6,0,0,0,0,0,0,0,0,0,0,0,0,0,0,0,0,0,6,5,5,0,0
0,0,5,5,0,0,0,0,0,0,0,0,0,0,0,0,0,0,0,0,0,0,0,5,5,0,0
0,5,5,5,0,5,0,0,0,0,0,0,0,0,0,0,0,0,0,0,0,5,0,5,5,5,0
0,5,0,0,0,0,0,6,6,6,6,6,6,6,6,6,6,6,6,6,0,0,0,0,0,5,0
0,5,0,0,14,5,5,5,5,5,5,5,5,5,5,5,5,5,5,5,5,5,14,0,0,5,0
0,5,0,11,12,5,5,5,5,5,5,5,5,5,5,5,5,5,5,5,5,5,12,11,0,5,0
0,5,5,5,5,5,0,0,0,0,0,0,0,0,0,0,0,0,0,0,0,5,5,5,5,5,0
0,0,0,0,0,0,0,0,0,0,0,0,0,0,0,0,0,0,0,0,0,0,0,0,0,0,0
:endlayer

layer:
0,0,0,0,0,0,0,0,0,0,0,0,0,0,0,0,0,0,0,0,0,0,0,0,0,0,0
0,5,5,5,5,5,0,0,0,0,0,0,0,0,0,0,0,0,0,0,0,5,5,5,5,5,0
0,5,12,14,0,5,15,6,15,6,5,6,15,6,15,6,5,6,15,6,15,5,0,14,12,5,0
0,5,11,0,0,5,0,0,18,0,0,0,18,0,18,0,0,0,18,0,0,5,0,0,11,5,0
0,5,0,22,0,0,0,0,0,0,0,0,0,0,0,0,0,0,0,0,0,0,0,22,0,5,0
0,5,5,5,0,5,28,0,0,0,0,0,0,0,0,0,0,0,0,0,27,5,0,5,5,5,0
0,0,15,0,0,18,0,0,0,0,0,0,0,0,0,0,0,0,0,0,0,18,0,0,5,0,0
0,0,6,0,0,0,0,0,0,0,0,0,0,0,0,0,0,0,0,0,0,0,0,0,6,0,0
0,0,15,28,0,0,0,0,0,0,0,0,0,0,0,0,0,0,0,0,0,0,0,27,5,0,0
0,0,6,0,0,0,0,0,0,0,22,0,0,0,0,0,22,0,0,0,0,0,0,0,6,0,0
0,0,5,0,0,0,0,0,0,27,5,5,5,5,5,5,5,28,0,0,0,0,0,0,5,0,0
0,0,6,0,0,0,0,0,0,0,5,0,0,0,0,0,5,0,0,0,0,0,0,0,6,0,0
0,0,15,28,0,0,0,0,0,0,5,0,0,0,0,0,5,0,0,0,0,0,0,27,15,0,0
0,0,6,0,0,0,0,0,0,0,5,0,0,0,0,0,5,0,0,0,0,0,0,0,6,0,0
0,0,15,28,0,0,0,0,0,0,5,0,0,0,0,0,5,0,0,0,0,0,0,27,15,0,0
0,0,6,0,0,0,0,0,0,0,5,0,0,0,0,0,5,0,0,0,0,0,0,0,6,0,0
0,0,5,0,0,0,0,0,0,27,5,5,5,5,5,5,5,28,0,0,0,0,0,0,5,0,0
0,0,6,0,0,0,0,0,0,0,18,0,0,0,0,0,18,0,0,0,0,0,0,0,6,0,0
0,0,15,28,0,0,0,0,0,0,0,0,0,0,0,0,0,0,0,0,0,0,0,27,15,0,0
0,0,6,0,0,0,0,0,0,0,0,0,0,0,0,0,0,0,0,0,0,0,0,0,6,0,0
0,0,15,0,0,22,0,0,0,0,0,0,0,0,0,0,0,0,0,0,0,22,0,0,15,0,0
0,5,5,5,0,5,28,0,0,0,0,0,0,0,0,0,0,0,0,0,27,5,0,5,5,5,0
0,5,0,18,0,0,0,0,0,0,0,0,0,0,0,0,0,0,0,0,0,0,0,18,0,5,0
0,5,11,0,0,5,0,0,22,0,0,0,22,0,22,0,0,0,22,0,0,5,0,0,11,5,0
0,5,12,14,0,5,15,6,15,6,5,6,15,6,15,6,5,6,15,6,15,5,0,14,12,5,0
0,5,5,5,5,5,0,0,0,0,0,0,0,0,0,0,0,0,0,0,0,5,5,5,5,5,0
0,0,0,0,0,0,0,0,0,0,0,0,0,0,0,0,0,0,0,0,0,0,0,0,0,0,0
:endlayer

layer:
0,3,4,3,4,3,0,0,0,0,0,0,0,0,0,0,0,0,0,0,0,3,4,3,4,3,0
10,9,9,9,9,9,8,0,0,0,0,0,0,0,0,0,0,0,0,0,10,9,9,9,9,9,8
4,9,0,0,0,9,4,0,0,0,0,0,0,0,0,0,0,0,0,0,4,9,0,0,0,9,4
10,9,14,0,0,9,8,0,0,0,0,0,0,0,0,0,0,0,0,0,10,9,0,0,14,9,8
4,9,12,11,0,9,4,0,0,0,0,0,0,0,0,0,0,0,0,0,4,9,0,11,12,9,4
10,9,9,9,9,9,8,0,0,0,0,0,0,0,0,0,0,0,0,0,10,9,9,9,9,9,8
0,7,4,7,4,7,0,0,0,0,0,0,0,0,0,0,0,0,0,0,0,7,4,7,4,7,0
0,0,0,0,0,0,0,0,0,0,0,0,0,0,0,0,0,0,0,0,0,0,0,0,0,0,0
0,0,0,0,0,0,0,0,0,0,0,0,0,0,0,0,0,0,0,0,0,0,0,0,0,0,0
0,0,0,0,0,0,0,0,0,0,0,0,0,0,0,0,0,0,0,0,0,0,0,0,0,0,0
0,0,0,0,0,0,0,0,0,0,0,0,0,0,0,0,0,0,0,0,0,0,0,0,0,0,0
0,0,0,0,0,0,0,0,0,0,0,0,0,0,0,0,0,0,0,0,0,0,0,0,0,0,0
0,0,0,0,0,0,0,0,0,0,0,0,0,0,0,0,0,0,0,0,0,0,0,0,0,0,0
0,0,0,0,0,0,0,0,0,0,0,0,0,0,0,0,0,0,0,0,0,0,0,0,0,0,0
0,0,0,0,0,0,0,0,0,0,0,0,0,0,0,0,0,0,0,0,0,0,0,0,0,0,0
0,0,0,0,0,0,0,0,0,0,0,0,0,0,0,0,0,0,0,0,0,0,0,0,0,0,0
0,0,0,0,0,0,0,0,0,0,0,0,0,0,0,0,0,0,0,0,0,0,0,0,0,0,0
0,0,0,0,0,0,0,0,0,0,0,0,0,0,0,0,0,0,0,0,0,0,0,0,0,0,0
0,0,0,0,0,0,0,0,0,0,0,0,0,0,0,0,0,0,0,0,0,0,0,0,0,0,0
0,0,0,0,0,0,0,0,0,0,0,0,0,0,0,0,0,0,0,0,0,0,0,0,0,0,0
0,3,4,3,4,3,0,0,0,0,0,0,0,0,0,0,0,0,0,0,0,3,4,3,4,3,0
10,9,9,9,9,9,8,0,0,0,0,0,0,0,0,0,0,0,0,0,10,9,9,9,9,9,8
4,9,12,11,0,9,4,0,0,0,0,0,0,0,0,0,0,0,0,0,4,9,0,11,12,9,4
10,9,14,0,0,9,8,0,0,0,0,0,0,0,0,0,0,0,0,0,10,9,0,0,14,9,8
4,9,0,0,0,9,4,0,0,0,0,0,0,0,0,0,0,0,0,0,4,9,0,0,0,9,4
10,9,9,9,9,9,8,0,0,0,0,0,0,0,0,0,0,0,0,0,10,9,9,9,9,9,8
0,7,4,7,4,7,0,0,0,0,0,0,0,0,0,0,0,0,0,0,0,7,4,7,4,7,0
:endlayer

layer:
5,5,5,5,5,5,5,0,0,0,0,0,0,0,0,0,0,0,0,0,5,5,5,5,5,5,5
5,5,5,5,5,5,5,0,0,0,0,0,0,0,0,0,0,0,0,0,5,5,5,5,5,5,5
5,5,0,0,11,5,5,0,0,0,0,0,0,0,0,0,0,0,0,0,5,5,11,0,0,5,5
5,5,0,11,11,5,5,0,0,0,0,0,0,0,0,0,0,0,0,0,5,5,11,11,0,5,5
5,5,0,14,12,5,5,0,0,0,0,0,0,0,0,0,0,0,0,0,5,5,12,14,0,5,5
5,5,5,5,5,5,5,0,0,0,0,0,0,0,0,0,0,0,0,0,5,5,5,5,5,5,5
5,5,5,5,5,5,5,0,0,0,0,0,0,0,0,0,0,0,0,0,5,5,5,5,5,5,5
0,0,0,0,0,0,0,0,0,0,0,0,0,0,0,0,0,0,0,0,0,0,0,0,0,0,0
0,0,0,0,0,0,0,0,0,0,0,0,0,0,0,0,0,0,0,0,0,0,0,0,0,0,0
0,0,0,0,0,0,0,0,0,0,0,0,0,0,0,0,0,0,0,0,0,0,0,0,0,0,0
0,0,0,0,0,0,0,0,0,0,0,0,0,0,0,0,0,0,0,0,0,0,0,0,0,0,0
0,0,0,0,0,0,0,0,0,0,0,0,0,0,0,0,0,0,0,0,0,0,0,0,0,0,0
0,0,0,0,0,0,0,0,0,0,0,0,0,0,0,0,0,0,0,0,0,0,0,0,0,0,0
0,0,0,0,0,0,0,0,0,0,0,0,0,0,0,0,0,0,0,0,0,0,0,0,0,0,0
0,0,0,0,0,0,0,0,0,0,0,0,0,0,0,0,0,0,0,0,0,0,0,0,0,0,0
0,0,0,0,0,0,0,0,0,0,0,0,0,0,0,0,0,0,0,0,0,0,0,0,0,0,0
0,0,0,0,0,0,0,0,0,0,0,0,0,0,0,0,0,0,0,0,0,0,0,0,0,0,0
0,0,0,0,0,0,0,0,0,0,0,0,0,0,0,0,0,0,0,0,0,0,0,0,0,0,0
0,0,0,0,0,0,0,0,0,0,0,0,0,0,0,0,0,0,0,0,0,0,0,0,0,0,0
0,0,0,0,0,0,0,0,0,0,0,0,0,0,0,0,0,0,0,0,0,0,0,0,0,0,0
5,5,5,5,5,5,5,0,0,0,0,0,0,0,0,0,0,0,0,0,5,5,5,5,5,5,5
5,5,5,5,5,5,5,0,0,0,0,0,0,0,0,0,0,0,0,0,5,5,5,5,5,5,5
5,5,0,14,12,5,5,0,0,0,0,0,0,0,0,0,0,0,0,0,5,5,12,14,0,5,5
5,5,0,11,11,5,5,0,0,0,0,0,0,0,0,0,0,0,0,0,5,5,11,11,0,5,5
5,5,0,0,11,5,5,0,0,0,0,0,0,0,0,0,0,0,0,0,5,5,11,0,0,5,5
5,5,5,5,5,5,5,0,0,0,0,0,0,0,0,0,0,0,0,0,5,5,5,5,5,5,5
5,5,5,5,5,5,5,0,0,0,0,0,0,0,0,0,0,0,0,0,5,5,5,5,5,5,5
:endlayer

layer:
5,5,5,5,5,5,5,0,0,0,0,0,0,0,0,0,0,0,0,0,5,5,5,5,5,5,5
5,0,0,0,0,0,5,0,0,0,0,0,0,0,0,0,0,0,0,0,5,0,0,0,0,0,5
5,0,0,0,0,0,5,0,0,0,0,0,0,0,0,0,0,0,0,0,5,0,0,0,0,0,5
5,0,0,19,0,0,5,0,0,0,0,0,0,0,0,0,0,0,0,0,5,0,0,19,0,0,5
5,0,0,0,0,0,5,0,0,0,0,0,0,0,0,0,0,0,0,0,5,0,0,0,0,0,5
5,0,0,0,0,0,5,0,0,0,0,0,0,0,0,0,0,0,0,0,5,0,0,0,0,0,5
5,5,5,5,5,5,5,0,0,0,0,0,0,0,0,0,0,0,0,0,5,5,5,5,5,5,5
0,0,0,0,0,0,0,0,0,0,0,0,0,0,0,0,0,0,0,0,0,0,0,0,0,0,0
0,0,0,0,0,0,0,0,0,0,0,0,0,0,0,0,0,0,0,0,0,0,0,0,0,0,0
0,0,0,0,0,0,0,0,0,0,0,0,0,0,0,0,0,0,0,0,0,0,0,0,0,0,0
0,0,0,0,0,0,0,0,0,0,0,0,0,0,0,0,0,0,0,0,0,0,0,0,0,0,0
0,0,0,0,0,0,0,0,0,0,0,0,0,0,0,0,0,0,0,0,0,0,0,0,0,0,0
0,0,0,0,0,0,0,0,0,0,0,0,0,0,0,0,0,0,0,0,0,0,0,0,0,0,0
0,0,0,0,0,0,0,0,0,0,0,0,0,0,0,0,0,0,0,0,0,0,0,0,0,0,0
0,0,0,0,0,0,0,0,0,0,0,0,0,0,0,0,0,0,0,0,0,0,0,0,0,0,0
0,0,0,0,0,0,0,0,0,0,0,0,0,0,0,0,0,0,0,0,0,0,0,0,0,0,0
0,0,0,0,0,0,0,0,0,0,0,0,0,0,0,0,0,0,0,0,0,0,0,0,0,0,0
0,0,0,0,0,0,0,0,0,0,0,0,0,0,0,0,0,0,0,0,0,0,0,0,0,0,0
0,0,0,0,0,0,0,0,0,0,0,0,0,0,0,0,0,0,0,0,0,0,0,0,0,0,0
0,0,0,0,0,0,0,0,0,0,0,0,0,0,0,0,0,0,0,0,0,0,0,0,0,0,0
5,5,5,5,5,5,5,0,0,0,0,0,0,0,0,0,0,0,0,0,5,5,5,5,5,5,5
5,0,0,0,0,0,5,0,0,0,0,0,0,0,0,0,0,0,0,0,5,0,0,0,0,0,5
5,0,0,0,0,0,5,0,0,0,0,0,0,0,0,0,0,0,0,0,5,0,0,0,0,0,5
5,0,0,19,0,0,5,0,0,0,0,0,0,0,0,0,0,0,0,0,5,0,0,19,0,0,5
5,0,0,0,0,0,5,0,0,0,0,0,0,0,0,0,0,0,0,0,5,0,0,0,0,0,5
5,0,0,0,0,0,5,0,0,0,0,0,0,0,0,0,0,0,0,0,5,0,0,0,0,0,5
5,5,5,5,5,5,5,0,0,0,0,0,0,0,0,0,0,0,0,0,5,5,5,5,5,5,5
:endlayer

layer:
5,6,5,6,5,6,5,0,0,0,0,0,0,0,0,0,0,0,0,0,5,6,5,6,5,6,5
6,0,0,0,0,0,6,0,0,0,0,0,0,0,0,0,0,0,0,0,6,0,0,0,0,0,6
5,0,0,0,0,0,5,0,0,0,0,0,0,0,0,0,0,0,0,0,5,0,0,0,0,0,5
6,0,0,0,0,0,6,0,0,0,0,0,0,0,0,0,0,0,0,0,6,0,0,0,0,0,6
5,0,0,0,0,0,5,0,0,0,0,0,0,0,0,0,0,0,0,0,5,0,0,0,0,0,5
6,0,0,0,0,0,6,0,0,0,0,0,0,0,0,0,0,0,0,0,6,0,0,0,0,0,6
5,6,5,6,5,6,5,0,0,0,0,0,0,0,0,0,0,0,0,0,5,6,5,6,5,6,5
0,0,0,0,0,0,0,0,0,0,0,0,0,0,0,0,0,0,0,0,0,0,0,0,0,0,0
0,0,0,0,0,0,0,0,0,0,0,0,0,0,0,0,0,0,0,0,0,0,0,0,0,0,0
0,0,0,0,0,0,0,0,0,0,0,0,0,0,0,0,0,0,0,0,0,0,0,0,0,0,0
0,0,0,0,0,0,0,0,0,0,0,0,0,0,0,0,0,0,0,0,0,0,0,0,0,0,0
0,0,0,0,0,0,0,0,0,0,0,0,0,0,0,0,0,0,0,0,0,0,0,0,0,0,0
0,0,0,0,0,0,0,0,0,0,0,0,0,0,0,0,0,0,0,0,0,0,0,0,0,0,0
0,0,0,0,0,0,0,0,0,0,0,0,0,0,0,0,0,0,0,0,0,0,0,0,0,0,0
0,0,0,0,0,0,0,0,0,0,0,0,0,0,0,0,0,0,0,0,0,0,0,0,0,0,0
0,0,0,0,0,0,0,0,0,0,0,0,0,0,0,0,0,0,0,0,0,0,0,0,0,0,0
0,0,0,0,0,0,0,0,0,0,0,0,0,0,0,0,0,0,0,0,0,0,0,0,0,0,0
0,0,0,0,0,0,0,0,0,0,0,0,0,0,0,0,0,0,0,0,0,0,0,0,0,0,0
0,0,0,0,0,0,0,0,0,0,0,0,0,0,0,0,0,0,0,0,0,0,0,0,0,0,0
0,0,0,0,0,0,0,0,0,0,0,0,0,0,0,0,0,0,0,0,0,0,0,0,0,0,0
5,6,5,6,5,6,5,0,0,0,0,0,0,0,0,0,0,0,0,0,5,6,5,6,5,6,5
6,0,0,0,0,0,6,0,0,0,0,0,0,0,0,0,0,0,0,0,6,0,0,0,0,0,6
5,0,0,0,0,0,5,0,0,0,0,0,0,0,0,0,0,0,0,0,5,0,0,0,0,0,5
6,0,0,0,0,0,6,0,0,0,0,0,0,0,0,0,0,0,0,0,6,0,0,0,0,0,6
5,0,0,0,0,0,5,0,0,0,0,0,0,0,0,0,0,0,0,0,5,0,0,0,0,0,5
6,0,0,0,0,0,6,0,0,0,0,0,0,0,0,0,0,0,0,0,6,0,0,0,0,0,6
5,6,5,6,5,6,5,0,0,0,0,0,0,0,0,0,0,0,0,0,5,6,5,6,5,6,5
:endlayer


####INVENTORIES####


