# Ancient Warfare Structure Template File
# auto-generated structure file. created on: 6/7/2013 at: 23:8:33
# Lines beginning with # denote comments

survival=false
validTargetblocks=1,2,3,12,13

underground=false
undergroundMinLevel=1
undergroundMaxLevel=238
undergroundMaxAirAbove=0
minSubmergedDepth=0
maxWaterDepth=0
maxLavaDepth=0

xSize=23
ySize=16
zSize=27

verticalOffset=16
xOffset=7
zOffset=0

maxOverhang=1000
maxLeveling=1
levelingBuffer=4
maxVerticalClear=-1
clearingBuffer=0
preserveWater=false
preserveLava=false
preservePlants=false
preserveBlocks=false

####BLOCK RULES####
rule:
number=0
order=0
conditional=0
percent=100
blocks=0-0
:endrule

rule:
number=2
order=1
conditional=0
percent=100
blocks=13-0
inventory=0
:endrule

rule:
number=3
order=0
conditional=0
percent=100
blocks=1-0
inventory=0
:endrule

rule:
number=4
order=0
conditional=0
percent=100
blocks=3-0
inventory=0
:endrule

rule:
number=5
order=0
conditional=0
percent=100
blocks=49-0
inventory=0
:endrule

rule:
number=6
order=0
conditional=0
percent=100
blocks=2-0
inventory=0
:endrule

rule:
number=7
order=1
conditional=0
percent=100
blocks=31-1
inventory=0
:endrule

rule:
number=8
order=1
conditional=0
percent=100
blocks=55-0
inventory=0
:endrule

rule:
number=9
order=1
conditional=0
percent=100
blocks=76-2
inventory=0
:endrule

rule:
number=10
order=1
conditional=0
percent=100
blocks=55-15
inventory=0
:endrule

rule:
number=11
order=1
conditional=0
percent=100
blocks=55-14
inventory=0
:endrule

rule:
number=12
order=1
conditional=0
percent=100
blocks=55-13
inventory=0
:endrule

rule:
number=13
order=1
conditional=0
percent=100
blocks=55-12
inventory=0
:endrule

rule:
number=14
order=1
conditional=0
percent=100
blocks=93-3
inventory=0
:endrule

rule:
number=15
order=1
conditional=0
percent=100
blocks=94-2
inventory=0
:endrule

rule:
number=17
order=0
conditional=0
percent=100
blocks=154-11
inventory=0
:endrule

rule:
number=16
order=1
conditional=0
percent=100
blocks=93-2
inventory=0
:endrule

rule:
number=19
order=0
conditional=0
percent=100
blocks=54-3
inventory=0
:endrule

rule:
number=18
order=0
conditional=0
percent=100
blocks=154-5
inventory=0
:endrule

rule:
number=21
order=0
conditional=0
percent=100
blocks=15-0
inventory=0
:endrule

rule:
number=20
order=0
conditional=0
percent=100
blocks=46-0
inventory=0
:endrule

rule:
number=23
order=0
conditional=0
percent=100
blocks=33-4
inventory=0
:endrule

rule:
number=22
order=1
conditional=0
percent=100
blocks=75-1
inventory=0
:endrule

rule:
number=25
order=1
conditional=0
percent=100
blocks=94-0
inventory=0
:endrule

rule:
number=24
order=0
conditional=0
percent=100
blocks=33-5
inventory=0
:endrule

rule:
number=27
order=1
conditional=0
percent=100
blocks=93-8
inventory=0
:endrule

rule:
number=26
order=1
conditional=0
percent=100
blocks=93-0
inventory=0
:endrule

rule:
number=29
order=0
conditional=0
percent=100
blocks=98-0
inventory=0
:endrule

rule:
number=28
order=1
conditional=0
percent=100
blocks=37-0
inventory=0
:endrule

rule:
number=31
order=1
conditional=0
percent=100
blocks=75-5
inventory=0
:endrule

rule:
number=30
order=1
conditional=0
percent=100
blocks=76-4
inventory=0
:endrule

rule:
number=34
order=0
conditional=0
percent=100
blocks=101-0
inventory=0
:endrule

rule:
number=35
order=1
conditional=0
percent=100
blocks=93-5
inventory=0
:endrule

rule:
number=32
order=0
conditional=0
percent=100
blocks=158-3
inventory=0
:endrule

rule:
number=33
order=1
conditional=0
percent=100
blocks=149-3
inventory=0
:endrule

rule:
number=38
order=0
conditional=0
percent=100
blocks=44-0
inventory=0
:endrule

rule:
number=39
order=0
conditional=0
percent=100
blocks=4-0
inventory=0
:endrule

rule:
number=36
order=1
conditional=0
percent=100
blocks=75-3
inventory=0
:endrule

rule:
number=37
order=1
conditional=0
percent=100
blocks=50-4
inventory=0
:endrule

rule:
number=42
order=1
conditional=0
percent=100
blocks=76-1
inventory=0
:endrule

rule:
number=43
order=1
conditional=0
percent=100
blocks=69-2
inventory=0
:endrule

rule:
number=40
order=0
conditional=0
percent=100
blocks=77-3
inventory=0
:endrule

rule:
number=41
order=1
conditional=0
percent=100
blocks=94-12
inventory=0
:endrule

rule:
number=46
order=1
conditional=0
percent=100
blocks=93-1
inventory=0
:endrule

rule:
number=47
order=0
conditional=0
percent=100
blocks=16-0
inventory=0
:endrule

rule:
number=44
order=1
conditional=0
percent=100
blocks=93-6
inventory=0
:endrule

rule:
number=45
order=0
conditional=0
percent=100
blocks=33-0
inventory=0
:endrule

rule:
number=50
order=0
conditional=0
percent=100
blocks=67-2
inventory=0
:endrule

rule:
number=49
order=0
conditional=0
percent=100
blocks=67-7
inventory=0
:endrule

rule:
number=48
order=0
conditional=0
percent=100
blocks=33-2
inventory=0
:endrule


####SWAP RULESS####

####VEHICLE RULES####

####NPC RULES####
####CIVIC RULES####

####GATE RULES####

####ENTITY RULES####

####RESOURCE LIST####
resources:
1-0,5217
3-0,2689
75-0,3
331-0,71
76-0,7
15-0,56
13-0,197
16-0,33
31-0,197
37-0,8
356-0,19
50-0,1
98-0,51
149-0,1
4-0,218
49-0,633
154-0,9
158-0,1
44-0,1
101-0,7
54-0,4
67-0,54
46-0,2
77-0,1
69-0,4
33-0,5
:endresources

####LAYERS####

layer:
3,3,4,4,2,2,2,2,3,3,3,3,3,3,3,3,3,3,2,2,2,2,2
3,3,3,4,4,4,2,4,3,3,3,3,3,3,3,3,3,3,3,2,2,2,2
3,3,3,3,4,4,4,4,4,3,3,3,3,3,3,3,3,3,3,2,2,2,2
3,3,3,3,3,4,4,4,4,4,3,3,3,3,3,3,3,3,3,3,2,2,2
3,3,3,3,3,3,3,3,4,3,3,3,3,3,3,3,3,3,3,3,2,2,2
3,3,3,3,3,3,3,3,3,3,3,3,3,3,3,3,3,3,3,3,3,2,2
3,3,3,3,3,3,3,3,3,3,3,3,3,3,3,3,3,3,3,3,3,3,3
3,3,3,3,3,3,3,3,3,3,3,3,3,3,3,3,3,3,3,3,3,3,3
3,3,3,3,3,3,3,3,3,3,3,3,3,3,3,3,3,3,3,3,3,3,3
3,3,3,3,3,3,3,3,3,3,3,3,3,3,3,3,3,3,3,3,3,3,3
3,3,3,3,3,3,3,3,3,3,3,3,3,3,3,3,3,3,3,3,3,3,3
3,3,3,3,3,3,3,3,3,3,3,3,21,3,3,3,3,3,3,3,3,3,3
3,3,3,3,3,3,3,3,3,3,3,21,3,3,3,3,3,3,3,3,3,3,3
3,3,3,3,3,3,3,3,3,3,3,3,3,3,3,3,3,3,3,3,3,3,3
3,3,3,3,3,3,3,3,3,3,3,3,3,3,3,3,3,3,3,3,3,3,3
3,3,3,3,3,3,3,3,3,3,3,3,3,3,3,3,3,3,3,3,3,3,3
3,3,3,3,3,3,3,3,3,3,3,3,3,3,3,3,3,3,3,3,3,3,3
3,3,3,3,3,3,3,3,3,3,3,3,3,3,3,3,3,3,3,4,3,3,3
3,3,3,3,3,3,3,3,3,3,3,3,3,3,3,3,3,3,4,4,4,4,4
3,3,3,3,3,3,3,3,3,3,3,3,3,3,3,3,3,3,4,4,4,4,4
4,3,3,3,3,3,3,3,3,3,3,3,3,3,3,3,3,3,3,3,3,3,4
4,3,3,3,3,3,3,3,3,3,3,3,3,3,3,3,3,3,3,3,3,3,3
3,3,3,3,3,3,3,3,3,3,3,3,3,3,3,3,3,3,3,3,3,3,4
3,3,3,3,3,3,3,3,3,3,3,3,3,3,3,3,3,3,3,3,3,3,4
3,3,3,3,3,3,3,3,3,3,3,3,3,3,3,3,3,3,3,3,3,3,4
3,3,3,3,3,3,3,3,3,3,3,3,3,3,3,3,3,3,3,3,3,3,3
3,3,3,3,3,3,3,3,3,3,3,3,3,3,3,3,3,3,3,3,3,3,3
:endlayer

layer:
3,3,3,3,3,3,3,3,3,3,3,3,3,3,3,3,3,3,3,2,2,2,2
3,3,3,3,3,3,3,3,3,3,3,3,3,3,3,3,3,3,3,2,2,2,2
3,3,3,3,3,3,3,3,3,3,3,3,3,3,3,3,3,3,3,2,2,2,2
3,3,3,3,3,3,3,3,3,3,3,3,3,3,3,3,3,3,3,3,2,2,4
3,3,3,3,3,3,3,3,3,3,3,3,3,3,3,3,3,3,3,3,2,2,2
3,3,3,3,3,3,3,3,3,3,3,3,3,3,3,3,3,3,3,3,3,3,3
3,3,3,3,3,3,3,3,3,3,3,3,3,3,3,3,3,3,3,3,3,3,3
3,3,3,3,3,3,3,3,3,3,3,3,3,3,3,3,3,3,3,3,3,3,3
3,3,3,13,3,3,3,3,3,3,3,3,3,3,3,3,3,3,3,3,3,3,3
3,3,3,3,3,3,3,3,3,3,3,3,3,3,3,3,3,3,3,3,3,3,3
3,3,3,3,3,3,3,3,3,3,3,3,3,3,3,3,3,3,21,21,3,3,3
3,3,3,3,3,3,3,3,3,3,3,3,21,3,3,3,3,3,21,21,3,3,3
3,3,3,3,3,3,3,3,3,3,3,21,3,3,3,3,3,3,3,3,3,3,3
3,3,3,3,3,3,3,3,3,3,3,3,3,3,3,3,3,3,3,3,3,3,3
3,3,3,3,3,3,3,3,3,3,3,3,3,3,3,3,3,3,3,3,3,3,3
3,3,3,3,3,3,3,3,3,3,3,3,3,3,3,3,3,3,3,3,3,3,3
3,3,3,3,3,3,3,3,3,3,3,3,3,3,3,3,3,3,3,3,3,3,3
3,3,3,3,3,3,3,3,3,3,3,3,3,3,3,3,3,4,4,4,4,4,4
3,3,3,3,3,3,3,3,3,3,3,3,3,3,3,3,4,4,4,4,4,4,4
3,3,3,3,3,3,3,3,3,3,3,3,3,3,3,3,4,4,4,4,4,4,4
4,3,3,3,3,3,3,3,3,3,3,3,3,3,3,3,3,3,4,4,4,4,4
4,3,3,3,3,3,3,3,3,3,3,3,3,3,3,3,3,3,3,3,3,3,3
3,3,3,3,3,3,3,3,3,3,3,3,3,3,3,3,3,3,3,3,3,3,3
3,3,3,3,3,3,3,3,3,3,3,3,3,3,3,3,3,3,3,3,3,3,3
3,3,3,3,3,3,3,3,3,3,3,3,3,3,3,3,3,3,3,3,3,3,3
3,3,3,3,3,3,3,3,3,3,3,3,3,3,3,3,3,3,3,3,3,3,3
3,3,3,3,3,3,3,3,3,3,3,3,3,3,3,3,3,3,3,3,3,3,3
:endlayer

layer:
3,3,3,3,3,3,3,3,3,3,3,3,3,3,3,3,3,3,3,3,3,3,3
3,3,3,3,3,3,3,3,3,3,3,3,3,3,3,3,3,3,3,3,3,3,3
3,3,3,3,3,3,3,3,3,3,3,3,3,3,3,3,3,3,3,3,3,3,3
3,3,3,3,3,3,3,3,3,3,3,3,3,3,3,3,3,3,3,3,3,3,3
3,3,3,3,3,3,3,3,3,3,3,3,3,3,3,3,3,3,3,3,3,3,3
3,3,3,3,3,3,3,3,3,3,3,3,3,3,3,3,3,3,3,3,3,3,3
3,3,3,3,3,3,3,3,3,3,3,3,3,3,3,3,3,3,3,3,3,3,3
3,3,3,3,3,3,3,3,3,3,3,3,3,3,3,3,3,3,3,3,3,3,3
3,11,12,0,31,3,3,3,3,3,3,3,3,3,3,3,3,3,3,3,3,3,3
36,35,13,3,3,3,3,3,3,3,3,3,3,3,3,3,3,3,3,3,3,3,3
3,3,3,3,3,3,3,3,3,3,3,3,3,3,3,3,3,3,21,21,3,3,3
3,3,3,3,3,3,3,3,3,3,3,3,3,3,3,3,3,3,21,21,3,3,3
3,3,3,3,3,3,3,3,3,3,3,3,3,3,3,3,3,3,3,3,3,3,3
3,3,3,3,3,3,3,3,3,3,3,3,3,3,3,3,3,3,3,3,3,3,3
3,3,3,3,3,3,3,3,3,3,3,3,3,3,3,3,3,3,3,3,3,3,3
3,3,3,3,3,3,3,3,3,3,3,3,3,3,3,3,3,3,3,3,3,3,3
3,3,3,3,3,3,3,3,3,3,3,3,3,3,3,3,3,3,3,3,3,3,3
3,3,3,3,3,3,3,3,3,3,3,3,3,3,3,3,3,4,4,4,4,4,4
3,3,3,3,3,3,3,3,3,3,3,3,3,3,3,3,4,4,4,4,4,4,4
3,3,3,3,3,3,3,3,3,3,3,3,3,3,3,3,4,4,4,4,4,4,4
3,3,3,3,3,3,3,3,3,3,3,3,3,3,3,3,3,3,4,4,4,4,4
3,3,3,3,3,3,3,3,3,3,3,3,3,3,3,3,3,3,3,3,3,3,3
3,3,3,3,3,3,3,3,3,3,3,3,3,3,3,3,3,3,3,3,3,3,3
3,3,3,3,3,3,3,3,3,3,3,3,3,3,3,3,3,3,3,3,3,3,3
3,3,3,3,3,3,3,3,3,3,3,3,3,3,3,3,3,3,3,3,3,3,3
3,3,3,3,3,3,3,3,3,3,3,3,3,3,3,3,3,3,3,3,3,3,3
3,3,3,3,3,3,3,3,3,3,3,3,3,3,3,3,3,3,3,3,3,3,3
:endlayer

layer:
3,3,3,3,3,3,3,3,3,3,3,3,3,3,3,3,3,3,3,3,3,3,3
3,3,3,3,5,3,3,3,3,3,3,3,3,3,3,3,3,3,3,3,3,3,3
3,3,3,3,5,5,5,5,5,5,3,3,3,3,3,3,3,3,3,3,3,3,3
3,3,3,3,5,5,5,5,5,5,5,3,3,3,3,3,3,3,3,3,3,3,3
3,3,3,3,5,5,5,5,5,5,5,3,3,3,3,3,3,3,3,3,3,3,3
3,3,3,3,5,5,5,5,5,5,5,3,3,3,3,3,3,3,3,3,3,3,3
3,3,3,3,5,5,5,5,5,5,5,3,3,3,3,3,3,3,3,3,3,3,3
3,3,3,29,5,5,5,5,5,5,5,3,3,3,3,3,3,3,3,3,3,3,3
10,0,3,29,29,3,3,3,3,3,3,3,3,3,4,4,4,3,3,3,3,3,3
0,37,3,3,3,3,3,3,3,3,3,3,3,3,4,4,4,3,3,3,3,3,3
3,3,3,3,3,3,3,3,3,3,3,3,3,3,3,3,3,3,3,3,3,3,3
3,3,3,3,3,3,3,3,3,3,3,3,3,3,3,3,3,3,3,3,3,3,3
3,3,3,3,3,3,3,3,3,3,3,3,3,3,3,3,3,3,3,3,3,3,3
3,3,3,3,3,3,3,3,3,3,3,3,3,3,3,3,3,3,3,3,3,3,3
3,3,3,3,3,3,3,3,3,3,3,3,3,3,3,3,3,3,3,3,3,3,3
3,3,3,3,3,3,39,3,3,3,3,3,3,3,3,3,3,3,3,3,3,3,3
3,3,3,3,3,3,3,3,3,3,3,3,3,3,3,3,3,3,3,3,3,3,3
3,3,3,3,3,3,3,3,3,3,3,3,3,3,3,3,3,3,3,4,3,3,3
3,3,3,3,3,3,3,3,3,3,3,3,3,3,3,3,3,3,4,4,4,4,4
3,3,3,3,3,3,3,3,3,3,3,3,3,3,3,3,3,3,4,4,4,4,4
3,3,3,3,3,3,3,3,3,3,3,3,3,3,3,3,3,3,3,3,3,3,4
3,3,3,3,3,3,3,3,3,3,3,3,3,3,3,3,3,3,3,3,3,3,3
3,21,3,3,3,3,3,3,3,3,3,3,3,3,3,3,3,3,3,3,3,3,3
3,3,3,3,3,3,3,3,3,3,3,3,3,3,3,3,3,3,3,3,3,3,3
3,3,3,3,3,3,3,3,3,3,3,3,3,3,3,3,3,3,3,3,3,3,3
3,3,3,3,3,3,3,3,3,3,3,3,3,3,3,3,3,3,3,3,3,3,3
3,3,3,3,3,3,3,3,3,3,3,3,3,3,3,3,3,3,3,3,3,3,3
:endlayer

layer:
3,3,3,3,3,3,3,3,3,3,3,3,3,3,3,3,3,5,3,3,3,3,3
3,3,3,3,5,5,5,5,5,5,3,3,5,5,5,5,5,5,5,5,5,5,3
3,3,3,5,5,13,12,11,10,9,5,5,5,5,5,5,5,5,5,5,5,5,3
3,3,3,5,5,15,15,15,15,15,5,5,5,5,5,5,5,5,5,5,5,5,3
3,3,3,5,18,17,17,17,17,17,0,5,5,5,5,5,5,5,5,5,5,5,3
3,3,3,5,18,0,0,0,0,0,0,5,5,5,5,5,5,5,5,5,5,5,3
3,3,3,5,18,0,0,0,0,0,0,5,5,5,5,5,5,5,5,5,5,5,3
3,3,3,5,18,0,0,0,0,0,0,5,5,5,5,5,5,5,5,5,5,5,3
9,3,33,5,32,5,5,5,5,5,5,3,5,5,5,5,5,5,5,3,3,3,3
3,29,3,29,38,29,29,29,29,29,29,29,5,5,5,5,5,5,5,5,3,3,3
3,3,39,29,29,29,29,29,29,29,29,29,3,5,5,5,5,5,5,5,3,3,3
3,3,3,29,29,29,29,29,29,29,29,29,3,5,5,5,5,5,5,5,3,3,3
4,3,3,29,29,29,29,29,29,29,29,29,3,5,5,5,5,5,5,5,3,3,3
4,3,3,29,29,29,29,29,29,29,29,29,3,5,5,5,5,5,5,5,3,3,3
3,3,3,3,3,3,29,29,29,3,3,3,3,5,5,5,5,5,5,5,3,3,3
3,3,3,3,3,3,39,39,39,3,3,3,3,3,3,3,3,3,3,3,3,3,3
3,3,3,3,3,3,3,3,3,3,3,3,3,3,3,3,3,3,3,3,3,3,3
3,3,3,3,3,3,3,3,3,3,3,3,3,3,3,3,3,3,3,3,3,3,3
3,3,3,3,3,3,3,3,3,3,3,3,3,3,3,3,3,3,3,3,3,3,3
3,3,3,3,3,3,3,3,3,3,3,3,3,3,3,3,3,3,3,3,3,3,3
3,3,3,3,3,3,3,3,3,3,3,3,3,3,3,3,3,3,3,3,3,3,3
3,21,3,3,3,3,3,3,3,3,3,3,3,3,3,3,3,3,3,3,3,3,3
21,21,3,3,3,3,3,3,4,4,3,3,3,3,3,3,3,3,3,3,3,3,3
3,3,3,3,3,3,3,3,4,4,3,3,3,3,3,3,3,3,3,3,3,3,3
3,3,3,3,3,3,3,3,4,4,3,3,3,3,3,3,3,3,3,3,3,3,3
3,3,3,3,3,3,3,4,4,4,4,3,3,3,3,3,3,3,3,3,3,3,3
3,3,3,3,3,3,3,4,4,4,4,3,3,3,3,3,3,3,3,3,3,3,3
:endlayer

layer:
3,3,3,3,3,3,3,3,3,3,3,3,5,5,5,5,5,5,5,5,5,5,3
3,3,3,3,5,5,5,5,5,5,5,5,8,8,8,8,8,0,0,0,0,0,5
3,3,3,5,5,0,0,0,0,0,8,8,8,5,5,5,8,5,8,8,0,0,5
3,3,3,5,5,5,5,5,5,5,5,5,5,0,0,0,8,0,0,8,0,0,5
3,3,3,5,0,19,19,0,19,19,0,5,0,0,0,0,3,0,0,3,0,0,5
3,3,3,5,0,0,0,0,0,0,0,5,0,0,3,0,9,3,3,22,0,3,5
3,3,3,5,0,0,0,0,0,0,0,5,0,0,3,0,0,26,25,0,0,3,5
3,3,3,5,0,0,0,0,0,0,0,5,8,8,3,3,0,26,30,0,0,3,5
3,3,3,5,5,5,5,5,5,5,5,5,5,0,8,0,8,8,3,5,5,5,3
3,3,39,0,0,0,0,0,0,0,0,0,5,0,24,3,0,8,8,0,5,3,3
3,3,39,0,0,0,0,0,0,0,0,0,5,10,0,0,41,0,16,0,5,3,3
4,4,39,0,0,0,0,0,0,0,0,0,5,10,11,12,13,14,0,0,5,3,3
4,4,39,0,0,0,0,0,0,0,0,0,5,3,3,0,0,0,3,0,5,3,3
4,4,39,0,0,0,0,0,0,0,0,0,5,10,11,0,0,0,48,0,5,3,3
3,3,3,39,39,39,0,0,0,39,39,39,5,0,0,0,0,0,0,0,5,3,3
3,3,3,3,3,39,0,0,0,39,3,3,3,5,5,5,5,5,5,5,3,3,3
3,3,3,3,3,39,50,50,50,39,3,3,3,3,3,3,3,3,3,3,3,3,3
3,3,3,3,3,39,3,3,3,3,3,3,3,3,3,3,3,3,3,3,3,3,3
3,3,3,2,2,3,3,3,3,3,3,3,3,3,3,3,3,3,3,3,3,3,3
3,3,2,2,3,3,3,3,3,3,3,3,3,3,3,3,3,3,3,3,3,3,3
3,3,2,2,3,3,3,3,3,4,3,3,3,3,3,3,3,3,3,3,3,3,3
21,21,2,3,3,3,3,3,4,4,4,3,3,3,3,3,3,3,3,3,3,3,3
3,21,3,3,3,21,21,3,4,4,4,3,3,3,3,3,3,3,3,3,3,3,3
3,3,3,3,3,21,21,4,4,4,4,3,3,3,3,3,3,3,3,3,3,3,3
3,3,3,3,3,3,3,4,4,4,4,3,3,3,3,3,3,3,3,3,3,3,3
3,3,3,3,3,3,3,4,4,4,4,3,3,3,3,3,3,3,3,3,3,3,3
3,3,3,3,3,3,3,4,4,4,4,3,3,3,47,47,47,3,3,3,3,3,3
:endlayer

layer:
3,3,3,3,3,3,3,3,3,3,3,3,5,5,5,5,5,5,5,5,5,5,5
3,3,3,3,3,3,3,3,3,3,3,5,5,5,5,5,0,0,0,0,0,0,5
3,3,3,3,5,5,5,5,5,5,5,5,5,5,5,5,5,8,0,0,0,0,5
3,3,3,5,0,0,0,0,0,0,0,5,5,0,0,0,0,0,0,0,0,0,5
3,3,3,5,0,0,0,0,0,0,0,5,0,0,0,0,8,0,0,8,0,0,5
3,3,3,5,0,0,0,0,0,0,0,5,0,0,24,3,0,0,0,0,3,23,5
3,3,3,5,0,0,0,0,0,0,0,5,0,0,27,0,0,0,0,0,0,27,5
3,3,3,5,0,0,0,0,0,0,0,5,0,0,8,8,3,3,0,0,3,8,5
3,3,3,5,34,34,34,34,34,34,34,5,8,0,0,0,3,0,8,5,5,5,3
3,3,39,0,0,0,0,0,0,0,0,40,5,0,0,0,3,3,3,0,5,3,3
3,3,39,0,0,0,0,0,0,0,0,43,5,42,0,0,3,0,3,0,5,3,3
4,4,39,0,0,0,0,0,0,0,0,43,5,42,0,45,3,0,3,0,5,3,3
4,4,39,0,0,0,0,0,0,0,0,43,5,46,12,0,0,0,3,0,5,3,3
4,4,39,0,0,0,0,0,0,0,0,43,5,42,0,0,0,0,3,0,5,47,3
3,3,3,39,39,39,0,0,0,39,39,39,5,0,0,0,0,0,0,0,5,3,3
3,3,3,3,3,39,0,0,0,39,3,3,3,5,5,5,5,5,5,5,3,3,3
3,3,3,2,2,39,0,0,0,39,3,3,3,3,3,3,3,3,3,3,3,3,3
3,3,2,2,2,39,50,50,50,39,3,3,3,3,3,3,3,3,3,3,3,3,3
3,2,2,2,2,2,3,3,3,3,3,3,3,3,3,3,3,3,3,3,3,3,3
3,2,2,2,2,3,3,3,3,3,3,3,3,3,3,3,3,3,3,3,3,3,3
3,2,2,2,2,3,3,3,3,4,3,3,3,3,3,3,3,3,3,3,3,3,3
2,2,2,2,2,3,3,3,4,4,4,3,3,3,3,3,3,3,3,3,3,3,3
3,2,2,2,3,3,3,3,4,4,4,3,3,3,3,3,3,3,3,3,3,3,3
3,2,3,3,3,3,3,4,4,4,4,3,3,3,3,3,3,3,3,3,3,3,3
3,3,3,3,3,3,3,4,4,4,4,3,3,3,3,3,3,3,3,3,3,3,3
3,3,3,3,3,3,3,4,4,4,4,3,3,3,3,3,3,3,3,3,3,3,3
3,3,3,3,3,3,3,4,4,4,4,3,3,3,47,47,3,3,3,3,3,3,3
:endlayer

layer:
3,3,3,3,3,3,3,3,3,3,3,3,3,3,5,5,5,5,5,5,5,5,3
3,3,3,3,3,3,3,3,3,3,3,3,3,5,0,0,0,0,0,0,0,0,5
3,3,3,3,5,5,5,5,5,5,5,5,8,8,14,8,8,0,0,0,0,0,5
3,3,3,5,0,0,0,5,5,5,5,8,8,0,0,0,0,0,0,0,0,0,5
3,3,3,5,0,0,5,0,5,5,5,5,0,0,0,0,0,0,0,0,0,0,5
3,3,3,5,0,0,0,5,5,5,5,5,0,0,0,0,0,0,0,0,0,0,5
3,3,3,5,0,0,0,0,0,0,0,5,0,0,0,0,0,0,0,0,0,0,5
3,3,3,5,0,0,0,0,0,0,0,5,0,0,0,0,8,8,3,3,8,0,5
3,3,3,5,5,5,5,5,5,5,5,5,0,0,0,0,8,0,5,5,5,5,3
3,3,39,0,0,0,0,0,0,0,0,0,5,0,0,0,8,8,8,0,5,3,3
3,3,39,0,0,0,0,0,0,0,0,0,5,0,0,0,44,0,8,0,5,3,3
3,3,39,0,0,0,0,0,0,0,0,0,5,0,0,0,8,0,8,0,5,5,3
4,3,39,0,0,0,0,0,0,0,0,0,5,0,0,0,0,0,8,0,5,3,3
4,3,39,0,0,0,0,0,0,0,0,0,5,0,0,0,0,0,8,0,5,3,3
47,3,3,39,39,39,0,0,0,39,39,39,5,0,0,0,0,0,0,0,5,3,3
3,3,3,3,3,39,0,0,0,39,3,3,3,5,5,5,5,5,5,5,3,3,3
3,3,3,2,2,39,0,0,0,39,3,3,3,3,3,3,3,3,3,3,3,3,3
3,3,2,2,2,39,0,0,0,39,3,3,3,3,3,3,3,3,3,3,3,3,3
3,2,2,2,2,39,50,50,50,39,3,3,3,3,3,3,3,3,3,3,3,3,3
3,2,2,2,2,3,3,3,3,3,3,3,3,3,3,3,3,3,3,3,3,3,3
2,2,2,2,2,3,3,3,3,3,3,3,3,3,3,3,3,3,3,3,3,3,3
2,2,2,2,2,3,3,3,3,3,3,3,3,3,3,3,3,3,3,3,3,3,3
2,2,2,2,3,3,3,3,4,4,3,3,3,3,3,3,3,3,3,3,3,3,3
2,2,2,3,3,3,3,3,4,4,3,3,3,3,3,3,3,3,3,3,3,3,3
2,2,3,3,3,3,3,3,4,4,3,3,3,3,3,3,3,3,3,3,3,3,3
3,3,3,3,3,3,3,4,4,4,4,3,3,3,3,3,3,3,3,3,3,3,3
3,3,3,3,3,3,3,4,4,4,4,3,3,3,3,3,3,3,3,3,3,3,3
:endlayer

layer:
3,3,3,3,3,3,3,3,3,3,3,3,3,3,4,4,4,5,3,3,3,3,3
3,3,3,3,3,3,3,3,3,3,3,3,3,3,5,5,5,5,5,5,5,5,3
3,3,3,3,3,3,3,5,5,5,5,5,5,5,5,5,5,5,5,5,5,5,3
3,3,3,5,5,5,5,5,5,8,8,0,5,5,5,5,5,5,5,5,5,5,3
3,3,3,5,0,0,5,20,14,8,5,5,0,5,5,5,5,5,5,5,5,5,3
3,3,3,5,0,0,0,5,5,5,5,5,5,5,5,5,5,5,5,5,5,5,3
3,3,3,5,0,0,0,0,0,0,0,5,5,5,5,5,5,0,0,0,0,5,3
3,3,3,5,0,0,0,0,0,0,0,5,5,5,5,5,0,0,8,8,0,5,3
3,3,3,5,5,5,5,5,5,5,5,5,5,5,5,5,5,5,5,5,5,3,3
3,3,39,0,0,0,0,0,0,0,0,0,5,5,5,5,5,5,5,5,3,3,3
3,3,39,0,0,0,0,0,0,0,0,0,5,5,5,5,5,5,5,5,3,3,3
3,3,39,0,0,0,0,0,0,0,0,0,5,5,5,5,5,5,5,5,3,3,3
47,3,39,0,0,0,0,0,0,0,0,0,5,5,5,5,5,5,5,5,3,3,3
47,47,39,0,0,0,0,0,0,0,0,0,5,5,5,5,5,5,5,5,3,3,3
47,47,47,39,39,39,39,39,39,39,39,39,39,5,5,5,5,5,5,5,3,3,3
3,47,47,3,3,39,49,49,49,39,3,3,3,3,3,3,3,3,3,3,3,3,3
3,3,3,3,3,39,0,0,0,39,3,3,3,3,3,3,3,3,3,3,3,3,3
3,3,2,2,2,39,0,0,0,39,3,3,3,3,3,47,3,3,3,3,3,3,3
3,2,2,2,2,39,0,0,0,39,3,3,3,3,3,47,3,3,3,3,3,3,3
3,2,2,2,2,39,50,50,50,39,3,3,3,3,3,3,3,3,3,3,3,3,3
3,2,2,2,2,21,2,2,3,3,3,3,3,3,3,3,3,3,3,3,3,3,3
2,2,2,2,2,3,2,2,3,3,3,3,3,3,3,3,3,3,3,3,3,3,3
2,2,2,2,3,3,2,2,3,3,3,3,3,3,3,3,3,3,3,3,3,3,3
2,2,2,3,3,3,3,3,3,3,3,4,3,3,3,3,21,3,3,3,3,3,3
2,2,3,3,3,3,3,3,3,4,4,4,4,3,3,3,3,3,3,3,3,3,3
3,3,3,3,3,3,3,3,4,4,4,4,3,3,3,3,3,3,3,3,3,3,3
3,3,3,3,4,3,3,3,4,4,4,2,2,3,3,3,3,3,3,3,21,3,3
:endlayer

layer:
3,3,3,3,3,3,3,3,3,3,3,3,3,3,3,4,4,4,4,3,3,3,3
3,3,3,3,3,3,3,5,5,5,5,3,3,3,3,4,4,3,3,3,3,3,3
3,3,3,3,3,3,5,8,8,8,5,5,5,3,3,3,3,3,3,3,3,3,3
3,3,3,3,3,3,5,16,5,0,0,5,5,3,3,3,3,3,3,3,3,3,3
3,3,3,3,5,5,5,20,5,5,0,5,5,3,3,3,21,21,3,3,3,3,3
3,3,3,3,5,5,5,5,5,5,5,3,3,3,3,3,21,21,3,3,3,3,3
3,3,3,3,5,5,5,5,5,5,5,3,3,3,3,3,5,5,5,5,5,3,3
3,3,3,3,5,5,5,5,5,5,5,3,3,3,3,3,5,5,5,5,5,3,3
3,3,3,3,3,3,3,3,3,3,3,3,3,3,3,3,3,3,3,3,21,3,3
3,3,3,39,39,39,39,39,39,39,39,39,39,3,3,3,3,3,3,21,21,3,3
3,3,3,39,39,39,39,39,39,39,39,39,39,3,3,3,3,3,3,3,3,3,3
3,3,3,39,39,39,39,39,39,39,39,39,39,3,3,3,3,3,3,3,3,3,3
3,3,3,39,39,39,39,39,39,39,39,39,3,3,3,3,3,3,3,3,3,3,3
47,3,3,39,39,39,39,39,39,39,39,39,3,3,3,3,3,3,3,3,3,3,3
3,47,47,3,3,3,3,3,3,39,3,3,3,3,3,3,3,3,3,3,3,3,3
3,3,47,3,3,3,39,39,39,39,3,3,3,3,3,3,3,3,3,3,3,3,3
3,3,3,3,3,39,49,49,49,39,3,3,3,3,3,3,3,3,3,3,3,3,3
3,3,3,3,3,39,0,0,0,39,3,3,3,0,47,47,3,3,3,3,3,3,3
3,3,3,3,3,39,0,0,0,39,3,3,3,3,47,47,3,3,3,3,3,3,3
3,3,2,2,3,39,0,0,0,39,3,3,3,3,47,47,3,3,3,3,3,3,3
3,2,2,2,21,39,50,50,50,39,3,3,3,3,47,47,3,3,3,3,3,3,3
3,2,2,2,21,2,2,2,2,3,3,3,3,3,3,3,3,3,3,3,3,3,3
3,2,2,3,3,2,2,2,2,3,3,4,4,3,3,3,3,3,3,3,3,3,3
3,3,3,3,3,2,2,2,3,4,4,4,4,4,3,21,21,3,3,3,3,3,3
3,3,3,3,3,2,2,2,4,4,4,4,4,4,3,21,21,3,3,3,3,3,3
3,3,3,3,4,4,2,2,4,4,4,4,4,4,3,3,3,3,3,3,21,21,3
3,3,4,4,4,4,3,4,4,4,4,4,2,2,2,3,3,3,3,3,21,21,3
:endlayer

layer:
3,3,3,3,3,3,3,3,3,3,3,3,3,3,3,3,3,3,3,3,3,3,3
3,3,3,3,3,3,3,3,3,3,3,3,3,3,3,3,3,3,3,3,3,3,3
3,3,3,3,3,3,3,5,5,5,5,3,3,3,3,3,3,3,3,3,3,3,3
3,3,3,3,3,3,3,5,5,5,5,3,3,3,3,3,3,3,3,3,3,3,3
3,3,3,3,3,3,3,5,5,5,5,3,3,3,3,3,3,21,3,3,3,3,3
3,3,3,3,3,3,3,3,3,3,3,3,3,3,3,3,3,3,3,3,3,3,3
3,3,3,3,3,3,3,3,3,3,3,3,3,3,3,3,3,3,3,3,3,3,3
3,3,3,3,3,3,3,3,3,3,3,3,3,3,3,3,3,3,3,3,3,3,3
3,3,3,3,3,3,3,3,3,3,3,3,3,3,3,3,3,3,3,3,3,3,3
3,3,3,3,3,3,3,3,0,3,3,3,3,3,3,3,3,3,3,3,21,3,3
3,3,3,3,3,3,3,3,3,3,3,0,3,3,3,3,3,3,3,3,3,3,3
3,3,3,3,3,3,3,3,3,3,3,3,3,3,3,3,3,3,3,3,3,3,3
3,3,3,3,3,3,3,3,3,3,3,3,3,3,3,3,3,3,3,3,3,3,3
3,3,3,3,3,3,3,3,3,3,3,3,3,3,3,3,3,3,3,3,3,3,3
3,3,3,3,3,3,3,3,3,3,3,3,3,3,3,3,3,3,3,3,3,3,3
3,3,3,3,3,3,3,3,3,39,3,3,3,3,3,3,3,3,3,3,3,3,3
3,3,3,3,3,3,39,3,3,39,3,3,3,3,3,3,3,3,3,3,3,3,3
3,3,3,3,3,39,49,49,49,39,3,3,3,3,3,3,3,3,3,3,3,3,3
3,3,3,3,3,39,0,0,0,39,3,3,3,3,3,3,3,3,3,3,3,3,3
3,3,3,3,3,39,0,0,0,39,3,3,3,3,47,47,3,3,3,3,3,3,3
3,3,3,3,3,39,0,0,0,39,3,3,3,3,47,47,3,3,3,3,3,3,3
3,3,3,3,21,39,50,50,50,39,3,3,3,4,4,3,3,3,3,3,3,3,3
3,3,3,3,3,2,2,2,2,3,4,4,4,4,4,3,3,3,3,3,3,3,3
3,3,3,3,3,2,2,2,2,4,4,4,4,4,4,21,21,3,3,3,3,3,3
3,3,3,3,3,2,2,2,4,4,4,4,4,4,3,21,21,3,3,3,3,3,3
3,3,3,3,4,4,2,4,4,4,4,4,4,4,3,3,3,3,3,3,3,21,3
3,4,4,4,4,4,3,4,4,4,4,4,4,2,2,3,3,3,3,3,3,3,3
:endlayer

layer:
3,3,3,3,3,3,3,3,3,3,3,3,3,3,3,3,3,3,3,3,3,3,3
3,3,3,3,3,3,3,3,3,3,3,3,3,3,3,3,3,3,3,3,3,3,3
3,3,3,3,3,3,3,3,3,3,3,3,3,3,3,3,3,3,3,3,3,3,3
3,3,3,3,3,3,3,3,3,3,3,3,3,3,3,3,3,3,3,3,3,3,3
3,3,3,3,3,3,3,3,3,3,3,3,3,3,3,3,3,3,3,3,3,3,3
3,3,3,3,3,3,3,3,3,3,3,3,3,3,3,3,3,3,3,3,3,3,3
3,3,3,3,3,3,3,3,3,3,3,3,3,3,3,3,3,3,3,3,3,3,3
3,3,3,3,3,3,3,3,3,3,3,3,3,3,3,3,3,3,3,3,3,3,3
3,3,3,3,3,3,3,3,3,3,3,3,3,3,3,3,3,3,3,3,3,3,3
3,3,3,3,3,3,3,3,3,3,3,3,3,3,3,3,3,3,3,3,3,3,3
3,3,3,3,3,3,3,3,3,3,3,3,3,3,3,3,3,3,3,3,3,3,3
3,3,3,3,3,3,3,3,3,3,3,3,3,3,3,3,3,3,3,3,3,3,3
3,3,3,3,3,3,3,3,3,3,3,3,3,3,3,3,3,3,3,3,3,3,3
3,3,3,3,3,3,3,3,3,3,3,3,3,3,3,3,3,3,3,3,3,3,3
3,3,3,3,3,3,3,3,3,3,3,21,21,3,3,3,3,3,3,3,3,3,3
3,3,3,3,3,3,3,3,3,3,3,21,21,3,3,3,3,3,3,3,3,3,3
3,3,3,3,3,3,3,3,3,3,3,3,3,3,3,3,3,3,3,3,3,3,3
3,3,3,3,3,3,3,3,3,39,3,3,3,3,3,3,3,3,3,3,3,3,3
3,3,3,3,3,39,49,49,49,39,3,3,3,3,3,3,3,3,3,3,3,3,3
3,3,3,3,3,39,0,0,0,39,3,3,3,3,3,3,3,3,3,3,3,3,3
3,3,3,3,3,39,0,0,0,39,3,3,3,3,3,3,3,3,3,3,3,3,3
3,3,3,3,3,39,0,0,0,39,3,3,3,4,3,3,3,3,3,3,3,3,3
3,3,3,3,3,39,50,50,50,39,3,4,4,4,4,3,3,3,3,3,3,3,3
3,3,3,3,3,3,2,2,3,4,4,4,4,4,4,3,3,3,3,3,3,3,3
3,3,3,3,3,3,2,3,3,4,4,4,4,4,3,21,3,3,3,2,2,3,3
3,3,3,3,3,3,3,3,4,4,4,4,4,4,3,3,3,3,3,2,2,3,3
3,3,4,4,4,4,3,4,4,4,4,4,3,3,3,3,3,3,2,3,3,3,3
:endlayer

layer:
4,4,4,4,4,4,4,4,4,4,4,4,4,4,4,4,4,4,4,4,4,4,4
4,4,4,4,4,4,4,4,4,4,4,4,4,4,4,4,4,4,4,4,4,4,4
4,4,4,4,4,4,4,4,4,4,4,4,4,4,4,4,4,4,4,4,4,4,4
4,4,4,4,4,4,4,4,4,4,4,4,4,4,4,4,4,4,4,4,4,4,4
4,4,4,4,4,4,4,4,4,4,4,4,4,4,4,4,4,4,4,4,4,4,4
4,4,4,4,4,4,4,4,4,4,4,4,4,4,4,4,4,4,4,4,4,4,4
4,4,4,4,4,4,4,4,4,4,4,4,4,4,4,4,4,4,4,4,4,4,4
4,4,4,4,4,4,4,4,4,4,4,4,4,4,4,4,4,4,4,4,4,4,4
4,4,4,4,4,4,4,4,4,4,4,4,4,4,4,4,4,4,4,4,4,3,3
4,4,4,4,4,4,4,4,4,4,4,4,4,4,4,4,4,4,4,4,4,4,4
4,4,4,4,4,4,4,4,4,4,4,4,4,4,4,4,4,4,4,4,4,4,4
4,4,4,4,4,4,4,4,4,4,4,4,4,4,4,4,4,4,4,4,4,4,4
4,4,4,4,4,4,4,4,4,4,4,4,4,4,4,4,4,4,4,4,4,4,4
4,4,4,4,4,4,4,4,4,4,4,4,4,4,4,4,4,4,4,4,4,4,4
4,4,4,4,4,4,4,4,4,4,4,4,4,4,4,4,4,4,4,4,4,4,4
4,4,4,4,4,4,4,4,4,4,4,4,4,4,4,4,4,4,4,4,4,4,4
4,4,4,4,4,4,4,4,4,4,4,4,4,4,4,4,4,4,4,4,4,4,4
4,4,4,4,4,4,4,4,4,4,4,4,4,4,4,4,4,4,4,4,4,4,4
4,4,4,4,4,4,39,39,4,39,4,4,4,4,4,4,4,4,4,4,4,4,4
4,4,4,4,4,39,49,49,49,39,4,4,4,4,4,4,4,4,4,4,4,4,4
4,4,4,4,4,39,0,0,0,39,4,4,4,4,4,4,4,4,4,4,4,4,4
4,4,4,4,4,39,0,0,0,39,4,4,4,4,4,4,4,4,4,4,4,4,4
4,4,4,4,4,39,0,0,0,39,4,4,4,4,4,4,4,4,4,4,4,4,4
4,4,4,4,4,39,50,50,50,39,4,4,4,4,4,4,4,4,4,4,4,4,4
4,4,4,4,4,4,4,4,4,39,4,4,4,4,4,4,4,4,4,4,4,4,4
4,4,4,4,4,4,4,4,4,4,4,4,4,4,4,4,4,4,4,4,4,4,4
4,4,4,4,4,4,4,4,4,4,4,4,4,4,4,4,4,4,4,4,4,4,4
:endlayer

layer:
4,4,4,4,4,4,4,4,4,4,4,4,4,4,4,4,4,4,4,4,4,4,4
4,4,4,4,4,4,4,4,4,4,4,4,4,4,4,4,4,4,4,4,4,4,4
4,4,4,4,4,4,4,4,4,4,4,4,4,4,4,4,4,4,4,4,4,4,4
4,4,4,4,4,4,4,4,4,4,4,4,4,4,4,4,4,4,4,4,4,4,4
4,4,4,4,4,4,4,4,4,4,4,4,4,4,4,4,4,4,4,4,4,4,4
4,4,4,4,4,4,4,4,4,4,4,4,4,4,4,4,4,4,4,4,4,4,4
4,4,4,4,4,4,4,4,4,4,4,4,4,4,4,4,4,4,4,4,4,4,4
4,4,4,4,4,4,4,4,4,4,4,4,4,4,4,4,4,4,4,4,4,4,4
4,4,4,4,4,4,4,4,4,4,4,4,4,4,4,4,4,4,4,4,4,4,3
4,4,4,4,4,4,4,4,4,4,4,4,4,4,4,4,4,4,4,4,4,4,4
4,4,4,4,4,4,4,4,4,4,4,4,4,4,4,4,4,4,4,4,4,4,4
4,4,4,4,4,4,4,4,4,4,4,4,4,4,4,4,4,4,4,4,4,4,4
4,4,4,4,4,4,4,4,4,4,4,4,4,4,4,4,4,4,4,4,4,4,4
4,4,4,4,4,4,4,4,4,4,4,4,4,4,4,4,4,4,4,4,4,4,4
4,4,4,4,4,4,4,4,4,4,4,4,4,4,4,4,4,4,4,4,4,4,4
4,4,4,4,4,4,4,4,4,4,4,4,4,4,4,4,4,4,4,4,4,4,4
4,4,4,4,4,4,4,4,4,4,4,4,4,4,4,4,4,4,4,4,4,4,4
4,4,4,4,4,4,4,4,4,4,4,4,4,4,4,4,4,4,4,4,4,4,4
4,4,4,4,4,4,4,4,4,4,4,4,4,4,4,4,4,4,4,4,4,4,4
4,4,4,4,4,4,4,4,4,4,4,4,4,4,4,4,4,4,4,4,4,4,4
4,4,4,4,4,39,49,49,49,39,4,4,4,4,4,4,4,4,4,4,4,4,4
4,4,4,4,4,39,0,0,0,39,4,4,4,4,4,4,4,4,4,4,4,4,4
4,4,4,4,4,39,0,0,0,39,4,4,4,4,4,4,4,4,4,4,4,4,4
4,4,4,4,4,39,0,0,0,39,4,4,4,4,4,4,4,4,4,4,4,4,4
4,4,4,4,4,39,50,50,50,39,4,4,4,4,4,4,4,4,4,4,4,4,4
4,4,4,4,4,4,4,4,4,4,4,4,4,4,4,4,4,4,4,4,4,4,4
4,4,4,4,4,4,4,4,4,4,4,4,4,4,4,4,4,4,4,4,4,4,4
:endlayer

layer:
4,4,4,4,4,4,4,4,4,4,4,4,4,4,4,4,4,4,4,4,4,4,4
4,4,4,4,4,4,4,4,4,4,4,4,4,4,4,4,4,4,4,4,4,4,4
4,4,4,4,4,4,4,4,4,4,4,4,4,4,4,4,4,4,4,4,4,4,4
4,4,4,4,4,4,4,4,4,4,4,4,4,4,4,4,4,4,4,4,4,4,4
4,4,4,4,4,4,4,4,4,4,4,4,4,4,4,4,4,4,4,4,4,4,4
4,4,4,4,4,4,4,4,4,4,4,4,4,4,4,4,4,4,4,4,4,4,4
4,4,4,4,4,4,4,4,4,4,4,4,4,4,4,4,4,4,4,4,4,4,4
4,4,4,4,4,4,4,4,4,4,4,4,4,4,4,4,4,4,4,4,4,4,4
4,4,4,4,4,4,4,4,4,4,4,4,4,4,4,4,4,4,4,4,4,4,4
4,4,4,4,4,4,4,4,4,4,4,4,4,4,4,4,4,4,4,4,4,4,4
4,4,4,4,4,4,4,4,4,4,4,4,4,4,4,4,4,4,4,4,4,4,4
4,4,4,4,4,4,4,4,4,4,4,4,4,4,4,4,4,4,4,4,4,4,4
4,4,4,4,4,4,4,4,4,4,4,4,4,4,4,4,4,4,4,4,4,4,4
4,4,4,4,4,4,4,4,4,4,4,4,4,4,4,4,4,4,4,4,4,4,4
4,4,4,4,4,4,4,4,4,4,4,4,4,4,4,4,4,4,4,4,4,4,4
4,4,4,4,4,4,4,4,4,4,4,4,4,4,4,4,4,4,4,4,4,4,4
4,4,4,4,4,4,4,4,4,4,4,4,4,4,4,4,4,4,4,4,4,4,4
4,4,4,4,4,4,4,4,4,4,4,4,4,4,4,4,4,4,4,4,4,4,4
4,4,4,4,4,4,4,4,4,4,4,4,4,4,4,4,4,4,4,4,4,4,4
4,4,4,4,4,4,4,4,4,4,4,4,4,4,4,4,4,4,4,4,4,4,4
4,4,4,4,4,4,4,4,4,4,4,4,4,4,4,4,4,4,4,4,4,4,4
4,4,4,4,4,39,49,49,49,39,4,4,4,4,4,4,4,4,4,4,4,4,4
4,4,4,4,4,39,0,0,0,39,4,4,4,4,4,4,4,4,4,4,4,4,4
4,4,4,4,4,39,0,0,0,39,4,4,4,4,4,4,4,4,4,4,4,4,4
4,4,4,4,4,39,0,0,0,39,4,4,4,4,4,4,4,4,4,4,4,4,4
4,4,4,4,4,39,50,50,50,39,4,4,4,4,4,4,4,4,4,4,4,4,4
4,4,4,4,4,4,4,4,4,4,4,4,4,4,4,4,4,4,4,4,4,4,4
:endlayer

layer:
6,6,6,6,6,6,6,6,6,6,6,6,6,6,6,6,6,6,6,6,6,6,6
6,6,6,6,6,6,6,6,6,6,6,6,6,6,6,6,6,6,6,6,6,6,6
6,6,6,6,6,6,6,6,6,6,6,6,6,6,6,6,6,6,6,6,6,6,6
6,6,6,6,6,6,6,6,6,6,6,6,6,6,6,6,6,6,6,6,6,6,6
6,6,6,6,6,6,6,6,6,6,6,6,6,6,6,6,6,6,6,6,6,6,6
6,6,6,6,6,6,6,6,6,6,6,6,6,6,6,6,6,6,6,6,6,6,6
6,6,6,6,6,6,6,6,6,6,6,6,6,6,6,6,6,6,6,6,6,6,6
6,6,6,6,6,6,6,6,6,6,6,6,6,6,6,6,6,6,6,6,6,6,6
6,6,6,6,6,6,6,6,6,6,6,6,6,6,6,6,6,6,6,6,6,6,6
6,6,6,6,6,6,6,6,6,6,6,6,6,6,6,6,6,6,6,6,6,6,6
6,6,6,6,6,6,6,6,6,6,6,6,6,6,6,6,6,6,6,6,6,6,6
6,6,6,6,6,6,6,6,6,6,6,6,6,6,6,6,6,6,6,6,6,6,6
6,6,6,6,6,6,6,6,6,6,6,6,6,6,6,6,6,6,6,6,6,6,6
6,6,6,6,6,6,6,6,6,6,6,6,6,6,6,6,6,6,6,6,6,6,6
6,6,6,6,6,6,6,6,6,6,6,6,6,6,6,6,6,6,6,6,6,6,6
6,6,6,6,6,6,6,6,6,6,6,6,6,6,6,6,6,6,6,6,6,6,6
6,6,6,6,6,6,6,6,6,6,6,6,6,6,6,6,6,6,6,6,6,6,6
6,6,6,6,6,6,6,6,6,6,6,6,6,6,6,6,6,6,6,6,6,6,6
6,6,6,6,6,6,6,6,6,6,6,6,6,6,6,6,6,6,6,6,6,6,6
6,6,6,6,6,6,6,6,6,6,6,6,6,6,6,6,6,6,6,6,6,6,6
6,6,6,6,6,6,6,6,6,6,6,6,6,6,6,6,6,6,6,6,6,6,6
6,6,6,6,6,39,39,39,39,39,6,6,6,6,6,6,6,6,6,6,6,6,6
6,6,6,6,6,39,0,0,0,39,6,6,6,6,6,6,6,6,6,6,6,6,6
6,6,6,6,6,39,0,0,0,39,6,6,6,6,6,6,6,6,6,6,6,6,6
6,6,6,6,6,39,0,0,0,39,6,6,6,6,6,6,6,6,6,6,6,6,6
6,6,6,6,6,39,0,0,0,39,6,6,6,6,6,6,6,6,6,6,6,6,6
6,6,6,6,6,39,50,50,50,39,6,6,6,6,6,6,6,6,6,6,6,6,6
:endlayer

####INVENTORIES####


