# Ancient Warfare Structure Template File
# auto-generated structure file. created on: 7/19/2013 at: 19:53:48
# Lines beginning with # denote comments
# original structure by Me2005, modified to add gates/npcs/loot

survival=false
validTargetblocks=1,2,3,12,13

underground=false
undergroundMinLevel=1
undergroundMaxLevel=236
undergroundMaxAirAbove=0
minSubmergedDepth=0
maxWaterDepth=0
maxLavaDepth=0
fillType=1

xSize=15
ySize=19
zSize=13

verticalOffset=1
xOffset=7
zOffset=0

maxOverhang=0
maxLeveling=0
levelingBuffer=0
maxVerticalClear=1
clearingBuffer=0
preserveWater=false
preserveLava=false
preservePlants=false
preserveBlocks=false

####BLOCK RULES####
rule:
number=0
order=0
conditional=0
percent=100
blocks=0-0
:endrule

rule:
number=2
order=0
conditional=0
percent=100
blocks=2-0
inventory=0
:endrule

rule:
number=3
order=0
conditional=0
percent=100
blocks=109-6
inventory=0
:endrule

rule:
number=4
order=0
conditional=0
percent=100
blocks=44-13
inventory=0
:endrule

rule:
number=5
order=0
conditional=0
percent=100
blocks=98-0
inventory=0
:endrule

rule:
number=6
order=0
conditional=0
percent=100
blocks=43-5
inventory=0
:endrule

rule:
number=7
order=0
conditional=0
percent=100
blocks=133-0
inventory=0
:endrule

rule:
number=8
order=0
conditional=0
percent=100
blocks=44-5
inventory=0
:endrule

rule:
number=9
order=0
conditional=0
percent=100
blocks=109-3
inventory=0
:endrule

rule:
number=10
order=0
conditional=0
percent=100
blocks=109-5
inventory=0
:endrule

rule:
number=11
order=0
conditional=0
percent=100
blocks=43-0
inventory=0
:endrule

rule:
number=12
order=0
conditional=0
percent=100
blocks=109-4
inventory=0
:endrule

rule:
number=13
order=1
conditional=0
percent=100
blocks=50-2
inventory=0
:endrule

rule:
number=14
order=1
conditional=0
percent=100
blocks=50-1
inventory=0
:endrule

rule:
number=15
order=0
conditional=0
percent=100
blocks=54-4
inventory=0
lootlevel=0
:endrule

rule:
number=17
order=0
conditional=0
percent=100
blocks=125-0
inventory=0
:endrule

rule:
number=16
order=0
conditional=0
percent=100
blocks=54-5
lootlevel=0
inventory=0
:endrule

rule:
number=19
order=0
conditional=0
percent=100
blocks=53-3
inventory=0
:endrule

rule:
number=18
order=0
conditional=0
percent=100
blocks=126-0
inventory=0
:endrule

rule:
number=21
order=1
conditional=0
percent=100
blocks=50-3
inventory=0
:endrule

rule:
number=20
order=0
conditional=0
percent=100
blocks=53-1
inventory=0
:endrule

rule:
number=23
order=1
conditional=0
percent=100
blocks=64-7
inventory=0
:endrule

rule:
number=22
order=0
conditional=0
percent=100
blocks=1-0
inventory=0
:endrule

rule:
number=25
order=1
conditional=0
percent=100
blocks=64-8
inventory=0
:endrule

rule:
number=24
order=1
conditional=0
percent=100
blocks=64-2
inventory=0
:endrule

rule:
number=27
order=0
conditional=0
percent=100
blocks=44-0
inventory=0
:endrule

rule:
number=26
order=0
conditional=0
percent=100
blocks=44-8
inventory=0
:endrule

rule:
number=29
order=0
conditional=0
percent=100
blocks=72-0
inventory=0
:endrule

rule:
number=28
order=0
conditional=0
percent=100
blocks=109-0
inventory=0
:endrule

rule:
number=31
order=0
conditional=0
percent=100
blocks=109-1
inventory=0
:endrule

rule:
number=30
order=1
conditional=0
percent=100
blocks=71-0
inventory=0
:endrule

rule:
number=34
order=0
conditional=0
percent=100
blocks=53-0
inventory=0
:endrule

rule:
number=35
order=0
conditional=0
percent=100
blocks=109-7
inventory=0
:endrule

rule:
number=32
order=1
conditional=0
percent=100
blocks=71-8
inventory=0
:endrule

rule:
number=33
order=0
conditional=0
percent=100
blocks=53-2
inventory=0
:endrule

rule:
number=38
order=1
conditional=0
percent=100
blocks=69-2
inventory=0
:endrule

rule:
number=39
order=0
conditional=0
percent=100
blocks=77-1
inventory=0
:endrule

rule:
number=36
order=1
conditional=0
percent=100
blocks=50-4
inventory=0
:endrule

rule:
number=37
order=1
conditional=0
percent=100
blocks=64-0
inventory=0
:endrule

rule:
number=40
order=0
conditional=0
percent=100
blocks=77-3
inventory=0
:endrule

rule:
number=41
order=0
conditional=0
percent=100
blocks=109-2
inventory=0
:endrule


####SWAP RULESS####

####VEHICLE RULES####

####NPC RULES####

npc:
type=7
rank=0
team=17
bx=7
by=1
bz=5
ox=0.42606258
oy=0.0
oz=0.03490305
rotation=214.4997
pitch=0.0
:endnpc


npc:
type=2
rank=0
team=17
bx=9
by=1
bz=6
ox=0.026676655
oy=0.0
oz=0.59894943
rotation=165.44983
pitch=0.0
:endnpc


npc:
type=2
rank=0
team=17
bx=5
by=1
bz=6
ox=0.5
oy=0.0
oz=0.5
rotation=185.09988
pitch=0.0
:endnpc


npc:
type=2
rank=0
team=17
bx=7
by=1
bz=10
ox=0.8343334
oy=0.0
oz=0.83281326
rotation=183.90005
pitch=0.0
:endnpc


npc:
type=2
rank=0
team=17
bx=6
by=10
bz=5
ox=0.1397295
oy=0.5
oz=0.9234185
rotation=186.00008
pitch=0.0
:endnpc


npc:
type=3
rank=0
team=17
bx=8
by=10
bz=8
ox=0.5
oy=0.5
oz=0.5
rotation=172.50009
pitch=0.0
:endnpc


npc:
type=3
rank=0
team=17
bx=6
by=10
bz=4
ox=0.5
oy=0.5
oz=0.5
rotation=241.20009
pitch=0.0
:endnpc


npc:
type=3
rank=0
team=17
bx=6
by=6
bz=4
ox=0.1544218
oy=0.0
oz=0.22365522
rotation=353.55008
pitch=0.0
:endnpc


npc:
type=3
rank=0
team=17
bx=8
by=6
bz=4
ox=0.5
oy=0.0
oz=0.5
rotation=396.45007
pitch=0.0
:endnpc


npc:
type=3
rank=0
team=17
bx=8
by=6
bz=7
ox=0.02933979
oy=0.0
oz=0.7735052
rotation=481.95007
pitch=0.0
:endnpc


npc:
type=3
rank=0
team=17
bx=6
by=6
bz=8
ox=0.58953285
oy=0.0
oz=0.5865669
rotation=519.60004
pitch=0.0
:endnpc

####CIVIC RULES####

####GATE RULES####

gate:
pos1=8,1,9
pos2=6,3,9
team=17
type=1
facing=0
:endgate


####ENTITY RULES####

####RESOURCE LIST####
resources:
3-0,74
109-0,59
44-5,198
98-0,950
44-0,315
50-0,30
54-0,4
126-0,20
53-0,25
1-0,39
324-0,4
77-0,2
69-0,1
72-0,2
330-0,1
133-0,1
:endresources

####LAYERS####

layer:
2,2,2,2,2,2,2,2,2,2,2,2,2,2,2
2,5,5,5,5,2,2,2,2,2,5,5,5,5,2
2,5,11,5,5,5,5,5,5,5,5,11,11,5,2
2,5,11,11,22,22,22,22,22,22,22,11,11,5,2
2,5,5,22,11,11,11,11,11,11,11,22,5,5,2
2,2,2,5,11,11,11,11,11,11,11,5,2,2,2
2,2,2,5,11,11,11,11,11,11,11,5,2,2,2
2,2,2,5,11,11,11,11,11,11,11,5,2,2,2
2,5,5,22,22,22,22,22,22,22,22,22,5,5,2
2,5,11,11,5,22,22,22,22,22,5,11,11,5,2
2,5,11,11,5,22,22,22,22,22,5,11,11,5,2
2,5,5,5,5,2,2,2,2,2,5,5,5,5,2
2,2,2,2,2,2,2,2,2,2,2,2,2,2,2
:endlayer

layer:
0,0,0,0,0,0,0,0,0,0,0,0,0,0,0
0,5,5,5,5,0,0,0,0,0,5,5,5,5,0
0,5,16,0,5,5,5,5,5,5,5,0,15,5,0
0,5,16,24,0,0,0,0,0,0,0,23,15,5,0
0,5,5,5,0,0,0,0,0,0,0,5,5,5,0
0,0,0,5,0,0,0,0,0,0,0,5,0,0,0
0,0,0,5,0,0,0,0,0,0,0,5,0,0,0
0,0,0,5,0,0,0,0,0,0,0,5,0,0,0
0,5,5,24,0,5,39,0,38,5,0,37,5,5,0
0,5,17,33,5,22,0,0,0,22,5,33,17,5,0
0,5,0,18,5,40,0,0,0,0,5,18,0,5,0
0,5,5,5,5,0,0,0,0,0,5,5,5,5,0
0,0,0,0,0,0,0,0,0,0,0,0,0,0,0
:endlayer

layer:
0,0,0,0,0,0,0,0,0,0,0,0,0,0,0
0,5,5,5,5,0,0,0,0,0,5,5,5,5,0
0,5,0,0,5,5,5,5,5,5,5,0,0,5,0
0,5,0,25,0,0,0,0,0,0,0,25,0,5,0
0,5,5,5,0,0,0,0,0,0,0,5,5,5,0
0,0,0,5,0,0,0,0,0,0,0,5,0,0,0
0,0,0,5,0,0,0,0,0,0,0,5,0,0,0
0,0,0,5,0,0,0,0,0,0,0,5,0,0,0
0,5,5,25,0,5,0,0,0,5,0,25,5,5,0
0,5,20,0,5,22,0,0,0,22,5,0,34,5,0
0,5,0,0,5,0,0,0,0,0,5,0,0,5,0
0,5,5,5,5,0,0,0,0,0,5,5,5,5,0
0,0,0,0,0,0,0,0,0,0,0,0,0,0,0
:endlayer

layer:
0,0,0,0,0,0,0,0,0,0,0,0,0,0,0
0,5,5,5,5,0,0,0,0,0,5,5,5,5,0
0,5,0,0,5,5,5,5,5,5,5,0,0,5,0
0,5,0,5,0,21,0,0,0,21,0,5,0,5,0
0,5,5,5,0,0,0,0,0,0,0,5,5,5,0
0,0,0,5,0,0,0,0,0,0,0,5,0,0,0
0,0,0,5,0,0,0,0,0,0,0,5,0,0,0
0,0,0,5,0,36,0,0,0,36,0,5,0,0,0
0,5,5,0,5,5,0,0,0,5,5,0,5,5,0
0,5,0,13,5,22,0,0,0,22,5,14,0,5,0
0,5,33,0,5,14,0,0,0,13,5,0,33,5,0
0,5,5,5,5,0,0,0,0,0,5,5,5,5,0
0,0,0,0,0,0,0,0,0,0,0,0,0,0,0
:endlayer

layer:
0,0,0,0,0,0,0,0,0,0,0,0,0,0,0
0,5,5,5,5,0,0,0,0,0,5,5,5,5,0
0,5,0,0,5,5,5,5,5,5,5,0,0,5,0
0,5,0,5,10,0,0,0,0,0,12,5,0,5,0
0,5,5,5,35,0,0,0,0,0,35,5,5,5,0
0,0,0,5,0,0,0,0,0,0,0,5,0,0,0
0,0,0,5,0,0,0,0,0,0,0,5,0,0,0
0,0,0,5,0,0,0,0,0,0,0,5,0,0,0
0,5,5,5,5,5,3,3,3,5,5,5,5,5,0
0,5,0,0,5,22,22,22,22,22,5,0,0,5,0
0,5,0,34,5,10,0,0,0,12,5,20,0,5,0
0,5,5,5,5,0,0,0,0,0,5,5,5,5,0
0,0,0,0,0,0,0,0,0,0,0,0,0,0,0
:endlayer

layer:
0,0,0,0,0,0,0,0,0,0,0,0,0,0,0
0,5,5,5,5,0,0,0,0,0,5,5,5,5,0
0,5,11,11,11,11,11,11,11,11,11,11,11,5,0
0,5,11,11,5,26,26,26,26,26,5,11,11,5,0
0,5,5,5,5,26,26,26,26,26,5,5,5,5,0
0,0,0,11,26,26,26,26,26,26,26,11,0,0,0
0,0,0,11,26,26,26,26,26,26,26,11,0,0,0
0,0,0,11,26,26,26,26,26,26,26,11,0,0,0
0,5,5,5,11,11,11,11,11,11,11,5,5,5,0
0,5,0,19,11,11,11,11,11,11,5,19,0,5,0
0,5,0,0,5,5,5,5,5,5,5,0,0,5,0
0,5,5,5,5,0,0,0,0,0,5,5,5,5,0
0,0,0,0,0,0,0,0,0,0,0,0,0,0,0
:endlayer

layer:
0,0,0,0,0,0,0,0,0,0,0,0,0,0,0
0,5,5,5,5,0,0,0,0,0,5,5,5,5,0
0,5,0,0,5,5,9,5,9,5,5,0,0,5,0
0,5,0,0,0,0,0,0,0,0,0,0,0,5,0
0,5,5,5,5,0,0,0,0,0,5,5,5,5,0
0,0,0,5,0,0,0,0,0,0,0,5,0,0,0
0,0,0,31,0,0,0,0,0,0,0,28,0,0,0
0,0,0,5,0,0,0,0,0,0,0,5,0,0,0
0,5,5,5,5,0,0,0,0,0,5,5,5,5,0
0,5,20,0,0,0,0,0,0,0,0,0,34,5,0
0,5,0,0,5,5,41,5,41,5,5,0,0,5,0
0,5,5,5,5,0,0,0,0,0,5,5,5,5,0
0,0,0,0,0,0,0,0,0,0,0,0,0,0,0
:endlayer

layer:
0,0,0,0,0,0,0,0,0,0,0,0,0,0,0
0,5,5,8,5,0,0,0,0,0,5,8,5,5,0
0,5,0,0,5,5,0,5,0,5,5,0,0,5,0
0,8,0,0,0,0,0,0,0,0,0,0,0,8,0
0,5,5,5,5,0,0,0,0,0,5,5,5,5,0
0,0,0,5,0,0,0,0,0,0,0,5,0,0,0
0,0,0,0,0,0,0,0,0,0,0,0,0,0,0
0,0,0,5,0,0,0,0,0,0,0,5,0,0,0
0,5,5,5,5,0,0,0,0,0,5,5,5,5,0
0,8,0,0,0,0,0,0,0,0,0,0,0,8,0
0,5,33,0,5,5,0,5,0,5,5,0,33,5,0
0,5,5,8,5,0,0,0,0,0,5,8,5,5,0
0,0,0,0,0,0,0,0,0,0,0,0,0,0,0
:endlayer

layer:
0,0,0,0,0,0,0,0,0,0,0,0,0,0,0
0,5,5,4,5,0,0,0,0,0,5,4,5,5,0
0,5,0,0,5,5,4,5,4,5,5,0,0,5,0
0,4,0,0,5,21,0,0,0,21,5,0,0,4,0
0,5,5,5,5,0,0,0,0,0,5,5,5,5,0
0,0,0,5,0,0,0,0,0,0,0,5,0,0,0
0,0,0,4,0,0,0,0,0,0,0,4,0,0,0
0,0,0,5,0,0,0,0,0,0,0,5,0,0,0
0,5,5,5,5,0,0,0,0,0,5,5,5,5,0
0,4,0,0,5,36,0,0,0,36,5,0,0,4,0
0,5,0,34,5,5,4,5,4,5,5,20,0,5,0
0,5,5,4,5,0,0,0,0,0,5,4,5,5,0
0,0,0,0,0,0,0,0,0,0,0,0,0,0,0
:endlayer

layer:
0,0,0,0,0,0,0,0,0,0,0,0,0,0,0
0,5,5,5,5,0,0,0,0,0,5,5,5,5,0
0,5,0,0,5,5,5,5,5,5,5,0,0,5,0
0,5,0,0,5,0,0,0,0,0,5,0,0,5,0
0,5,5,5,5,0,0,0,0,0,5,5,5,5,0
0,0,0,5,0,0,0,0,0,0,0,5,0,0,0
0,0,0,5,0,0,0,0,0,0,0,5,0,0,0
0,0,0,5,0,0,0,0,0,0,0,5,0,0,0
0,5,5,5,5,0,0,0,0,0,5,5,5,5,0
0,5,0,19,5,0,0,0,0,0,5,19,0,5,0
0,5,0,0,5,5,5,5,5,5,5,0,0,5,0
0,5,5,5,5,0,0,0,0,0,5,5,5,5,0
0,0,0,0,0,0,0,0,0,0,0,0,0,0,0
:endlayer

layer:
0,0,0,0,0,0,0,0,0,0,0,0,0,0,0
0,5,5,5,5,0,0,0,0,0,5,5,5,5,0
0,5,18,18,5,5,5,5,5,5,5,17,17,5,0
0,5,18,18,5,27,27,27,27,11,6,17,17,5,0
0,5,5,5,5,27,27,27,27,27,5,5,5,5,0
0,0,0,5,27,27,27,27,27,27,27,5,0,0,0
0,0,0,5,27,27,27,27,27,27,27,5,0,0,0
0,0,0,5,27,27,27,27,27,27,27,5,0,0,0
0,5,5,5,5,27,27,27,27,27,5,5,5,5,0
0,5,20,0,8,27,27,27,27,27,8,0,34,5,0
0,5,0,0,5,5,5,5,5,5,5,0,0,5,0
0,5,5,5,5,0,0,0,0,0,5,5,5,5,0
0,0,0,0,0,0,0,0,0,0,0,0,0,0,0
:endlayer

layer:
0,0,0,0,0,0,0,0,0,0,0,0,0,0,0
0,5,5,9,5,0,0,0,0,0,5,9,5,5,0
0,5,0,0,5,5,9,5,9,5,5,0,19,5,0
0,31,0,0,0,0,0,0,0,29,30,29,0,28,0
0,5,5,5,5,0,0,0,0,0,5,5,5,5,0
0,0,0,5,0,0,0,0,0,0,0,5,0,0,0
0,0,0,31,0,0,0,0,0,0,0,28,0,0,0
0,0,0,5,0,0,0,0,0,0,0,5,0,0,0
0,5,5,5,5,0,0,0,0,0,5,5,5,5,0
0,31,0,0,0,0,0,0,0,0,0,0,0,28,0
0,5,18,0,5,5,41,5,41,5,5,0,18,5,0
0,5,5,41,5,0,0,0,0,0,5,41,5,5,0
0,0,0,0,0,0,0,0,0,0,0,0,0,0,0
:endlayer

layer:
0,0,0,0,0,0,0,0,0,0,0,0,0,0,0
0,5,5,0,5,0,0,0,0,0,5,0,5,5,0
0,5,0,0,5,5,0,5,0,5,5,20,0,5,0
0,0,0,0,0,0,0,21,0,0,32,0,0,0,0
0,5,5,5,5,0,0,0,0,0,5,5,5,5,0
0,0,0,5,0,0,0,0,0,0,0,5,0,0,0
0,0,0,0,0,0,0,0,0,0,0,0,0,0,0
0,0,0,5,0,0,0,0,0,0,0,5,0,0,0
0,5,5,5,5,0,0,0,0,0,5,5,5,5,0
0,0,0,0,0,0,0,36,0,0,0,0,0,0,0
0,5,0,0,5,5,0,5,0,5,5,0,0,5,0
0,5,5,0,5,0,0,0,0,0,5,0,5,5,0
0,0,0,0,0,0,0,0,0,0,0,0,0,0,0
:endlayer

layer:
0,0,0,0,0,0,0,0,0,0,0,0,0,0,0
0,5,5,4,5,0,0,0,0,0,5,4,5,5,0
0,5,14,0,5,5,4,5,4,5,5,0,13,5,0
0,4,0,0,5,0,0,0,0,0,5,33,0,4,0
0,5,5,5,5,0,0,0,0,0,5,5,5,5,0
0,0,0,5,0,0,0,0,0,0,0,5,0,0,0
0,0,0,4,0,0,0,0,0,0,0,4,0,0,0
0,0,0,5,0,0,0,0,0,0,0,5,0,0,0
0,5,5,5,5,0,0,0,0,0,5,5,5,5,0
0,4,0,0,5,0,0,0,0,0,5,0,0,4,0
0,5,14,0,5,5,4,5,4,5,5,0,13,5,0
0,5,5,4,5,0,0,0,0,0,5,4,5,5,0
0,0,0,0,0,0,0,0,0,0,0,0,0,0,0
:endlayer

layer:
0,0,0,0,0,0,0,0,0,0,0,0,0,0,0
0,5,5,5,5,3,4,3,4,3,5,5,5,5,0
0,5,0,0,5,11,11,11,11,11,5,0,0,5,0
0,5,0,0,5,0,0,0,0,0,5,0,34,5,0
0,5,5,5,5,0,0,0,0,0,5,5,5,5,0
0,0,12,11,0,0,0,0,0,0,0,11,10,0,0
0,0,4,11,0,0,0,0,0,0,0,11,4,0,0
0,0,12,11,0,0,0,0,0,0,0,11,10,0,0
0,5,5,5,5,0,0,0,0,0,5,5,5,5,0
0,5,0,0,5,0,0,0,0,0,5,0,0,5,0
0,5,0,0,5,11,11,11,11,11,5,0,0,5,0
0,5,5,5,5,35,4,35,4,35,5,5,5,5,0
0,0,0,0,0,0,0,0,0,0,0,0,0,0,0
:endlayer

layer:
0,3,4,4,3,0,0,0,0,0,3,4,4,3,0
12,11,11,11,11,5,5,5,5,5,11,11,11,11,10
4,11,0,0,5,5,5,5,5,5,5,0,19,11,4
4,11,0,0,5,5,5,5,5,5,5,0,0,11,4
12,11,5,5,5,5,5,5,5,5,5,5,5,11,10
0,35,5,5,5,5,5,5,5,5,5,5,5,35,0
0,0,5,5,5,5,5,5,5,5,5,5,5,0,0
0,3,5,5,5,5,5,5,5,5,5,5,5,3,0
12,11,5,5,5,5,5,5,5,5,5,5,5,11,10
4,11,0,0,5,5,5,5,5,5,5,0,0,11,4
4,11,0,0,5,5,5,5,5,5,5,0,0,11,4
12,11,11,11,11,5,5,5,5,5,11,11,11,11,10
0,35,4,4,35,0,0,0,0,0,35,0,0,35,0
:endlayer

layer:
0,5,5,5,5,0,0,0,0,0,5,5,5,5,0
5,8,8,8,8,5,5,5,5,5,8,8,8,8,5
5,8,8,8,8,0,0,0,0,0,8,8,0,8,5
5,8,8,8,8,0,0,0,0,0,8,0,0,8,5
5,8,8,8,0,0,0,0,0,0,0,8,8,8,5
0,5,5,0,0,0,0,0,0,0,0,0,5,5,0
0,0,5,0,0,0,0,0,0,0,0,0,5,0,0
0,5,5,0,0,0,0,0,0,0,0,0,5,5,0
5,8,8,8,0,0,0,0,0,0,0,8,8,8,5
5,8,8,8,8,0,0,0,0,0,0,8,8,8,5
5,8,8,8,8,0,0,0,0,0,8,8,8,8,5
5,8,8,8,8,5,5,5,5,5,8,8,8,8,5
0,5,5,5,5,0,0,0,0,0,5,5,5,5,0
:endlayer

layer:
0,5,6,5,6,0,0,0,0,0,6,6,6,6,0
6,14,0,0,0,6,8,6,8,6,0,0,0,13,6
5,0,0,0,0,21,0,0,0,21,0,0,0,0,5
6,0,0,0,0,0,0,0,0,0,0,0,0,0,6
5,0,0,0,0,0,0,0,0,0,0,0,0,0,5
0,6,5,14,0,0,0,0,0,0,0,13,6,6,0
0,0,8,0,0,0,0,0,0,0,0,0,8,0,0
0,6,5,14,0,0,0,0,0,0,0,13,5,6,0
5,0,0,0,0,0,0,0,0,0,0,0,0,0,5
6,0,0,0,0,0,0,0,0,0,0,0,0,0,6
5,0,0,0,0,36,0,0,0,36,0,0,0,0,5
6,14,0,0,0,5,8,5,8,5,0,0,0,13,6
0,5,6,5,6,0,0,0,0,0,6,5,6,5,0
:endlayer

layer:
0,8,0,8,0,0,0,0,0,0,0,8,0,8,0
0,0,0,0,0,8,0,0,0,8,0,0,0,0,0
8,0,0,0,0,0,0,0,0,0,0,0,0,0,8
0,0,0,0,0,0,0,0,0,0,0,0,0,0,0
8,0,0,0,0,0,0,0,0,0,0,0,0,0,8
0,0,8,0,0,0,0,0,0,0,0,0,8,0,0
0,0,0,0,0,0,0,0,0,0,0,0,0,0,0
0,0,8,0,0,0,0,0,0,0,0,0,8,0,0
8,0,0,0,0,0,0,0,0,0,0,0,0,0,8
0,0,0,0,0,0,0,0,0,0,0,0,0,0,0
8,0,0,0,0,0,0,0,0,0,0,0,0,0,8
0,0,0,0,0,8,0,0,0,8,0,0,0,0,0
0,8,0,8,0,0,0,0,0,0,0,8,0,8,0
:endlayer


####INVENTORIES####


