# Ancient Warfare Structure Template File
# auto-generated structure file. created on: 1/5/2013 at: 21:27:24
# Lines beginning with # denote comments

name=villageHouseGarden
worldgen=false
creative=true
survival=false
validTargetblocks=1,2,3,12,13

unique=false
chunkDistance=0
chunkAttempts=1

underground=false
undergroundMinLevel=1
undergroundMaxLevel=248
undergroundMaxAirAbove=0
minSubmergedDepth=0
maxWaterDepth=0
maxLavaDepth=0

xSize=9
ySize=7
zSize=12

verticalOffset=0
xOffset=6
zOffset=0

maxOverhang=0
maxLeveling=0
levelingBuffer=0
maxVerticalClear=0
clearingBuffer=0
preserveWater=false
preserveLava=false
preservePlants=false
preserveBlocks=false

####BLOCK RULES####
rule:
number=0
order=0
conditional=0
percent=100
blocks=0-0
:endrule

rule:
number=1
order=0
conditional=0
percent=100
blocks=4-0
:endrule

rule:
number=2
order=0
conditional=0
percent=100
blocks=17-0
:endrule

rule:
number=3
order=0
conditional=0
percent=100
blocks=102-0
:endrule

rule:
number=4
order=0
conditional=0
percent=100
blocks=53-3
:endrule

rule:
number=5
order=0
conditional=0
percent=100
blocks=53-2
:endrule

rule:
number=6
order=0
conditional=0
percent=100
blocks=5-0
:endrule

rule:
number=7
order=0
conditional=0
percent=100
blocks=53-0
:endrule

rule:
number=8
order=0
conditional=0
percent=100
blocks=67-3
:endrule

rule:
number=9
order=0
conditional=0
percent=100
blocks=3-0
:endrule

rule:
number=10
order=0
conditional=0
percent=100
blocks=2-0
:endrule

rule:
number=11
order=1
conditional=0
percent=100
blocks=64-3
:endrule

rule:
number=12
order=0
conditional=0
percent=100
blocks=85-0
:endrule

rule:
number=13
order=1
conditional=0
percent=100
blocks=64-8
:endrule

rule:
number=14
order=0
conditional=0
percent=100
blocks=72-0
:endrule

rule:
number=15
order=1
conditional=0
percent=100
blocks=50-4
:endrule

rule:
number=17
order=1
conditional=0
percent=100
blocks=50-3
:endrule

rule:
number=16
order=0
conditional=0
percent=100
blocks=43-0
:endrule


####SWAP RULESS####

####VEHICLE RULES####

####NPC RULES####

####GATE RULES####

####RESOURCE LIST####
resources:
3-0,34
4-0,67
85-0,16
17-0,4
102-0,7
53-0,74
5-0,83
44-0,22
324-0,2
50-0,2
67-0,1
72-0,1
:endresources

####LAYERS####
layer:
10,10,10,10,10,10,10,0,0
10,10,9,10,10,10,10,0,0
10,10,10,9,10,10,10,0,0
10,10,10,10,10,10,10,0,0
10,10,1,10,9,9,9,0,0
1,1,1,1,1,1,1,1,1
1,6,6,6,6,6,6,6,1
1,16,16,16,6,6,6,6,1
1,16,16,16,6,6,6,6,1
1,16,16,16,6,6,6,6,1
1,1,1,1,1,1,1,1,1
0,0,0,0,0,0,8,0,0
:endlayer

layer:
12,12,12,12,12,12,12,0,0
12,0,0,0,0,0,12,0,0
12,0,0,0,0,0,12,0,0
12,0,0,0,0,0,12,0,0
12,0,0,0,0,0,12,0,0
1,1,11,1,1,1,1,1,1
1,0,0,0,0,0,4,6,1
1,0,0,0,0,0,12,7,1
1,0,16,0,0,0,0,0,1
1,0,16,0,0,0,0,0,1
1,1,1,1,1,1,11,1,1
0,0,0,0,0,0,0,0,0
:endlayer

layer:
0,0,0,0,0,0,0,0,0
0,0,0,0,0,0,0,0,0
0,0,0,0,0,0,0,0,0
0,0,0,0,0,0,0,0,0
0,0,0,0,0,0,0,0,0
1,6,13,6,6,3,3,6,1
2,0,0,0,0,0,0,0,2
3,0,0,0,0,0,14,0,3
3,0,0,0,0,0,0,0,3
2,0,0,0,0,0,0,0,2
1,6,6,3,6,6,13,6,1
0,0,0,0,0,0,0,0,0
:endlayer

layer:
0,0,0,0,0,0,0,0,0
0,0,0,0,0,0,0,0,0
0,0,0,0,0,0,0,0,0
0,0,0,0,0,0,0,0,0
5,5,5,5,5,5,5,5,5
1,6,6,6,6,6,6,6,1
1,0,17,0,0,0,0,0,1
1,0,0,0,0,0,0,0,1
1,0,0,0,0,0,0,0,1
1,0,0,0,0,0,15,0,1
1,6,6,6,6,6,6,6,1
4,4,4,4,4,4,4,4,4
:endlayer

layer:
0,0,0,0,0,0,0,0,0
0,0,0,0,0,0,0,0,0
0,0,0,0,0,0,0,0,0
0,0,0,0,0,0,0,0,0
0,0,0,0,0,0,0,0,0
5,5,5,5,5,5,5,5,5
6,6,6,6,6,6,6,6,6
6,0,0,0,0,0,0,0,6
6,0,0,0,0,0,0,0,6
6,6,6,6,6,6,6,6,6
4,4,4,4,4,4,4,4,4
0,0,0,0,0,0,0,0,0
:endlayer

layer:
0,0,0,0,0,0,0,0,0
0,0,0,0,0,0,0,0,0
0,0,0,0,0,0,0,0,0
0,0,0,0,0,0,0,0,0
0,0,0,0,0,0,0,0,0
0,0,0,0,0,0,0,0,0
5,5,5,5,5,5,5,5,5
6,6,6,6,6,6,6,6,6
6,6,6,6,6,6,6,6,6
4,4,4,4,4,4,4,4,4
0,0,0,0,0,0,0,0,0
0,0,0,0,0,0,0,0,0
:endlayer

layer:
0,0,0,0,0,0,0,0,0
0,0,0,0,0,0,0,0,0
0,0,0,0,0,0,0,0,0
0,0,0,0,0,0,0,0,0
0,0,0,0,0,0,0,0,0
0,0,0,0,0,0,0,0,0
0,0,0,0,0,0,0,0,0
5,5,5,5,5,5,5,5,5
4,4,4,4,4,4,4,4,4
0,0,0,0,0,0,0,0,0
0,0,0,0,0,0,0,0,0
0,0,0,0,0,0,0,0,0
:endlayer


