# Ancient Warfare Structure Template File
# auto-generated structure file. created on: 1/5/2013 at: 21:21:55
# Lines beginning with # denote comments

name=villageHouse1
worldgen=false
creative=true
survival=true
validTargetblocks=1,2,3,12,13

unique=false
chunkDistance=0
chunkAttempts=1

underground=false
undergroundMinLevel=1
undergroundMaxLevel=248
undergroundMaxAirAbove=0
minSubmergedDepth=0
maxWaterDepth=0
maxLavaDepth=0

xSize=9
ySize=7
zSize=12

verticalOffset=0
xOffset=6
zOffset=0

maxOverhang=0
maxLeveling=0
levelingBuffer=0
maxVerticalClear=0
clearingBuffer=0
preserveWater=false
preserveLava=false
preservePlants=false
preserveBlocks=false

####BLOCK RULES####
rule:
number=0
order=0
conditional=0
percent=100
blocks=0-0
:endrule

rule:
number=1
order=0
conditional=0
percent=100
blocks=4-0
:endrule

rule:
number=2
order=0
conditional=0
percent=100
blocks=53-1
:endrule

rule:
number=3
order=0
conditional=0
percent=100
blocks=5-0
:endrule

rule:
number=4
order=0
conditional=0
percent=100
blocks=17-0
:endrule

rule:
number=5
order=0
conditional=0
percent=100
blocks=102-0
:endrule

rule:
number=6
order=0
conditional=0
percent=100
blocks=53-0
:endrule

rule:
number=7
order=0
conditional=0
percent=100
blocks=53-2
:endrule

rule:
number=8
order=0
conditional=0
percent=100
blocks=53-3
:endrule

rule:
number=9
order=1
conditional=0
percent=100
blocks=50-4
:endrule

rule:
number=10
order=1
conditional=0
percent=100
blocks=64-3
:endrule

rule:
number=11
order=1
conditional=0
percent=100
blocks=64-8
:endrule

rule:
number=12
order=0
conditional=0
percent=100
blocks=67-3
:endrule


####SWAP RULESS####

####VEHICLE RULES####

####NPC RULES####

####GATE RULES####

####RESOURCE LIST####
resources:
4-0,108
17-0,12
102-0,10
5-0,148
53-0,90
67-0,1
324-0,1
50-0,1
:endresources

####LAYERS####
layer:
1,1,1,1,1,1,1,0,0
1,3,3,3,3,3,1,0,0
1,3,3,3,3,3,1,0,0
1,3,3,3,3,3,1,0,0
1,3,3,3,3,3,1,0,0
1,3,3,3,3,3,1,1,1
1,3,3,3,3,3,3,3,1
1,3,3,3,3,3,3,3,1
1,3,3,3,3,3,3,3,1
1,3,3,3,3,3,3,3,1
1,1,1,1,1,1,1,1,1
0,0,0,0,0,0,12,0,0
:endlayer

layer:
1,1,1,1,1,1,1,0,0
1,0,0,0,0,0,1,0,0
1,0,0,0,0,0,1,0,0
1,0,0,0,0,0,1,0,0
1,0,0,0,0,0,1,0,0
1,0,0,0,0,0,1,1,1
1,0,0,0,0,0,0,0,1
1,0,0,0,0,0,0,0,1
1,0,0,0,0,0,0,0,1
1,0,0,0,0,0,0,0,1
1,1,1,1,1,1,10,1,1
0,0,0,0,0,0,0,0,0
:endlayer

layer:
1,1,1,1,1,1,1,0,0
4,0,0,0,0,0,4,0,0
5,0,0,0,0,0,5,0,0
5,0,0,0,0,0,5,0,0
4,0,0,0,0,0,4,0,0
3,0,0,0,0,0,3,3,1
4,0,0,0,0,0,0,0,4
5,0,0,0,0,0,0,0,5
5,0,0,0,0,0,0,0,5
4,0,0,0,0,0,0,0,4
1,3,4,5,4,3,11,3,1
0,0,0,0,0,0,0,0,0
:endlayer

layer:
1,1,1,1,1,1,1,2,0
1,0,0,0,0,0,1,2,0
1,0,0,0,0,0,1,2,0
1,0,0,0,0,0,1,2,0
1,0,0,0,0,0,1,3,7
1,0,0,0,0,0,3,3,1
1,0,0,0,0,0,0,0,1
1,0,0,0,0,0,0,0,1
1,0,0,0,0,0,0,0,1
1,0,0,0,0,0,9,0,1
1,3,3,3,3,3,3,3,1
8,8,8,8,8,8,8,8,8
:endlayer

layer:
6,3,4,5,4,3,2,0,0
6,3,0,0,0,3,2,0,0
6,3,0,0,0,3,2,0,0
6,3,0,0,0,3,2,0,0
6,3,0,0,0,3,2,0,0
6,3,0,0,0,3,3,7,7
3,3,0,0,0,3,3,3,3
3,3,0,0,0,0,0,0,3
3,3,0,0,0,0,0,0,3
3,3,3,3,3,3,3,3,3
8,8,8,8,8,8,8,8,8
0,0,0,0,0,0,0,0,0
:endlayer

layer:
0,6,3,3,3,2,0,0,0
0,6,3,0,3,2,0,0,0
0,6,3,0,3,2,0,0,0
0,6,3,0,3,2,0,0,0
0,6,3,0,3,2,0,0,0
0,6,3,0,3,2,0,0,0
7,3,3,0,3,3,7,7,7
3,3,3,3,3,3,3,3,3
3,3,3,3,3,3,3,3,3
8,8,8,8,8,8,8,8,8
0,0,0,0,0,0,0,0,0
0,0,0,0,0,0,0,0,0
:endlayer

layer:
0,0,6,3,2,0,0,0,0
0,0,6,3,2,0,0,0,0
0,0,6,3,2,0,0,0,0
0,0,6,3,2,0,0,0,0
0,0,6,3,2,0,0,0,0
0,0,6,3,2,0,0,0,0
0,0,6,3,2,0,0,0,0
7,7,3,3,3,7,7,7,7
8,8,8,8,8,8,8,8,8
0,0,0,0,0,0,0,0,0
0,0,0,0,0,0,0,0,0
0,0,0,0,0,0,0,0,0
:endlayer


