# Ancient Warfare Structure Template File
# auto-generated structure file. created on: 1/5/2013 at: 21:25:53
# Lines beginning with # denote comments

name=villageHouse2
worldgen=false
creative=true
survival=true
validTargetblocks=1,2,3,12,13

unique=false
chunkDistance=0
chunkAttempts=1

underground=false
undergroundMinLevel=1
undergroundMaxLevel=248
undergroundMaxAirAbove=0
minSubmergedDepth=0
maxWaterDepth=0
maxLavaDepth=0

xSize=9
ySize=7
zSize=12

verticalOffset=0
xOffset=2
zOffset=0

maxOverhang=0
maxLeveling=0
levelingBuffer=0
maxVerticalClear=0
clearingBuffer=0
preserveWater=false
preserveLava=false
preservePlants=false
preserveBlocks=false

####BLOCK RULES####
rule:
number=0
order=0
conditional=0
percent=100
blocks=0-0
:endrule

rule:
number=1
order=0
conditional=0
percent=100
blocks=67-3
:endrule

rule:
number=2
order=0
conditional=0
percent=100
blocks=53-3
:endrule

rule:
number=3
order=0
conditional=0
percent=100
blocks=4-0
:endrule

rule:
number=4
order=1
conditional=0
percent=100
blocks=64-3
:endrule

rule:
number=5
order=0
conditional=0
percent=100
blocks=5-0
:endrule

rule:
number=6
order=1
conditional=0
percent=100
blocks=64-8
:endrule

rule:
number=7
order=0
conditional=0
percent=100
blocks=17-0
:endrule

rule:
number=8
order=0
conditional=0
percent=100
blocks=102-0
:endrule

rule:
number=9
order=1
conditional=0
percent=100
blocks=50-4
:endrule

rule:
number=10
order=0
conditional=0
percent=100
blocks=53-2
:endrule

rule:
number=11
order=0
conditional=0
percent=100
blocks=53-0
:endrule

rule:
number=12
order=0
conditional=0
percent=100
blocks=53-1
:endrule


####SWAP RULESS####

####VEHICLE RULES####

####NPC RULES####

####GATE RULES####

####RESOURCE LIST####
resources:
4-0,108
17-0,12
102-0,10
53-0,90
5-0,148
67-0,1
324-0,1
50-0,1
:endresources

####LAYERS####
layer:
0,0,3,3,3,3,3,3,3
0,0,3,5,5,5,5,5,3
0,0,3,5,5,5,5,5,3
0,0,3,5,5,5,5,5,3
0,0,3,5,5,5,5,5,3
3,3,3,5,5,5,5,5,3
3,5,5,5,5,5,5,5,3
3,5,5,5,5,5,5,5,3
3,5,5,5,5,5,5,5,3
3,5,5,5,5,5,5,5,3
3,3,3,3,3,3,3,3,3
0,0,1,0,0,0,0,0,0
:endlayer

layer:
0,0,3,3,3,3,3,3,3
0,0,3,0,0,0,0,0,3
0,0,3,0,0,0,0,0,3
0,0,3,0,0,0,0,0,3
0,0,3,0,0,0,0,0,3
3,3,3,0,0,0,0,0,3
3,0,0,0,0,0,0,0,3
3,0,0,0,0,0,0,0,3
3,0,0,0,0,0,0,0,3
3,0,0,0,0,0,0,0,3
3,3,4,3,3,3,3,3,3
0,0,0,0,0,0,0,0,0
:endlayer

layer:
0,0,3,3,3,3,3,3,3
0,0,7,0,0,0,0,0,7
0,0,8,0,0,0,0,0,8
0,0,8,0,0,0,0,0,8
0,0,7,0,0,0,0,0,7
3,5,5,0,0,0,0,0,5
7,0,0,0,0,0,0,0,7
8,0,0,0,0,0,0,0,8
8,0,0,0,0,0,0,0,8
7,0,0,0,0,0,0,0,7
3,5,6,5,7,8,7,5,3
0,0,0,0,0,0,0,0,0
:endlayer

layer:
0,11,3,3,3,3,3,3,3
0,11,3,0,0,0,0,0,3
0,11,3,0,0,0,0,0,3
0,11,3,0,0,0,0,0,3
10,5,3,0,0,0,0,0,3
3,5,5,0,0,0,0,0,3
3,0,0,0,0,0,0,0,3
3,0,0,0,0,0,0,0,3
3,0,0,0,0,0,0,0,3
3,0,9,0,0,0,0,0,3
3,5,5,5,5,5,5,5,3
2,2,2,2,2,2,2,2,2
:endlayer

layer:
0,0,11,5,7,8,7,5,12
0,0,11,5,0,0,0,5,12
0,0,11,5,0,0,0,5,12
0,0,11,5,0,0,0,5,12
0,0,11,5,0,0,0,5,12
10,10,5,5,0,0,0,5,12
5,5,5,5,0,0,0,5,5
5,0,0,0,0,0,0,5,5
5,0,0,0,0,0,0,5,5
5,5,5,5,5,5,5,5,5
2,2,2,2,2,2,2,2,2
0,0,0,0,0,0,0,0,0
:endlayer

layer:
0,0,0,11,5,5,5,12,0
0,0,0,11,5,0,5,12,0
0,0,0,11,5,0,5,12,0
0,0,0,11,5,0,5,12,0
0,0,0,11,5,0,5,12,0
0,0,0,11,5,0,5,12,0
10,10,10,5,5,0,5,5,10
5,5,5,5,5,5,5,5,5
5,5,5,5,5,5,5,5,5
2,2,2,2,2,2,2,2,2
0,0,0,0,0,0,0,0,0
0,0,0,0,0,0,0,0,0
:endlayer

layer:
0,0,0,0,11,5,12,0,0
0,0,0,0,11,5,12,0,0
0,0,0,0,11,5,12,0,0
0,0,0,0,11,5,12,0,0
0,0,0,0,11,5,12,0,0
0,0,0,0,11,5,12,0,0
0,0,0,0,11,5,12,0,0
10,10,10,10,5,5,5,10,10
2,2,2,2,2,2,2,2,2
0,0,0,0,0,0,0,0,0
0,0,0,0,0,0,0,0,0
0,0,0,0,0,0,0,0,0
:endlayer


