# Ancient Warfare Structure Template File
# auto-generated structure file. created on: 0/18/2013 at: 18:2:31
# Lines beginning with # denote comments

name=library
worldgen=false
creative=true
survival=false
unique=false
chunkDistance=0
chunkAttempts=1

underground=false
undergroundMinLevel=1
undergroundMaxLevel=246
undergroundMaxAirAbove=0
undergroundAllowPartial=false

xSize=9
ySize=9
zSize=8

verticalOffset=0
xOffset=7
zOffset=0

maxOverhang=0
maxLeveling=0
levelingBuffer=0
maxVerticalClear=0
clearingBuffer=0
preserveWater=false
preserveLava=false
preservePlants=false
preserveBlocks=false

####BLOCK RULES####
rule:
number=0
order=0
conditional=0
percent=100
blocks=0-0
:endrule

rule:
number=1
order=1
conditional=0
percent=100
blocks=31-1
:endrule

rule:
number=2
order=0
conditional=0
percent=100
blocks=53-2
:endrule

rule:
number=3
order=0
conditional=0
percent=100
blocks=4-0
:endrule

rule:
number=4
order=0
conditional=0
percent=100
blocks=5-0
:endrule

rule:
number=5
order=0
conditional=0
percent=100
blocks=102-0
:endrule

rule:
number=6
order=0
conditional=0
percent=100
blocks=53-3
:endrule

rule:
number=7
order=0
conditional=0
percent=100
blocks=47-0
:endrule

rule:
number=8
order=0
conditional=0
percent=100
blocks=85-0
:endrule

rule:
number=9
order=0
conditional=0
percent=100
blocks=53-1
:endrule

rule:
number=10
order=0
conditional=0
percent=100
blocks=72-0
:endrule

rule:
number=11
order=0
conditional=0
percent=100
blocks=58-0
:endrule

rule:
number=12
order=1
conditional=0
percent=100
blocks=64-3
:endrule

rule:
number=13
order=1
conditional=0
percent=100
blocks=64-8
:endrule

rule:
number=14
order=0
conditional=0
percent=100
blocks=67-3
:endrule


####LAYERS####
layer:
0,0,0,1,1,1,1,0,1
3,3,3,3,3,3,3,3,3
3,3,3,3,3,3,3,3,3
3,3,3,3,3,3,3,3,3
3,3,3,3,3,3,3,3,3
3,3,3,3,3,3,3,3,3
3,3,3,3,3,3,3,3,3
0,0,0,0,0,0,0,14,0
:endlayer

layer:
0,0,0,0,0,0,0,0,0
3,3,3,3,3,3,3,3,3
3,4,6,6,6,6,0,0,3
3,9,8,0,8,0,0,0,3
3,0,0,0,0,0,0,0,3
3,11,0,0,0,0,0,0,3
3,3,3,3,3,3,3,12,3
0,0,0,0,0,0,0,0,0
:endlayer

layer:
0,0,0,0,0,0,0,0,0
3,4,5,5,4,5,5,4,3
4,0,0,0,0,0,0,0,4
5,0,10,0,10,0,0,0,5
5,0,0,0,0,0,0,0,5
4,0,0,0,0,0,0,0,4
3,4,5,5,5,4,4,13,3
0,0,0,0,0,0,0,0,0
:endlayer

layer:
0,0,0,0,0,0,0,0,0
3,4,4,4,4,4,4,4,3
4,7,7,7,7,7,7,7,4
5,0,0,0,0,0,0,0,5
5,0,0,0,0,0,0,0,5
4,0,0,0,0,0,0,0,4
3,4,5,5,5,4,4,4,3
0,0,0,0,0,0,0,0,0
:endlayer

layer:
0,0,0,0,0,0,0,0,0
3,4,4,4,4,4,4,4,3
4,4,4,4,4,4,4,4,4
4,0,0,0,0,0,0,0,4
4,0,0,0,0,0,0,0,4
4,4,4,4,4,4,4,4,4
3,4,4,4,4,4,4,4,3
0,0,0,0,0,0,0,0,0
:endlayer

layer:
2,2,2,2,2,2,2,2,2
3,3,3,3,3,3,3,3,3
3,3,3,3,3,3,3,3,3
3,3,3,3,3,3,3,3,3
3,3,3,3,3,3,3,3,3
3,3,3,3,3,3,3,3,3
3,3,3,3,3,3,3,3,3
6,6,6,6,6,6,6,6,6
:endlayer

layer:
0,0,0,0,0,0,0,0,0
2,2,2,2,2,2,2,2,2
3,3,3,3,3,3,3,3,3
3,3,3,3,3,3,3,3,3
3,3,3,3,3,3,3,3,3
3,3,3,3,3,3,3,3,3
6,6,6,6,6,6,6,6,6
0,0,0,0,0,0,0,0,0
:endlayer

layer:
0,0,0,0,0,0,0,0,0
0,0,0,0,0,0,0,0,0
2,2,2,2,2,2,2,2,2
3,3,3,3,3,3,3,3,3
3,3,3,3,3,3,3,3,3
6,6,6,6,6,6,6,6,6
0,0,0,0,0,0,0,0,0
0,0,0,0,0,0,0,0,0
:endlayer

layer:
0,0,0,0,0,0,0,0,0
0,0,0,0,0,0,0,0,0
0,0,0,0,0,0,0,0,0
2,2,2,2,2,2,2,2,2
6,6,6,6,6,6,6,6,6
0,0,0,0,0,0,0,0,0
0,0,0,0,0,0,0,0,0
0,0,0,0,0,0,0,0,0
:endlayer

