# Ancient Warfare Structure Template File
# auto-generated structure file. created on: 3/25/2013 at: 16:10:40
# Lines beginning with # denote comments

survival=false
validTargetblocks=1,2,3,12,13

underground=false
undergroundMinLevel=1
undergroundMaxLevel=252
undergroundMaxAirAbove=0
minSubmergedDepth=0
maxWaterDepth=0
maxLavaDepth=0

xSize=18
ySize=3
zSize=18

verticalOffset=1
xOffset=8
zOffset=0

maxOverhang=0
maxLeveling=0
levelingBuffer=0
maxVerticalClear=0
clearingBuffer=0
preserveWater=false
preserveLava=false
preservePlants=false
preserveBlocks=false

####BLOCK RULES####
rule:
number=0
order=0
conditional=0
percent=100
blocks=0-0
:endrule

rule:
number=1
order=0
conditional=0
percent=100
blocks=3-0
:endrule

rule:
number=2
order=0
conditional=0
percent=100
blocks=2-0
:endrule

rule:
number=3
order=0
conditional=0
percent=100
blocks=5-0
:endrule

rule:
number=4
order=0
conditional=0
percent=100
blocks=85-0
:endrule

rule:
number=5
order=0
conditional=0
percent=100
blocks=4-0
:endrule

rule:
number=6
order=0
conditional=0
percent=100
blocks=1-0
:endrule


####SWAP RULESS####

####VEHICLE RULES####

####NPC RULES####

####GATE RULES####

####ENTITY RULES####

####RESOURCE LIST####
resources:
3-0,256
1-0,53
5-0,66
85-0,66
4-0,12
:endresources

####LAYERS####

layer:
0,0,1,1,1,1,1,1,1,1,1,1,1,1,2,1,1,1
0,2,2,2,2,2,2,2,1,2,2,2,2,2,2,2,2,1
1,2,2,2,2,2,2,2,2,2,2,2,2,2,2,2,2,1
1,2,2,2,2,2,2,2,2,2,2,2,2,2,2,2,2,1
1,2,2,2,2,2,2,2,2,2,2,2,2,2,2,2,2,1
1,2,2,2,2,2,2,2,2,2,2,2,2,2,2,2,2,1
1,1,1,2,1,1,2,2,2,2,2,2,2,2,2,2,2,1
1,1,1,1,1,2,2,5,5,5,5,2,2,2,2,2,2,1
1,1,6,1,1,2,1,5,1,2,5,2,2,2,2,2,2,2
6,6,6,6,1,2,1,5,2,2,5,1,2,2,2,2,2,2
6,6,6,6,6,6,1,5,5,5,5,2,2,2,2,2,2,1
6,6,6,6,6,6,6,1,1,1,2,2,2,2,2,2,2,1
6,6,6,6,1,1,6,1,1,1,2,2,2,2,2,2,2,2
6,6,6,6,6,1,1,6,2,1,2,2,2,2,2,2,2,2
6,6,6,6,6,6,6,1,1,2,2,2,2,2,2,2,2,1
6,6,6,6,6,1,1,6,1,2,2,2,2,2,2,2,2,1
6,6,6,6,6,6,1,1,1,1,2,2,2,2,2,2,2,2
6,6,6,6,6,1,1,1,1,2,1,1,1,1,2,1,1,1
:endlayer

layer:
3,3,3,3,3,3,3,3,3,3,3,3,3,3,3,3,3,3
3,0,0,0,0,0,0,0,0,0,0,0,0,0,0,0,0,3
3,0,0,0,0,0,0,0,0,0,0,0,0,0,0,0,0,3
3,0,0,0,0,0,0,0,0,0,0,0,0,0,0,0,0,3
3,0,0,0,0,0,0,0,0,0,0,0,0,0,0,0,0,3
3,0,0,0,0,0,0,0,0,0,0,0,0,0,0,0,0,3
3,0,0,0,0,0,0,0,0,0,0,0,0,0,0,0,0,3
3,0,0,0,0,0,0,0,0,0,0,0,0,0,0,0,0,3
3,0,0,0,0,0,0,0,0,0,0,0,0,0,0,0,0,3
3,0,0,0,0,0,0,0,0,0,0,0,0,0,0,0,0,3
3,0,0,0,0,0,0,0,0,0,0,0,0,0,0,0,0,3
3,0,0,0,0,0,0,0,0,0,0,0,0,0,0,0,0,3
3,0,0,0,0,0,0,0,0,0,0,0,0,0,0,0,0,3
3,0,0,0,0,0,0,0,0,0,0,0,0,0,0,0,0,3
3,0,0,0,0,0,0,0,0,0,0,0,0,0,0,0,0,3
3,0,0,0,0,0,0,0,0,0,0,0,0,0,0,0,0,3
3,0,0,0,0,0,0,0,0,0,0,0,0,0,0,0,0,3
3,3,3,3,3,3,3,3,0,0,3,3,3,3,3,3,3,3
:endlayer

layer:
4,4,4,4,4,4,4,4,4,4,4,4,4,4,4,4,4,4
4,0,0,0,0,0,0,0,0,0,0,0,0,0,0,0,0,4
4,0,0,0,0,0,0,0,0,0,0,0,0,0,0,0,0,4
4,0,0,0,0,0,0,0,0,0,0,0,0,0,0,0,0,4
4,0,0,0,0,0,0,0,0,0,0,0,0,0,0,0,0,4
4,0,0,0,0,0,0,0,0,0,0,0,0,0,0,0,0,4
4,0,0,0,0,0,0,0,0,0,0,0,0,0,0,0,0,4
4,0,0,0,0,0,0,0,0,0,0,0,0,0,0,0,0,4
4,0,0,0,0,0,0,0,0,0,0,0,0,0,0,0,0,4
4,0,0,0,0,0,0,0,0,0,0,0,0,0,0,0,0,4
4,0,0,0,0,0,0,0,0,0,0,0,0,0,0,0,0,4
4,0,0,0,0,0,0,0,0,0,0,0,0,0,0,0,0,4
4,0,0,0,0,0,0,0,0,0,0,0,0,0,0,0,0,4
4,0,0,0,0,0,0,0,0,0,0,0,0,0,0,0,0,4
4,0,0,0,0,0,0,0,0,0,0,0,0,0,0,0,0,4
4,0,0,0,0,0,0,0,0,0,0,0,0,0,0,0,0,4
4,0,0,0,0,0,0,0,0,0,0,0,0,0,0,0,0,4
4,4,4,4,4,4,4,4,0,0,4,4,4,4,4,4,4,4
:endlayer


