# Ancient Warfare Structure Template File
# auto-generated structure file. created on: 4/17/2014 at: 17:6:38
# Lines beginning with # denote comments

header:
version=2.0
name=farm_house_czarified
size=14,10,11
offset=12,1,10
:endheader

#### VALIDATION ####
validation:
type=ground
survival=false
worldGenEnabled=false
unique=false
preserveBlocks=false
selectionWeight=1
clusterValue=1
minDuplicateDistance=1
dimensionWhiteList=false
dimensionList=
biomeWhiteList=false
biomeList=
leveling=0
fill=0
border=0
validTargetBlocks=clay,lapis_ore,lit_redstone_ore,stone,tile.bop.mud,gravel,coal_block,diamond_ore,ice,snow,netherrack,tile.bop.generic.hard_dirt,tile.bop.redRocks,dirt,redstone_ore,mycelium,tile.bop.holyStone,sand,grass,tile.bop.ash,iron_ore,tile.bop.originGrass,soul_sand,snow_layer,tile.bop.generic.dried_dirt,stained_hardened_clay,tile.extrabiomes.redrock,tile.bop.generic.hard_ice,tile.bop.generic.ash_stone,coal_ore,gold_ore,tile.bop.generic.hard_sand
data:
:enddata
:endvalidation

#### LAYERS ####
layer: 0
1,1,1,1,1,1,1,1,1,1,1,1,1,1
4,4,4,4,4,4,4,4,4,4,4,4,4,4
4,4,4,3,4,4,5,4,5,4,3,4,4,4
4,5,4,4,5,4,4,3,4,4,4,4,3,4
4,4,3,5,4,3,5,4,4,3,5,4,4,4
4,5,4,4,4,4,4,5,5,4,3,4,3,4
4,5,4,4,5,4,4,3,4,4,4,4,3,4
4,4,3,3,4,5,3,4,5,5,4,3,4,4
4,4,4,4,4,4,4,4,4,5,4,4,4,4
4,4,4,4,4,4,4,4,4,4,4,4,4,4
1,1,1,1,1,1,1,1,3,3,3,1,2,1
:endlayer
layer: 1
0,0,0,0,0,0,0,0,0,0,0,0,0,0
6,7,7,6,7,7,6,7,6,7,7,6,7,6
8,0,0,0,0,0,9,0,0,0,0,0,0,8
8,0,0,0,0,0,0,0,0,0,0,0,0,8
8,0,0,0,0,0,0,0,0,0,0,0,0,8
8,0,0,0,0,0,0,0,0,0,0,0,0,8
8,0,0,0,0,0,0,0,0,0,0,0,0,8
8,0,0,0,0,0,0,0,0,0,0,0,0,8
8,0,0,0,0,0,0,0,0,0,0,0,0,8
6,7,7,6,7,7,6,7,6,7,7,6,0,6
0,0,0,0,0,0,0,0,0,0,0,0,0,0
:endlayer
layer: 2
0,0,0,0,0,0,0,0,0,0,0,0,0,0
6,7,7,6,0,0,6,7,6,0,0,6,7,6
8,0,0,0,0,0,9,0,0,0,0,0,0,8
8,0,0,0,0,0,0,0,0,0,0,0,0,8
8,0,0,0,0,0,0,0,0,0,0,0,0,8
8,0,0,0,0,0,0,0,0,0,0,0,10,8
8,0,0,0,0,0,0,0,0,0,0,0,0,8
8,0,0,0,0,0,0,0,0,0,0,0,0,8
8,0,0,0,0,0,0,0,0,0,0,0,0,8
6,7,7,6,0,0,6,7,6,0,0,6,0,6
0,0,0,0,0,0,0,0,0,0,0,0,0,0
:endlayer
layer: 3
0,0,0,0,0,0,0,0,0,0,0,11,0,0
6,7,7,6,0,0,6,7,6,0,0,6,7,12
8,0,0,14,0,0,9,0,0,0,0,0,0,12
8,0,0,0,0,0,0,0,0,0,0,0,0,12
8,0,0,0,0,0,0,0,0,0,0,0,0,12
8,0,0,0,0,0,0,0,0,0,0,0,0,12
8,0,0,0,0,0,0,0,0,0,0,0,0,12
8,0,0,0,0,0,0,0,0,0,0,0,0,12
8,0,0,0,0,0,13,0,0,0,0,0,0,12
6,7,7,6,0,0,6,7,6,0,0,6,7,6
0,0,0,0,0,0,0,0,0,0,0,11,0,0
:endlayer
layer: 4
15,11,0,0,0,0,0,0,0,11,15,15,0,0
15,16,16,6,16,16,6,16,6,16,15,15,15,0
15,0,0,0,0,0,9,0,0,0,0,15,15,0
15,0,0,0,0,0,0,0,0,0,0,0,15,0
15,0,0,0,0,0,0,0,0,0,0,0,15,0
15,0,0,0,0,0,0,0,0,0,0,0,15,0
15,0,0,0,0,0,0,0,0,0,0,0,15,0
15,0,0,0,0,0,0,0,0,0,0,0,15,0
15,0,0,0,0,0,0,0,0,0,0,15,15,0
15,16,16,6,16,16,6,16,6,16,15,15,15,0
15,11,0,0,0,0,0,0,0,11,15,15,0,0
:endlayer
layer: 5
0,15,11,0,0,0,0,0,11,15,0,0,0,0
0,15,16,6,17,17,6,16,18,15,0,0,0,0
0,15,0,18,19,19,9,19,18,15,15,0,0,0
0,15,0,18,19,19,19,19,18,15,15,15,0,0
0,15,0,18,19,19,19,19,18,15,15,15,0,0
0,15,0,18,19,19,19,19,18,15,15,15,0,0
0,15,0,18,19,19,19,19,18,15,15,15,0,0
0,15,0,18,19,19,19,19,18,15,15,15,0,0
0,15,0,18,19,19,19,19,18,15,15,0,0,0
0,15,16,6,17,17,6,16,6,15,0,0,0,0
0,15,11,0,0,0,0,0,11,15,0,0,0,0
:endlayer
layer: 6
0,0,15,11,0,0,0,11,15,0,0,0,0,0
0,0,15,6,16,16,6,16,15,0,0,0,0,0
0,0,15,0,0,0,0,0,15,0,0,0,0,0
0,0,15,0,0,0,0,11,0,0,0,0,0,0
0,0,15,0,0,0,0,0,11,0,0,0,0,0
0,0,15,0,0,0,0,0,11,0,0,0,0,0
0,0,15,0,0,0,0,0,11,0,0,0,0,0
0,0,15,0,0,0,0,11,0,0,0,0,0,0
0,0,15,0,0,20,0,0,15,0,0,0,0,0
0,0,15,6,16,16,6,16,15,0,0,0,0,0
0,0,15,11,0,0,0,11,15,0,0,0,0,0
:endlayer
layer: 7
0,0,0,15,11,0,11,15,0,0,0,0,0,0
0,0,0,15,16,16,6,15,0,0,0,0,0,0
0,0,0,15,0,14,0,15,0,0,0,0,0,0
0,0,0,15,0,0,0,11,0,0,0,0,0,0
0,0,0,15,0,0,0,0,11,0,0,0,0,0
0,0,0,15,0,0,0,0,0,0,0,0,0,0
0,0,0,15,0,0,0,0,11,0,0,0,0,0
0,0,0,15,0,0,0,11,0,0,0,0,0,0
0,0,0,15,0,13,0,15,0,0,0,0,0,0
0,0,0,15,16,16,6,15,0,0,0,0,0,0
0,0,0,15,11,0,11,15,0,0,0,0,0,0
:endlayer
layer: 8
0,0,0,0,15,11,15,0,0,0,0,0,0,0
0,0,0,0,15,18,15,0,0,0,0,0,0,0
0,0,0,0,15,18,15,0,0,0,0,0,0,0
0,0,0,0,15,18,19,21,0,0,0,0,0,0
0,0,0,0,15,18,19,21,22,0,0,0,0,0
0,0,0,0,15,18,19,21,22,0,0,0,0,0
0,0,0,0,15,18,19,21,22,0,0,0,0,0
0,0,0,0,15,18,19,21,0,0,0,0,0,0
0,0,0,0,15,18,15,0,0,0,0,0,0,0
0,0,0,0,15,18,15,0,0,0,0,0,0,0
0,0,0,0,15,18,15,0,0,0,0,0,0,0
:endlayer
layer: 9
0,0,0,0,0,15,0,0,0,0,0,0,0,0
0,0,0,0,0,15,0,0,0,0,0,0,0,0
0,0,0,0,0,15,0,0,0,0,0,0,0,0
0,0,0,0,0,15,0,0,0,0,0,0,0,0
0,0,0,0,0,15,22,0,0,0,0,0,0,0
0,0,0,0,0,15,22,0,0,0,0,0,0,0
0,0,0,0,0,15,22,0,0,0,0,0,0,0
0,0,0,0,0,15,0,0,0,0,0,0,0,0
0,0,0,0,0,15,0,0,0,0,0,0,0,0
0,0,0,0,0,15,0,0,0,0,0,0,0,0
0,0,0,0,0,15,0,0,0,0,0,0,0,0
:endlayer

#### RULES ####
rule:
plugin=vanillaBlocks
number=1
data:
tag:
TAG=10={
TAG=8=blockName{grass}
TAG=3=meta{0}
TAG=3=buildPass{0}
}
:endtag
:enddata
:endrule

rule:
plugin=vanillaBlocks
number=2
data:
tag:
TAG=10={
TAG=8=blockName{stone_slab}
TAG=3=meta{8}
TAG=3=buildPass{0}
}
:endtag
:enddata
:endrule

rule:
plugin=vanillaBlocks
number=3
data:
tag:
TAG=10={
TAG=8=blockName{gravel}
TAG=3=meta{0}
TAG=3=buildPass{1}
}
:endtag
:enddata
:endrule

rule:
plugin=vanillaBlocks
number=4
data:
tag:
TAG=10={
TAG=8=blockName{stained_hardened_clay}
TAG=3=meta{12}
TAG=3=buildPass{0}
}
:endtag
:enddata
:endrule

rule:
plugin=vanillaBlocks
number=5
data:
tag:
TAG=10={
TAG=8=blockName{dirt}
TAG=3=meta{0}
TAG=3=buildPass{0}
}
:endtag
:enddata
:endrule

rule:
plugin=vanillaBlocks
number=6
data:
tag:
TAG=10={
TAG=8=blockName{log}
TAG=3=meta{0}
TAG=3=buildPass{0}
}
:endtag
:enddata
:endrule

rule:
plugin=vanillaBlocks
number=7
data:
tag:
TAG=10={
TAG=8=blockName{wool}
TAG=3=meta{0}
TAG=3=buildPass{0}
}
:endtag
:enddata
:endrule

rule:
plugin=vanillaBlocks
number=8
data:
tag:
TAG=10={
TAG=8=blockName{cobblestone}
TAG=3=meta{0}
TAG=3=buildPass{0}
}
:endtag
:enddata
:endrule

rule:
plugin=vanillaBlocks
number=9
data:
tag:
TAG=10={
TAG=8=blockName{ladder}
TAG=3=meta{3}
TAG=3=buildPass{1}
}
:endtag
:enddata
:endrule

rule:
plugin=vanillaBlocks
number=10
data:
tag:
TAG=10={
TAG=8=blockName{torch}
TAG=3=meta{2}
TAG=3=buildPass{1}
}
:endtag
:enddata
:endrule

rule:
plugin=vanillaBlocks
number=11
data:
tag:
TAG=10={
TAG=8=blockName{fence}
TAG=3=meta{0}
TAG=3=buildPass{0}
}
:endtag
:enddata
:endrule

rule:
plugin=vanillaBlocks
number=12
data:
tag:
TAG=10={
TAG=8=blockName{stone_stairs}
TAG=3=meta{1}
TAG=3=buildPass{0}
}
:endtag
:enddata
:endrule

rule:
plugin=vanillaBlocks
number=13
data:
tag:
TAG=10={
TAG=8=blockName{torch}
TAG=3=meta{4}
TAG=3=buildPass{1}
}
:endtag
:enddata
:endrule

rule:
plugin=vanillaBlocks
number=14
data:
tag:
TAG=10={
TAG=8=blockName{torch}
TAG=3=meta{3}
TAG=3=buildPass{1}
}
:endtag
:enddata
:endrule

rule:
plugin=vanillaBlocks
number=15
data:
tag:
TAG=10={
TAG=8=blockName{hay_block}
TAG=3=meta{8}
TAG=3=buildPass{0}
}
:endtag
:enddata
:endrule

rule:
plugin=vanillaBlocks
number=16
data:
tag:
TAG=10={
TAG=8=blockName{planks}
TAG=3=meta{0}
TAG=3=buildPass{0}
}
:endtag
:enddata
:endrule

rule:
plugin=vanillaBlocks
number=17
data:
tag:
TAG=10={
TAG=8=blockName{log}
TAG=3=meta{4}
TAG=3=buildPass{0}
}
:endtag
:enddata
:endrule

rule:
plugin=vanillaBlocks
number=18
data:
tag:
TAG=10={
TAG=8=blockName{log}
TAG=3=meta{8}
TAG=3=buildPass{0}
}
:endtag
:enddata
:endrule

rule:
plugin=vanillaBlocks
number=19
data:
tag:
TAG=10={
TAG=8=blockName{wooden_slab}
TAG=3=meta{8}
TAG=3=buildPass{0}
}
:endtag
:enddata
:endrule

rule:
plugin=vanillaInventory
number=20
data:
tag:
TAG=10={
TAG=3=lootLevel{0}
TAG=10=teData{
TAG=9=Items{
TAG=10={
TAG=2=id{265}
TAG=2=Damage{0}
TAG=1=Count{3}
TAG=1=Slot{4}
}
TAG=10={
TAG=2=id{297}
TAG=2=Damage{0}
TAG=1=Count{1}
TAG=1=Slot{8}
}
TAG=10={
TAG=2=id{417}
TAG=2=Damage{0}
TAG=1=Count{1}
TAG=1=Slot{10}
}
}
TAG=8=id{Chest}
}
TAG=8=blockName{chest}
TAG=3=meta{2}
TAG=3=buildPass{0}
}
:endtag
:enddata
:endrule

rule:
plugin=vanillaBlocks
number=21
data:
tag:
TAG=10={
TAG=8=blockName{oak_stairs}
TAG=3=meta{1}
TAG=3=buildPass{0}
}
:endtag
:enddata
:endrule

rule:
plugin=vanillaBlocks
number=22
data:
tag:
TAG=10={
TAG=8=blockName{wooden_slab}
TAG=3=meta{0}
TAG=3=buildPass{0}
}
:endtag
:enddata
:endrule

#### ENTITIES ####
