# Ancient Warfare Structure Template File
# auto-generated structure file. created on: 4/17/2014 at: 17:14:47
# Lines beginning with # denote comments

header:
version=2.0
name=village_barracks_huntingBlock
size=13,26,13
offset=6,1,12
:endheader

#### VALIDATION ####
validation:
type=ground
survival=false
worldGenEnabled=false
unique=false
preserveBlocks=false
selectionWeight=1
clusterValue=1
minDuplicateDistance=1
dimensionWhiteList=false
dimensionList=
biomeWhiteList=false
biomeList=
leveling=0
fill=0
border=0
validTargetBlocks=clay,lapis_ore,lit_redstone_ore,stone,tile.bop.mud,gravel,coal_block,diamond_ore,ice,snow,netherrack,tile.bop.generic.hard_dirt,tile.bop.redRocks,dirt,redstone_ore,mycelium,tile.bop.holyStone,sand,grass,tile.bop.ash,iron_ore,tile.bop.originGrass,snow_layer,soul_sand,tile.bop.generic.dried_dirt,stained_hardened_clay,tile.extrabiomes.redrock,tile.bop.generic.hard_ice,tile.bop.generic.ash_stone,coal_ore,gold_ore,tile.bop.generic.hard_sand
data:
:enddata
:endvalidation

#### LAYERS ####
layer: 0
1,1,1,1,1,2,2,2,1,1,1,1,1
1,1,1,1,3,2,2,2,3,1,1,1,1
1,1,1,3,4,5,4,5,4,3,1,1,1
1,1,3,4,5,4,5,4,5,4,3,1,1
1,3,4,5,4,5,4,5,4,5,4,3,1
2,2,5,4,5,4,5,4,5,4,5,2,2
2,2,4,5,4,5,2,5,4,5,4,2,2
2,2,5,4,5,4,5,4,5,4,5,2,2
1,3,4,5,4,5,4,5,4,5,4,3,1
1,1,3,4,5,4,5,4,5,4,3,1,1
1,1,1,3,4,5,4,5,4,3,1,1,1
1,1,1,1,3,2,2,2,3,1,1,1,1
1,1,1,1,1,2,2,2,1,1,1,1,1
:endlayer
layer: 1
0,0,0,0,6,0,0,0,0,0,0,0,0
0,0,0,0,2,0,0,0,2,0,0,0,0
0,0,0,2,0,0,0,0,7,2,0,0,8
0,0,2,0,0,0,0,0,0,0,2,0,0
0,2,9,0,0,0,0,0,0,0,0,2,9
0,0,0,0,0,0,10,0,0,0,0,0,0
0,0,0,0,0,11,2,12,0,0,0,0,0
0,0,0,0,0,0,13,0,0,0,0,0,0
14,2,0,0,0,0,0,0,0,0,14,2,0
0,0,2,0,0,0,0,0,0,0,2,0,0
0,0,0,2,6,0,0,0,0,2,0,0,0
0,0,0,0,2,0,0,0,2,0,0,0,0
0,0,0,0,0,0,0,0,7,0,0,0,0
:endlayer
layer: 2
0,0,0,0,0,0,0,0,0,0,0,0,0
0,0,0,0,15,0,0,0,15,0,0,0,0
0,0,0,16,0,0,0,0,0,15,0,0,0
0,0,15,0,0,0,0,0,0,0,15,0,0
0,15,0,0,0,0,0,0,0,0,0,15,0
0,0,0,0,0,0,10,0,0,0,0,0,0
0,0,0,0,0,11,15,12,0,0,0,0,0
0,0,0,0,0,0,13,0,0,0,0,0,0
0,15,0,0,0,0,0,0,0,0,0,16,0
0,0,16,0,0,0,0,0,0,0,15,0,0
0,0,0,15,0,0,0,0,0,15,0,0,0
0,0,0,0,15,0,0,0,15,0,0,0,0
0,0,0,0,0,0,0,0,0,0,0,0,0
:endlayer
layer: 3
0,0,0,0,17,0,0,0,17,0,0,0,0
0,0,0,0,15,0,0,0,15,0,0,0,0
0,0,0,15,18,0,0,0,18,15,0,0,0
0,0,16,0,0,0,0,0,0,0,16,0,0
19,15,20,0,0,0,0,0,0,0,19,15,20
0,0,0,0,0,0,10,0,0,0,0,0,0
0,0,0,0,0,11,15,12,0,0,0,0,0
0,0,0,0,0,0,13,0,0,0,0,0,0
19,15,20,0,0,0,0,0,0,0,19,15,20
0,0,15,0,0,0,0,0,0,0,15,0,0
0,0,0,16,17,0,0,0,17,16,0,0,0
0,0,0,0,15,0,0,0,15,0,0,0,0
0,0,0,0,18,0,0,0,18,0,0,0,0
:endlayer
layer: 4
0,0,0,0,0,0,0,0,0,0,0,0,0
0,0,0,0,15,0,0,0,16,0,0,0,0
0,0,0,16,0,0,0,0,0,15,0,0,0
0,0,15,0,0,0,0,0,0,0,15,0,0
0,15,0,0,0,0,0,0,0,0,0,15,0
0,0,0,0,0,0,10,0,0,0,0,0,0
0,0,0,0,0,11,15,12,0,0,0,0,0
0,0,0,0,0,0,13,0,0,0,0,0,0
0,15,0,0,0,0,0,0,0,0,0,15,0
0,0,15,0,0,0,0,0,0,0,15,0,0
0,0,0,15,0,0,0,0,0,16,0,0,0
0,0,0,0,16,0,0,0,15,0,0,0,0
0,0,0,0,0,0,0,0,0,0,0,0,0
:endlayer
layer: 5
0,0,0,0,0,0,0,0,0,0,0,0,0
0,0,0,0,15,16,15,15,15,0,0,0,0
0,0,0,15,4,5,4,5,4,15,0,0,0
0,0,15,4,5,4,5,4,5,4,15,0,0
0,15,4,5,4,5,4,5,4,5,4,15,0
0,15,5,4,5,4,10,4,5,4,5,16,0
0,15,4,5,4,11,15,12,4,5,4,16,0
0,15,5,4,5,4,13,4,5,4,5,15,0
0,15,4,5,4,5,4,5,4,5,4,15,0
0,0,15,4,5,4,5,4,5,4,15,0,0
0,0,0,15,4,5,4,5,4,15,0,0,0
0,0,0,0,15,15,15,15,16,0,0,0,0
0,0,0,0,0,0,0,0,0,0,0,0,0
:endlayer
layer: 6
0,0,0,0,0,0,0,0,0,0,0,0,0
0,0,0,0,15,21,15,21,15,0,0,0,0
0,0,0,16,22,0,23,0,22,15,0,0,0
0,0,15,24,25,0,0,0,25,24,16,0,0
0,15,26,27,0,0,0,0,0,28,29,15,0
0,30,0,0,0,0,10,0,0,0,0,31,0
0,16,32,0,0,11,15,12,0,0,33,15,0
0,30,0,0,0,0,13,0,0,0,0,31,0
0,15,26,27,0,0,0,0,0,28,29,15,0
0,0,15,24,34,0,0,0,34,24,15,0,0
0,0,0,16,35,0,36,0,35,15,0,0,0
0,0,0,0,15,37,15,37,16,0,0,0,0
0,0,0,0,0,0,0,0,0,0,0,0,0
:endlayer
layer: 7
0,0,0,0,0,0,0,0,0,0,0,0,0
0,0,0,0,16,0,15,0,15,0,0,0,0
0,0,0,15,0,0,0,0,0,16,0,0,0
0,0,15,24,0,0,0,0,0,24,15,0,0
0,15,0,0,0,0,0,0,0,0,0,16,0
0,0,0,0,0,0,10,0,0,0,0,0,0
0,16,0,0,0,11,15,12,0,0,0,15,0
0,0,0,0,0,0,13,0,0,0,0,0,0
0,15,0,0,0,0,0,0,0,0,0,15,0
0,0,16,24,0,0,0,0,0,24,16,0,0
0,0,0,15,0,0,0,0,0,15,0,0,0
0,0,0,0,16,0,15,0,15,0,0,0,0
0,0,0,0,0,0,0,0,0,0,0,0,0
:endlayer
layer: 8
0,0,0,0,0,0,0,0,0,0,0,0,0
0,0,0,0,15,38,16,38,15,0,0,0,0
0,0,0,15,18,0,0,0,18,15,0,0,0
0,0,15,24,0,0,0,0,0,24,15,0,0
0,15,20,0,0,0,0,0,0,0,19,15,0
0,38,0,0,0,0,10,0,0,0,0,38,0
0,15,0,0,0,11,15,12,0,0,0,15,0
0,38,0,0,0,0,13,0,0,0,0,38,0
0,15,20,0,0,0,0,0,0,0,19,15,0
0,0,15,24,0,0,0,0,0,24,15,0,0
0,0,0,16,17,0,0,0,17,15,0,0,0
0,0,0,0,15,38,15,38,15,0,0,0,0
0,0,0,0,0,0,0,0,0,0,0,0,0
:endlayer
layer: 9
0,0,0,0,0,0,0,0,0,0,0,0,0
0,0,0,0,15,15,15,16,16,0,0,0,0
0,0,0,15,0,0,0,0,0,15,0,0,0
0,0,15,24,0,0,0,0,0,24,15,0,0
0,15,0,0,0,0,0,0,0,0,0,15,0
0,15,0,0,0,0,10,0,0,0,0,15,0
0,15,0,0,0,11,15,12,0,0,0,15,0
0,15,0,0,0,0,13,0,0,0,0,16,0
0,15,0,0,0,0,0,0,0,0,0,15,0
0,0,15,24,0,0,0,0,0,24,15,0,0
0,0,0,15,0,0,0,0,0,15,0,0,0
0,0,0,0,15,15,15,16,15,0,0,0,0
0,0,0,0,0,0,0,0,0,0,0,0,0
:endlayer
layer: 10
0,0,0,0,0,0,0,0,0,0,0,0,0
0,0,0,0,15,15,15,15,15,0,0,0,0
0,0,0,15,4,5,4,5,4,15,0,0,0
0,0,15,4,5,4,5,4,5,4,15,0,0
0,15,4,5,4,5,4,5,4,5,4,15,0
0,15,5,4,5,4,10,4,5,4,5,15,0
0,15,4,5,4,11,15,12,4,5,4,15,0
0,15,5,4,5,4,13,4,5,4,5,15,0
0,15,4,5,4,5,4,5,4,5,4,15,0
0,0,15,4,5,4,5,4,5,4,15,0,0
0,0,0,15,4,5,4,5,4,15,0,0,0
0,0,0,0,15,15,15,15,15,0,0,0,0
0,0,0,0,0,0,0,0,0,0,0,0,0
:endlayer
layer: 11
0,0,0,0,0,0,0,0,0,0,0,0,0
0,0,0,0,16,21,15,21,15,0,0,0,0
0,0,0,16,22,0,39,0,22,15,0,0,0
0,0,15,24,25,0,0,0,25,24,16,0,0
0,15,26,27,0,0,0,0,0,28,29,15,0
0,30,0,0,0,0,10,0,0,0,0,31,0
0,15,40,0,0,11,15,12,0,0,41,15,0
0,30,0,0,0,0,13,0,0,0,0,31,0
0,16,26,27,0,0,0,0,0,28,29,15,0
0,0,15,24,34,0,0,0,34,24,15,0,0
0,0,0,16,35,0,42,0,35,15,0,0,0
0,0,0,0,16,37,15,37,15,0,0,0,0
0,0,0,0,0,0,0,0,0,0,0,0,0
:endlayer
layer: 12
0,0,0,0,0,0,0,0,0,0,0,0,0
0,0,0,0,15,0,16,0,15,0,0,0,0
0,0,0,16,0,0,0,0,0,15,0,0,0
0,0,15,24,0,0,0,0,0,24,15,0,0
0,15,0,0,0,0,0,0,0,0,0,15,0
0,0,0,0,0,0,10,0,0,0,0,0,0
0,15,0,0,0,11,15,12,0,0,0,15,0
0,0,0,0,0,0,13,0,0,0,0,0,0
0,15,0,0,0,0,0,0,0,0,0,15,0
0,0,15,24,0,0,0,0,0,24,16,0,0
0,0,0,15,0,0,0,0,0,15,0,0,0
0,0,0,0,15,0,15,0,16,0,0,0,0
0,0,0,0,0,0,0,0,0,0,0,0,0
:endlayer
layer: 13
0,0,0,0,0,0,0,0,0,0,0,0,0
0,0,0,0,15,38,15,38,15,0,0,0,0
0,0,0,15,18,0,0,0,18,15,0,0,0
0,0,15,24,0,0,0,0,0,24,15,0,0
0,15,20,0,0,0,0,0,0,0,19,15,0
0,38,0,0,0,0,10,0,0,0,0,38,0
0,15,0,0,0,11,15,12,0,0,0,15,0
0,38,0,0,0,0,13,0,0,0,0,38,0
0,15,20,0,0,0,0,0,0,0,19,15,0
0,0,15,24,0,0,0,0,0,24,15,0,0
0,0,0,15,17,0,0,0,17,15,0,0,0
0,0,0,0,15,38,15,38,15,0,0,0,0
0,0,0,0,0,0,0,0,0,0,0,0,0
:endlayer
layer: 14
0,0,0,0,0,0,0,0,0,0,0,0,0
0,0,0,0,15,15,15,15,15,0,0,0,0
0,0,0,15,0,0,0,0,0,15,0,0,0
0,0,15,24,0,0,0,0,0,24,16,0,0
0,15,0,0,0,0,0,0,0,0,0,15,0
0,15,0,0,0,0,10,0,0,0,0,15,0
0,15,0,0,0,11,15,12,0,0,0,15,0
0,15,0,0,0,0,13,0,0,0,0,15,0
0,15,0,0,0,0,0,0,0,0,0,15,0
0,0,16,24,0,0,0,0,0,24,15,0,0
0,0,0,15,0,0,0,0,0,15,0,0,0
0,0,0,0,15,15,16,15,15,0,0,0,0
0,0,0,0,0,0,0,0,0,0,0,0,0
:endlayer
layer: 15
0,0,0,43,43,43,43,43,43,44,0,0,0
0,0,43,45,15,15,15,15,15,43,44,0,0
0,43,45,15,15,16,15,15,15,15,43,44,0
43,45,15,15,15,15,15,15,15,15,15,43,44
45,15,15,16,15,15,15,15,15,15,15,15,44
45,15,15,15,15,15,10,15,15,15,16,15,44
45,15,15,15,15,11,15,12,15,15,15,15,44
45,15,15,15,15,15,13,16,15,15,15,15,44
45,15,15,15,16,15,15,16,16,15,15,15,44
46,45,15,15,15,15,15,15,15,15,15,44,46
0,46,45,15,15,16,15,15,15,15,44,46,0
0,0,46,45,15,15,15,15,15,44,46,0,0
0,0,0,45,46,46,46,46,46,44,0,0,0
:endlayer
layer: 16
0,0,0,15,21,15,21,15,21,15,0,0,0
0,0,15,0,0,0,0,0,0,0,15,0,0
0,15,0,0,0,0,0,0,0,0,0,16,0
15,0,0,0,0,0,0,0,0,0,0,0,15
30,0,0,0,0,0,0,0,0,0,0,0,31
16,0,0,0,0,0,10,0,0,0,0,0,15
30,0,0,0,0,11,15,12,0,0,0,0,31
15,0,0,0,0,0,13,0,0,0,0,0,16
30,0,0,0,0,0,0,0,0,0,0,0,31
15,0,0,0,0,0,0,0,0,0,0,0,15
0,15,0,0,0,0,0,0,0,0,0,15,0
0,0,15,0,0,0,0,0,0,0,15,0,0
0,0,0,15,37,15,37,15,37,15,0,0,0
:endlayer
layer: 17
0,0,0,15,0,15,0,15,0,15,0,0,0
0,0,15,0,0,0,0,0,0,0,15,0,0
0,15,0,0,0,0,0,0,0,0,0,15,0
15,0,0,0,0,0,0,0,0,0,0,0,15
0,0,0,0,0,0,0,0,0,0,0,0,0
15,0,0,0,0,0,0,0,0,0,0,0,15
0,0,0,0,0,0,15,0,0,0,0,0,0
15,0,0,0,0,0,0,0,0,0,0,0,15
0,0,0,0,0,0,0,0,0,0,0,0,0
15,0,0,0,0,0,0,0,0,0,0,0,16
0,15,0,0,0,0,0,0,0,0,0,15,0
0,0,15,0,0,0,0,0,0,0,15,0,0
0,0,0,15,0,15,0,16,0,15,0,0,0
:endlayer
layer: 18
0,0,0,15,38,15,38,15,38,15,0,0,0
0,0,15,18,0,0,0,0,0,18,15,0,0
0,15,0,0,0,0,0,0,0,0,0,15,0
15,20,0,0,0,0,0,0,0,0,0,19,15
38,0,0,0,0,0,0,0,0,0,0,0,38
15,0,0,0,0,0,17,0,0,0,0,0,15
38,0,0,0,0,19,15,20,0,0,0,0,38
15,0,0,0,0,0,18,0,0,0,0,0,15
38,0,0,0,0,0,0,0,0,0,0,0,38
15,20,0,0,0,0,0,0,0,0,0,19,15
0,15,0,0,0,0,0,0,0,0,0,15,0
0,0,16,17,0,0,0,0,0,17,15,0,0
0,0,0,15,38,15,38,15,38,15,0,0,0
:endlayer
layer: 19
0,0,0,47,0,47,0,47,0,47,0,0,0
0,0,0,0,0,0,0,0,0,0,0,0,0
0,0,0,0,0,0,0,0,0,0,0,0,0
47,0,0,0,0,0,0,0,0,0,0,0,47
0,0,0,0,0,0,0,0,0,0,0,0,0
47,0,0,0,0,0,0,0,0,0,0,0,47
0,0,0,0,0,0,48,0,0,0,0,0,0
47,0,0,0,0,0,0,0,0,0,0,0,47
0,0,0,0,0,0,0,0,0,0,0,0,0
47,0,0,0,0,0,0,0,0,0,0,0,47
0,0,0,0,0,0,0,0,0,0,0,0,0
0,0,0,0,0,0,0,0,0,0,0,0,0
0,0,0,47,0,47,0,47,0,47,0,0,0
:endlayer
layer: 20
0,0,0,0,0,0,0,0,0,0,0,0,0
0,0,0,0,0,0,0,0,0,0,0,0,0
0,0,0,0,0,0,0,0,0,0,0,0,0
0,0,0,0,0,0,0,0,0,0,0,0,0
0,0,0,0,0,0,0,0,0,0,0,0,0
0,0,0,0,0,0,0,0,0,0,0,0,0
0,0,0,0,0,0,48,0,0,0,0,0,0
0,0,0,0,0,0,0,0,0,0,0,0,0
0,0,0,0,0,0,0,0,0,0,0,0,0
0,0,0,0,0,0,0,0,0,0,0,0,0
0,0,0,0,0,0,0,0,0,0,0,0,0
0,0,0,0,0,0,0,0,0,0,0,0,0
0,0,0,0,0,0,0,0,0,0,0,0,0
:endlayer
layer: 21
0,0,0,0,0,0,0,0,0,0,0,0,0
0,0,0,0,0,0,0,0,0,0,0,0,0
0,0,0,0,0,0,0,0,0,0,0,0,0
0,0,0,0,0,0,0,0,0,0,0,0,0
0,0,0,0,0,0,0,0,0,0,0,0,0
0,0,0,0,0,0,0,0,0,0,0,0,0
0,0,0,0,0,0,48,0,0,0,0,0,0
0,0,0,0,0,0,0,0,0,0,0,0,0
0,0,0,0,0,0,0,0,0,0,0,0,0
0,0,0,0,0,0,0,0,0,0,0,0,0
0,0,0,0,0,0,0,0,0,0,0,0,0
0,0,0,0,0,0,0,0,0,0,0,0,0
0,0,0,0,0,0,0,0,0,0,0,0,0
:endlayer
layer: 22
0,0,0,0,0,0,0,0,0,0,0,0,0
0,0,0,0,0,0,0,0,0,0,0,0,0
0,0,0,0,0,0,0,0,0,0,0,0,0
0,0,0,0,0,0,0,0,0,0,0,0,0
0,0,0,0,0,0,0,0,0,0,0,0,0
0,0,0,0,0,0,0,0,0,0,0,0,0
0,0,0,0,0,0,48,0,0,0,0,0,0
0,0,0,0,0,0,0,0,0,0,0,0,0
0,0,0,0,0,0,0,0,0,0,0,0,0
0,0,0,0,0,0,0,0,0,0,0,0,0
0,0,0,0,0,0,0,0,0,0,0,0,0
0,0,0,0,0,0,0,0,0,0,0,0,0
0,0,0,0,0,0,0,0,0,0,0,0,0
:endlayer
layer: 23
0,0,0,0,0,0,0,0,0,0,0,0,0
0,0,0,0,0,0,0,0,0,0,0,0,0
0,0,0,0,0,0,0,0,0,0,0,0,0
0,0,0,0,0,0,0,0,0,0,0,0,0
0,0,0,0,0,0,0,0,0,0,0,0,0
0,0,0,0,0,0,0,0,0,0,0,0,0
0,0,0,0,0,0,48,49,0,49,0,0,0
0,0,0,0,0,0,0,0,49,0,0,0,0
0,0,0,0,0,0,0,0,0,0,0,0,0
0,0,0,0,0,0,0,0,0,0,0,0,0
0,0,0,0,0,0,0,0,0,0,0,0,0
0,0,0,0,0,0,0,0,0,0,0,0,0
0,0,0,0,0,0,0,0,0,0,0,0,0
:endlayer
layer: 24
0,0,0,0,0,0,0,0,0,0,0,0,0
0,0,0,0,0,0,0,0,0,0,0,0,0
0,0,0,0,0,0,0,0,0,0,0,0,0
0,0,0,0,0,0,0,0,0,0,0,0,0
0,0,0,0,0,0,0,0,0,0,0,0,0
0,0,0,0,0,0,0,0,0,0,0,0,0
0,0,0,0,0,0,48,50,0,50,0,0,0
0,0,0,0,0,0,0,0,50,0,0,0,0
0,0,0,0,0,0,0,0,0,0,0,0,0
0,0,0,0,0,0,0,0,0,0,0,0,0
0,0,0,0,0,0,0,0,0,0,0,0,0
0,0,0,0,0,0,0,0,0,0,0,0,0
0,0,0,0,0,0,0,0,0,0,0,0,0
:endlayer
layer: 25
0,0,0,0,0,0,0,0,0,0,0,0,0
0,0,0,0,0,0,0,0,0,0,0,0,0
0,0,0,0,0,0,0,0,0,0,0,0,0
0,0,0,0,0,0,0,0,0,0,0,0,0
0,0,0,0,0,0,0,0,0,0,0,0,0
0,0,0,0,0,0,0,0,0,0,0,0,0
0,0,0,0,0,0,47,51,0,51,0,0,0
0,0,0,0,0,0,0,0,51,0,0,0,0
0,0,0,0,0,0,0,0,0,0,0,0,0
0,0,0,0,0,0,0,0,0,0,0,0,0
0,0,0,0,0,0,0,0,0,0,0,0,0
0,0,0,0,0,0,0,0,0,0,0,0,0
0,0,0,0,0,0,0,0,0,0,0,0,0
:endlayer

#### RULES ####
rule:
plugin=vanillaBlocks
number=1
data:
tag:
TAG=10={
TAG=8=blockName{grass}
TAG=3=meta{0}
TAG=3=buildPass{0}
}
:endtag
:enddata
:endrule

rule:
plugin=vanillaBlocks
number=2
data:
tag:
TAG=10={
TAG=8=blockName{cobblestone}
TAG=3=meta{0}
TAG=3=buildPass{0}
}
:endtag
:enddata
:endrule

rule:
plugin=vanillaBlocks
number=3
data:
tag:
TAG=10={
TAG=8=blockName{dirt}
TAG=3=meta{0}
TAG=3=buildPass{0}
}
:endtag
:enddata
:endrule

rule:
plugin=vanillaBlocks
number=4
data:
tag:
TAG=10={
TAG=8=blockName{log}
TAG=3=meta{4}
TAG=3=buildPass{0}
}
:endtag
:enddata
:endrule

rule:
plugin=vanillaBlocks
number=5
data:
tag:
TAG=10={
TAG=8=blockName{log}
TAG=3=meta{5}
TAG=3=buildPass{0}
}
:endtag
:enddata
:endrule

rule:
plugin=vanillaBlocks
number=6
data:
tag:
TAG=10={
TAG=8=blockName{stone_button}
TAG=3=meta{4}
TAG=3=buildPass{0}
}
:endtag
:enddata
:endrule

rule:
plugin=vanillaBlocks
number=7
data:
tag:
TAG=10={
TAG=8=blockName{stone_button}
TAG=3=meta{3}
TAG=3=buildPass{0}
}
:endtag
:enddata
:endrule

rule:
plugin=vanillaSign
number=8
data:
tag:
TAG=10={
TAG=8=signContents1{Barracks}
TAG=8=blockName{standing_sign}
TAG=8=signContents2{by}
TAG=8=signContents0{Village}
TAG=8=signContents3{HuntingBlock}
TAG=3=meta{12}
TAG=3=buildPass{1}
}
:endtag
:enddata
:endrule

rule:
plugin=vanillaBlocks
number=9
data:
tag:
TAG=10={
TAG=8=blockName{stone_button}
TAG=3=meta{1}
TAG=3=buildPass{0}
}
:endtag
:enddata
:endrule

rule:
plugin=vanillaBlocks
number=10
data:
tag:
TAG=10={
TAG=8=blockName{ladder}
TAG=3=meta{2}
TAG=3=buildPass{1}
}
:endtag
:enddata
:endrule

rule:
plugin=vanillaBlocks
number=11
data:
tag:
TAG=10={
TAG=8=blockName{ladder}
TAG=3=meta{4}
TAG=3=buildPass{1}
}
:endtag
:enddata
:endrule

rule:
plugin=vanillaBlocks
number=12
data:
tag:
TAG=10={
TAG=8=blockName{ladder}
TAG=3=meta{5}
TAG=3=buildPass{1}
}
:endtag
:enddata
:endrule

rule:
plugin=vanillaBlocks
number=13
data:
tag:
TAG=10={
TAG=8=blockName{ladder}
TAG=3=meta{3}
TAG=3=buildPass{1}
}
:endtag
:enddata
:endrule

rule:
plugin=vanillaBlocks
number=14
data:
tag:
TAG=10={
TAG=8=blockName{stone_button}
TAG=3=meta{2}
TAG=3=buildPass{0}
}
:endtag
:enddata
:endrule

rule:
plugin=vanillaBlocks
number=15
data:
tag:
TAG=10={
TAG=8=blockName{stonebrick}
TAG=3=meta{0}
TAG=3=buildPass{0}
}
:endtag
:enddata
:endrule

rule:
plugin=vanillaBlocks
number=16
data:
tag:
TAG=10={
TAG=8=blockName{stonebrick}
TAG=3=meta{2}
TAG=3=buildPass{0}
}
:endtag
:enddata
:endrule

rule:
plugin=vanillaBlocks
number=17
data:
tag:
TAG=10={
TAG=8=blockName{torch}
TAG=3=meta{4}
TAG=3=buildPass{1}
}
:endtag
:enddata
:endrule

rule:
plugin=vanillaBlocks
number=18
data:
tag:
TAG=10={
TAG=8=blockName{torch}
TAG=3=meta{3}
TAG=3=buildPass{1}
}
:endtag
:enddata
:endrule

rule:
plugin=vanillaBlocks
number=19
data:
tag:
TAG=10={
TAG=8=blockName{torch}
TAG=3=meta{2}
TAG=3=buildPass{1}
}
:endtag
:enddata
:endrule

rule:
plugin=vanillaBlocks
number=20
data:
tag:
TAG=10={
TAG=8=blockName{torch}
TAG=3=meta{1}
TAG=3=buildPass{1}
}
:endtag
:enddata
:endrule

rule:
plugin=vanillaBlocks
number=21
data:
tag:
TAG=10={
TAG=8=blockName{stone_brick_stairs}
TAG=3=meta{3}
TAG=3=buildPass{0}
}
:endtag
:enddata
:endrule

rule:
plugin=vanillaBlocks
number=22
data:
tag:
TAG=10={
TAG=8=blockName{bed}
TAG=3=meta{10}
TAG=3=buildPass{0}
}
:endtag
:enddata
:endrule

rule:
plugin=vanillaInventory
number=23
data:
tag:
TAG=10={
TAG=3=lootLevel{0}
TAG=10=teData{
TAG=9=Items{
}
TAG=8=id{Chest}
}
TAG=8=blockName{chest}
TAG=3=meta{3}
TAG=3=buildPass{0}
}
:endtag
:enddata
:endrule

rule:
plugin=vanillaBlocks
number=24
data:
tag:
TAG=10={
TAG=8=blockName{bookshelf}
TAG=3=meta{0}
TAG=3=buildPass{0}
}
:endtag
:enddata
:endrule

rule:
plugin=vanillaBlocks
number=25
data:
tag:
TAG=10={
TAG=8=blockName{bed}
TAG=3=meta{2}
TAG=3=buildPass{0}
}
:endtag
:enddata
:endrule

rule:
plugin=vanillaBlocks
number=26
data:
tag:
TAG=10={
TAG=8=blockName{bed}
TAG=3=meta{9}
TAG=3=buildPass{0}
}
:endtag
:enddata
:endrule

rule:
plugin=vanillaBlocks
number=27
data:
tag:
TAG=10={
TAG=8=blockName{bed}
TAG=3=meta{1}
TAG=3=buildPass{0}
}
:endtag
:enddata
:endrule

rule:
plugin=vanillaBlocks
number=28
data:
tag:
TAG=10={
TAG=8=blockName{bed}
TAG=3=meta{3}
TAG=3=buildPass{0}
}
:endtag
:enddata
:endrule

rule:
plugin=vanillaBlocks
number=29
data:
tag:
TAG=10={
TAG=8=blockName{bed}
TAG=3=meta{11}
TAG=3=buildPass{0}
}
:endtag
:enddata
:endrule

rule:
plugin=vanillaBlocks
number=30
data:
tag:
TAG=10={
TAG=8=blockName{stone_brick_stairs}
TAG=3=meta{1}
TAG=3=buildPass{0}
}
:endtag
:enddata
:endrule

rule:
plugin=vanillaBlocks
number=31
data:
tag:
TAG=10={
TAG=8=blockName{stone_brick_stairs}
TAG=3=meta{0}
TAG=3=buildPass{0}
}
:endtag
:enddata
:endrule

rule:
plugin=vanillaInventory
number=32
data:
tag:
TAG=10={
TAG=3=lootLevel{0}
TAG=10=teData{
TAG=9=Items{
}
TAG=8=id{Chest}
}
TAG=8=blockName{chest}
TAG=3=meta{5}
TAG=3=buildPass{0}
}
:endtag
:enddata
:endrule

rule:
plugin=vanillaInventory
number=33
data:
tag:
TAG=10={
TAG=3=lootLevel{0}
TAG=10=teData{
TAG=9=Items{
}
TAG=8=id{Chest}
}
TAG=8=blockName{chest}
TAG=3=meta{4}
TAG=3=buildPass{0}
}
:endtag
:enddata
:endrule

rule:
plugin=vanillaBlocks
number=34
data:
tag:
TAG=10={
TAG=8=blockName{bed}
TAG=3=meta{0}
TAG=3=buildPass{0}
}
:endtag
:enddata
:endrule

rule:
plugin=vanillaBlocks
number=35
data:
tag:
TAG=10={
TAG=8=blockName{bed}
TAG=3=meta{8}
TAG=3=buildPass{0}
}
:endtag
:enddata
:endrule

rule:
plugin=vanillaInventory
number=36
data:
tag:
TAG=10={
TAG=3=lootLevel{0}
TAG=10=teData{
TAG=9=Items{
}
TAG=8=id{Chest}
}
TAG=8=blockName{chest}
TAG=3=meta{2}
TAG=3=buildPass{0}
}
:endtag
:enddata
:endrule

rule:
plugin=vanillaBlocks
number=37
data:
tag:
TAG=10={
TAG=8=blockName{stone_brick_stairs}
TAG=3=meta{2}
TAG=3=buildPass{0}
}
:endtag
:enddata
:endrule

rule:
plugin=vanillaBlocks
number=38
data:
tag:
TAG=10={
TAG=8=blockName{stone_slab}
TAG=3=meta{13}
TAG=3=buildPass{0}
}
:endtag
:enddata
:endrule

rule:
plugin=vanillaInventory
number=39
data:
tag:
TAG=10={
TAG=3=lootLevel{0}
TAG=10=teData{
TAG=9=Items{
}
TAG=8=id{Chest}
}
TAG=8=blockName{chest}
TAG=3=meta{3}
TAG=3=buildPass{0}
}
:endtag
:enddata
:endrule

rule:
plugin=vanillaInventory
number=40
data:
tag:
TAG=10={
TAG=3=lootLevel{0}
TAG=10=teData{
TAG=9=Items{
}
TAG=8=id{Chest}
}
TAG=8=blockName{chest}
TAG=3=meta{5}
TAG=3=buildPass{0}
}
:endtag
:enddata
:endrule

rule:
plugin=vanillaInventory
number=41
data:
tag:
TAG=10={
TAG=3=lootLevel{0}
TAG=10=teData{
TAG=9=Items{
}
TAG=8=id{Chest}
}
TAG=8=blockName{chest}
TAG=3=meta{4}
TAG=3=buildPass{0}
}
:endtag
:enddata
:endrule

rule:
plugin=vanillaInventory
number=42
data:
tag:
TAG=10={
TAG=3=lootLevel{0}
TAG=10=teData{
TAG=9=Items{
}
TAG=8=id{Chest}
}
TAG=8=blockName{chest}
TAG=3=meta{2}
TAG=3=buildPass{0}
}
:endtag
:enddata
:endrule

rule:
plugin=vanillaBlocks
number=43
data:
tag:
TAG=10={
TAG=8=blockName{stone_brick_stairs}
TAG=3=meta{6}
TAG=3=buildPass{0}
}
:endtag
:enddata
:endrule

rule:
plugin=vanillaBlocks
number=44
data:
tag:
TAG=10={
TAG=8=blockName{stone_brick_stairs}
TAG=3=meta{5}
TAG=3=buildPass{0}
}
:endtag
:enddata
:endrule

rule:
plugin=vanillaBlocks
number=45
data:
tag:
TAG=10={
TAG=8=blockName{stone_brick_stairs}
TAG=3=meta{4}
TAG=3=buildPass{0}
}
:endtag
:enddata
:endrule

rule:
plugin=vanillaBlocks
number=46
data:
tag:
TAG=10={
TAG=8=blockName{stone_brick_stairs}
TAG=3=meta{7}
TAG=3=buildPass{0}
}
:endtag
:enddata
:endrule

rule:
plugin=vanillaBlocks
number=47
data:
tag:
TAG=10={
TAG=8=blockName{stone_slab}
TAG=3=meta{5}
TAG=3=buildPass{0}
}
:endtag
:enddata
:endrule

rule:
plugin=vanillaBlocks
number=48
data:
tag:
TAG=10={
TAG=8=blockName{cobblestone_wall}
TAG=3=meta{0}
TAG=3=buildPass{0}
}
:endtag
:enddata
:endrule

rule:
plugin=vanillaBlocks
number=49
data:
tag:
TAG=10={
TAG=8=blockName{stone_slab}
TAG=3=meta{15}
TAG=3=buildPass{0}
}
:endtag
:enddata
:endrule

rule:
plugin=vanillaBlocks
number=50
data:
tag:
TAG=10={
TAG=8=blockName{wool}
TAG=3=meta{14}
TAG=3=buildPass{0}
}
:endtag
:enddata
:endrule

rule:
plugin=vanillaBlocks
number=51
data:
tag:
TAG=10={
TAG=8=blockName{stone_slab}
TAG=3=meta{7}
TAG=3=buildPass{0}
}
:endtag
:enddata
:endrule

#### ENTITIES ####
entity:
plugin=awGates
number=0
data:
position=6,1,1
tag:
TAG=10={
TAG=10=pos1{
TAG=3=z{0}
TAG=3=y{0}
TAG=3=x{-1}
}
TAG=1=orientation{2}
TAG=10=pos2{
TAG=3=z{0}
TAG=3=y{3}
TAG=3=x{1}
}
TAG=8=gateType{gate.verticalIron}
}
:endtag
:enddata
:endentity

entity:
plugin=awGates
number=1
data:
position=1,1,6
tag:
TAG=10={
TAG=10=pos1{
TAG=3=z{-1}
TAG=3=y{0}
TAG=3=x{0}
}
TAG=1=orientation{1}
TAG=10=pos2{
TAG=3=z{1}
TAG=3=y{3}
TAG=3=x{0}
}
TAG=8=gateType{gate.verticalIron}
}
:endtag
:enddata
:endentity

entity:
plugin=awGates
number=2
data:
position=6,1,11
tag:
TAG=10={
TAG=10=pos1{
TAG=3=z{0}
TAG=3=y{0}
TAG=3=x{-1}
}
TAG=1=orientation{0}
TAG=10=pos2{
TAG=3=z{0}
TAG=3=y{3}
TAG=3=x{1}
}
TAG=8=gateType{gate.verticalIron}
}
:endtag
:enddata
:endentity

entity:
plugin=awGates
number=3
data:
position=11,1,6
tag:
TAG=10={
TAG=10=pos1{
TAG=3=z{-1}
TAG=3=y{0}
TAG=3=x{0}
}
TAG=1=orientation{3}
TAG=10=pos2{
TAG=3=z{1}
TAG=3=y{3}
TAG=3=x{0}
}
TAG=8=gateType{gate.verticalIron}
}
:endtag
:enddata
:endentity

