# Ancient Warfare Structure Template File
# auto-generated structure file. created on: 4/17/2014 at: 16:56:1
# Lines beginning with # denote comments

header:
version=2.0
name=windmill_czarified
size=25,29,15
offset=12,0,14
:endheader

#### VALIDATION ####
validation:
type=ground
survival=false
worldGenEnabled=false
unique=false
preserveBlocks=false
selectionWeight=1
clusterValue=1
minDuplicateDistance=1
dimensionWhiteList=false
dimensionList=
biomeWhiteList=false
biomeList=
leveling=0
fill=0
border=0
validTargetBlocks=clay,lapis_ore,lit_redstone_ore,stone,tile.bop.mud,gravel,coal_block,diamond_ore,ice,snow,netherrack,tile.bop.generic.hard_dirt,tile.bop.redRocks,dirt,redstone_ore,mycelium,tile.bop.holyStone,sand,grass,tile.bop.ash,iron_ore,tile.bop.originGrass,snow_layer,soul_sand,tile.bop.generic.dried_dirt,stained_hardened_clay,tile.extrabiomes.redrock,tile.bop.generic.hard_ice,tile.bop.generic.ash_stone,coal_ore,gold_ore,tile.bop.generic.hard_sand
data:
:enddata
:endvalidation

#### LAYERS ####
layer: 0
0,0,0,0,0,0,0,0,1,2,3,2,2,2,3,2,1,0,0,0,0,0,0,0,0
0,0,0,0,0,0,0,4,2,2,3,5,6,6,3,2,2,4,0,0,0,0,0,0,0
0,0,0,0,0,0,7,2,2,6,0,0,0,0,0,5,2,2,8,0,0,0,0,0,0
0,0,0,0,0,1,2,2,5,0,0,0,0,0,0,0,6,2,2,1,0,0,0,0,0
0,0,0,0,0,2,2,5,0,0,0,9,9,9,0,0,0,6,2,2,0,0,0,0,0
0,0,0,0,0,3,3,0,0,0,9,10,10,10,9,0,0,0,3,3,0,0,0,0,0
0,0,0,0,0,2,5,0,0,9,10,10,10,10,10,9,0,0,6,2,0,0,0,0,0
0,0,0,0,0,2,6,11,0,9,10,10,9,10,10,9,0,0,5,2,0,0,0,0,0
0,0,0,0,0,2,6,0,0,9,10,10,10,10,10,9,0,0,6,2,0,0,0,0,0
0,0,0,0,0,3,3,0,0,0,9,10,10,10,9,0,0,0,3,3,0,0,0,0,0
0,0,0,0,0,2,2,6,0,0,0,9,9,9,0,0,0,5,2,2,0,0,0,0,0
0,0,0,0,0,1,2,2,5,0,0,0,0,0,0,0,6,2,2,1,0,0,0,0,0
0,0,0,0,0,0,7,2,2,6,0,0,0,0,0,6,2,2,8,0,0,0,0,0,0
0,0,0,0,0,0,0,12,2,2,3,0,0,0,3,2,2,12,0,0,0,0,0,0,0
0,0,0,0,0,0,0,0,1,2,3,13,0,14,3,2,1,0,0,0,0,0,0,0,0
:endlayer
layer: 1
0,0,0,0,0,0,0,0,0,0,0,2,2,2,0,0,0,0,0,0,0,0,0,0,0
0,0,0,0,0,0,0,0,2,13,3,6,5,5,3,13,2,0,0,0,0,0,0,0,0
0,0,0,0,0,0,0,2,15,0,0,0,0,0,0,0,16,2,0,0,0,0,0,0,0
0,0,0,0,0,0,2,17,0,0,0,0,0,0,0,0,0,17,2,0,0,0,0,0,0
0,0,0,0,0,0,13,0,0,0,0,0,0,0,0,0,0,0,13,0,0,0,0,0,0
0,0,0,0,0,0,3,0,0,0,0,0,0,0,0,0,0,0,3,0,0,0,0,0,0
0,0,0,0,0,2,6,0,0,0,0,0,0,0,0,0,0,0,5,2,0,0,0,0,0
0,0,0,0,0,2,6,11,0,0,2,18,19,0,0,0,0,0,6,2,0,0,0,0,0
0,0,0,0,0,2,6,0,0,0,0,0,0,0,0,0,0,0,6,2,0,0,0,0,0
0,0,0,0,0,0,3,0,0,0,0,0,0,0,0,0,0,0,3,0,0,0,0,0,0
0,0,0,0,0,0,14,0,0,0,0,0,0,0,0,0,0,0,13,0,0,0,0,0,0
0,0,0,0,0,0,2,20,0,0,0,0,0,0,0,0,0,20,2,0,0,0,0,0,0
0,0,0,0,0,0,0,2,15,0,0,0,0,0,0,0,16,2,0,0,0,0,0,0,0
0,0,0,0,0,0,0,0,2,13,3,0,0,0,3,13,2,0,0,0,0,0,0,0,0
0,0,0,0,0,0,0,0,0,0,0,13,0,13,0,0,0,0,0,0,0,0,0,0,0
:endlayer
layer: 2
0,0,0,0,0,0,0,0,0,0,0,0,2,0,0,0,0,0,0,0,0,0,0,0,0
0,0,0,0,0,0,0,0,0,14,3,14,5,14,3,13,0,0,0,0,0,0,0,0,0
0,0,0,0,0,0,0,2,13,0,0,0,0,0,0,0,13,2,0,0,0,0,0,0,0
0,0,0,0,0,0,0,13,0,0,0,0,0,0,0,0,0,13,0,0,0,0,0,0,0
0,0,0,0,0,0,13,0,0,0,0,0,0,0,0,0,0,0,14,0,0,0,0,0,0
0,0,0,0,0,0,3,0,0,0,0,0,0,0,0,0,0,0,3,0,0,0,0,0,0
0,0,0,0,0,0,13,0,0,0,0,0,0,0,0,0,0,0,14,0,0,0,0,0,0
0,0,0,0,0,2,5,11,0,0,0,0,18,0,0,0,0,0,6,2,0,0,0,0,0
0,0,0,0,0,0,13,0,0,0,0,0,0,0,0,0,0,0,13,0,0,0,0,0,0
0,0,0,0,0,0,3,0,0,0,0,0,0,0,0,0,0,0,3,0,0,0,0,0,0
0,0,0,0,0,0,13,0,0,0,0,0,0,0,0,0,0,0,13,0,0,0,0,0,0
0,0,0,0,0,0,0,13,0,0,0,0,0,0,0,0,0,13,0,0,0,0,0,0,0
0,0,0,0,0,0,0,2,13,0,0,0,0,0,0,0,13,2,0,0,0,0,0,0,0
0,0,0,0,0,0,0,0,0,13,3,21,0,21,3,14,0,0,0,0,0,0,0,0,0
0,0,0,0,0,0,0,0,0,0,0,0,22,0,0,0,0,0,0,0,0,0,0,0,0
:endlayer
layer: 3
0,0,0,0,0,0,0,0,0,0,0,0,0,0,0,0,0,0,0,0,0,0,0,0,0
0,0,0,0,0,0,0,0,0,23,3,14,13,13,3,23,0,0,0,0,0,0,0,0,0
0,0,0,0,0,0,0,0,24,0,25,25,25,25,25,0,26,0,0,0,0,0,0,0,0
0,0,0,0,0,0,0,23,3,25,25,25,25,25,25,25,3,23,0,0,0,0,0,0,0
0,0,0,0,0,0,24,0,25,25,25,25,25,25,25,25,25,0,26,0,0,0,0,0,0
0,0,0,0,0,0,3,25,25,25,25,25,25,25,25,25,25,25,3,0,0,0,0,0,0
0,0,0,0,0,0,13,25,25,25,25,25,0,25,25,25,25,25,13,0,0,0,0,0,0
0,0,0,0,0,0,14,11,25,25,25,0,19,0,25,25,25,25,13,0,0,0,0,0,0
0,0,0,0,0,0,13,25,25,25,25,25,0,25,25,25,25,25,14,0,0,0,0,0,0
0,0,0,0,0,0,3,25,25,25,25,25,25,25,25,25,25,25,3,0,0,0,0,0,0
0,0,0,0,0,0,24,0,25,25,25,25,25,25,25,25,25,0,26,0,0,0,0,0,0
0,0,0,0,0,0,0,27,3,25,25,25,25,25,25,25,3,27,0,0,0,0,0,0,0
0,0,0,0,0,0,0,0,24,0,25,25,25,25,25,0,26,0,0,0,0,0,0,0,0
0,0,0,0,0,0,0,0,0,27,3,14,13,13,3,27,0,0,0,0,0,0,0,0,0
0,0,0,0,0,0,0,0,0,0,0,0,0,0,0,0,0,0,0,0,0,0,0,0,0
:endlayer
layer: 4
0,0,0,0,0,0,0,0,0,0,0,0,0,0,0,0,0,0,0,0,0,0,0,0,0
0,0,0,0,0,0,0,0,0,0,3,14,14,13,3,0,0,0,0,0,0,0,0,0,0
0,0,0,0,0,0,0,0,0,13,0,28,28,28,0,13,0,0,0,0,0,0,0,0,0
0,0,0,0,0,0,0,0,3,0,29,28,28,28,30,0,3,0,0,0,0,0,0,0,0
0,0,0,0,0,0,0,14,0,0,0,28,28,28,0,0,31,13,0,0,0,0,0,0,0
0,0,0,0,0,0,3,0,0,0,0,0,0,0,0,0,31,28,3,0,0,0,0,0,0
0,0,0,0,0,0,14,0,0,0,0,32,0,32,0,0,0,28,13,0,0,0,0,0,0
0,0,0,0,0,0,13,0,0,0,0,0,19,0,0,0,33,3,14,0,0,0,0,0,0
0,0,0,0,0,0,13,0,0,0,0,32,0,32,0,0,0,31,13,0,0,0,0,0,0
0,0,0,0,0,0,3,0,0,0,0,0,0,0,0,0,34,28,3,0,0,0,0,0,0
0,0,0,0,0,0,0,13,0,0,0,28,28,28,0,0,34,13,0,0,0,0,0,0,0
0,0,0,0,0,0,0,0,3,0,28,28,28,28,28,0,3,0,0,0,0,0,0,0,0
0,0,0,0,0,0,0,0,0,13,28,28,28,28,28,13,0,0,0,0,0,0,0,0,0
0,0,0,0,0,0,0,0,0,0,3,13,14,13,3,0,0,0,0,0,0,0,0,0,0
0,0,0,0,0,0,0,0,0,0,0,0,0,0,0,0,0,0,0,0,0,0,0,0,0
:endlayer
layer: 5
0,0,0,0,0,0,0,0,0,0,0,0,0,0,0,0,0,0,0,0,0,0,0,0,0
0,0,0,0,0,0,0,0,0,0,35,6,3,5,35,0,0,0,0,0,0,0,0,0,0
0,0,0,0,0,0,0,0,0,14,0,0,28,0,0,14,0,0,0,0,0,0,0,0,0
0,0,0,0,0,0,0,0,3,15,0,29,28,30,0,0,3,0,0,0,0,0,0,0,0
0,0,0,0,0,0,0,13,17,0,0,0,28,0,0,0,34,13,0,0,0,0,0,0,0
0,0,0,0,0,0,36,0,0,0,0,0,0,0,0,0,0,34,37,0,0,0,0,0,0
0,0,0,0,0,0,6,0,0,0,0,0,0,0,0,0,0,0,6,0,0,0,0,0,0
0,0,0,0,0,0,3,0,0,0,0,0,19,0,0,0,33,3,3,0,0,0,0,0,0
0,0,0,0,0,0,6,0,0,0,0,0,0,0,0,0,0,0,5,0,0,0,0,0,0
0,0,0,0,0,0,36,0,0,0,0,0,0,0,0,0,0,0,37,0,0,0,0,0,0
0,0,0,0,0,0,0,13,20,0,0,0,0,0,0,0,34,13,0,0,0,0,0,0,0
0,0,0,0,0,0,0,0,3,15,0,34,28,28,0,0,3,0,0,0,0,0,0,0,0
0,0,0,0,0,0,0,0,0,13,0,28,28,28,0,14,0,0,0,0,0,0,0,0,0
0,0,0,0,0,0,0,0,0,0,38,6,3,6,38,0,0,0,0,0,0,0,0,0,0
0,0,0,0,0,0,0,0,0,0,0,0,0,0,0,0,0,0,39,39,39,39,39,0,0
:endlayer
layer: 6
0,0,0,0,0,0,0,0,0,0,0,0,0,0,0,0,0,0,0,0,0,0,0,0,0
0,0,0,0,0,0,0,0,0,0,0,0,35,0,0,0,0,0,0,0,0,0,0,0,0
0,0,0,0,0,0,0,0,0,19,3,5,3,6,3,19,0,0,0,0,0,0,0,0,0
0,0,0,0,0,0,0,0,3,5,0,0,40,0,0,6,3,0,0,0,0,0,0,0,0
0,0,0,0,0,0,0,19,6,0,0,0,0,0,0,0,5,19,0,0,0,0,0,0,0
0,0,0,0,0,0,0,3,0,0,0,0,0,0,0,0,0,3,0,0,0,0,0,0,0
0,0,0,0,0,0,0,5,0,0,0,0,0,0,0,0,0,5,0,0,0,0,0,0,0
0,0,0,0,0,0,36,3,0,0,0,0,19,0,0,0,33,3,37,0,0,0,0,0,0
0,0,0,0,0,0,0,6,0,0,0,0,0,0,0,0,0,6,0,0,0,0,0,0,0
0,0,0,0,0,0,0,3,0,0,0,0,0,0,0,0,0,3,0,0,0,0,0,0,0
0,0,0,0,0,0,0,19,6,0,0,0,0,0,0,0,6,19,0,0,0,0,0,0,0
0,0,0,0,0,0,0,0,3,5,0,0,34,0,0,5,3,0,0,0,0,0,0,0,0
0,0,0,0,0,0,0,0,0,19,3,6,3,5,3,19,0,0,0,0,0,0,0,0,0
0,0,39,39,0,0,0,0,0,0,0,0,38,0,0,0,0,0,0,0,0,0,0,0,0
0,39,0,0,0,0,0,0,0,0,0,0,0,0,0,0,0,39,41,41,41,41,41,39,0
:endlayer
layer: 7
0,0,0,0,0,0,0,0,0,0,0,0,0,0,0,0,0,0,0,0,0,0,0,0,0
0,0,0,0,0,0,0,0,0,0,0,0,20,0,0,0,0,0,0,0,0,0,0,0,0
0,0,0,0,0,0,0,0,0,0,3,5,3,6,3,0,0,0,0,0,0,0,0,0,0
0,0,0,0,0,0,0,0,19,6,25,0,25,0,25,6,19,0,0,0,0,0,0,0,0
0,0,0,0,0,0,0,0,6,0,25,25,25,25,25,0,5,0,0,0,0,0,0,0,0
0,0,0,0,0,0,0,3,25,25,25,0,0,0,25,25,25,3,0,0,0,0,0,0,0
0,0,0,0,0,0,0,5,0,25,0,0,0,0,0,25,0,6,0,0,0,0,0,0,0
0,0,0,0,0,0,16,3,25,25,0,0,19,0,0,25,33,3,15,0,0,0,0,0,0
0,0,0,0,0,0,0,6,0,25,0,0,0,0,0,25,0,6,0,0,0,0,0,0,0
0,0,0,0,0,0,0,3,25,25,25,0,0,0,25,25,25,3,0,0,0,0,0,0,0
0,0,0,0,0,0,0,0,5,0,25,25,25,25,25,0,6,0,0,0,0,0,0,0,0
0,0,0,0,0,0,0,0,19,5,25,0,25,0,25,6,19,0,0,0,0,0,0,0,0
0,0,0,0,39,0,0,0,0,0,3,5,3,6,3,0,0,0,0,0,0,0,0,0,0
0,0,41,41,0,0,0,0,0,0,0,0,17,0,0,0,0,0,0,0,0,0,41,39,0
39,41,0,0,0,0,0,0,0,0,0,0,0,0,0,0,39,41,41,41,41,41,0,0,0
:endlayer
layer: 8
0,0,0,0,0,0,0,0,0,0,0,0,0,0,0,0,0,0,0,0,0,0,0,0,0
0,0,0,0,0,0,0,0,0,0,0,0,0,0,0,0,0,0,0,0,0,0,0,0,0
0,0,0,0,0,0,0,0,0,0,3,23,3,23,3,0,0,0,0,0,0,0,0,0,0
0,0,0,0,0,0,0,0,0,5,0,3,0,3,0,6,0,0,0,0,0,0,0,0,0
0,0,0,0,0,0,0,0,6,3,0,0,0,0,0,3,5,0,0,0,0,0,0,0,0
0,0,0,0,0,0,0,3,34,0,0,0,0,0,0,0,0,3,0,0,0,0,0,0,0
0,0,0,0,0,0,0,24,3,0,0,0,0,0,0,0,3,26,0,0,0,0,0,0,0
0,0,0,0,0,0,0,3,0,0,0,0,19,0,0,0,0,3,0,0,0,0,0,0,0
0,0,0,0,0,0,0,24,3,0,0,0,0,0,0,33,3,26,0,0,0,0,0,0,0
0,0,0,0,0,0,0,3,0,0,0,0,0,0,0,0,34,3,0,0,0,0,0,0,0
0,0,0,0,0,0,0,0,5,3,0,0,0,0,0,3,5,0,0,0,0,0,0,0,0
0,0,0,0,0,0,0,0,0,6,0,3,0,3,34,6,0,0,0,0,0,0,0,0,0
0,0,0,0,0,39,0,0,0,0,3,27,3,27,3,0,0,0,0,0,0,0,0,0,0
0,0,0,41,41,0,0,0,0,0,0,0,0,0,0,0,0,0,0,0,0,41,41,39,0
39,41,41,0,0,0,0,0,0,0,0,0,0,0,0,39,41,41,41,41,41,0,0,0,0
:endlayer
layer: 9
0,0,0,0,0,0,0,0,0,0,0,0,0,0,0,0,0,0,0,0,0,0,0,0,0
0,0,0,0,0,0,0,0,0,0,0,0,0,0,0,0,0,0,0,0,0,0,0,0,0
0,0,0,0,0,0,0,0,0,0,3,0,19,0,3,0,0,0,0,0,0,0,0,0,0
0,0,0,0,0,0,0,0,0,6,0,3,0,3,0,6,0,0,0,0,0,0,0,0,0
0,0,0,0,0,0,0,0,5,3,0,0,0,0,0,3,6,0,0,0,0,0,0,0,0
0,0,0,0,0,0,0,3,34,0,0,0,0,0,0,0,0,3,0,0,0,0,0,0,0
0,0,0,0,0,0,0,0,3,0,0,0,0,0,0,0,3,0,0,0,0,0,0,0,0
0,0,0,0,0,0,0,19,0,0,0,0,19,0,0,0,0,19,0,0,0,0,0,0,0
0,0,0,0,0,0,0,0,3,0,0,0,0,0,0,33,3,0,0,0,0,0,0,0,0
0,0,0,0,0,0,0,3,0,0,0,0,0,0,0,0,31,3,0,0,0,0,0,0,0
0,0,0,0,0,0,0,0,6,3,0,0,0,0,0,3,5,0,0,0,0,0,0,0,0
0,0,0,0,0,0,0,0,0,6,0,3,0,3,34,5,0,0,0,0,0,0,0,0,0
0,0,0,0,0,0,39,0,0,0,3,0,19,0,3,0,0,0,0,0,0,0,39,0,0
0,0,0,41,41,41,0,0,0,0,0,0,0,0,0,0,0,0,0,41,41,41,0,0,0
39,41,41,0,0,0,0,0,0,0,0,0,0,0,39,41,41,41,41,0,0,0,0,0,0
:endlayer
layer: 10
0,0,0,0,0,0,0,0,0,0,0,0,0,0,0,0,0,0,0,0,0,0,0,0,0
0,0,0,0,0,0,0,0,0,0,0,0,0,0,0,0,0,0,0,0,0,0,0,0,0
0,0,0,0,0,0,0,0,0,0,35,0,19,0,35,0,0,0,0,0,0,0,0,0,0
0,0,0,0,0,0,0,0,0,36,42,3,0,3,42,37,0,0,0,0,0,0,0,0,0
0,0,0,0,0,0,0,0,35,3,15,0,0,0,16,3,35,0,0,0,0,0,0,0,0
0,0,0,0,0,0,0,36,42,17,0,0,0,0,0,17,42,37,0,0,0,0,0,0,0
0,0,0,0,0,0,0,0,3,0,0,0,0,0,0,0,3,0,0,0,0,0,0,0,0
0,0,0,0,0,0,0,19,0,0,0,0,19,0,0,0,0,19,0,0,0,0,0,0,0
0,0,0,0,0,0,0,0,3,0,0,0,0,0,0,33,3,0,0,0,0,0,0,0,0
0,0,0,0,0,0,0,36,42,20,0,0,0,0,0,20,42,37,0,0,0,0,0,0,0
0,0,0,0,0,0,0,0,38,3,15,0,0,0,16,3,38,0,0,0,0,0,0,0,0
0,0,0,0,0,0,0,0,0,36,42,3,0,3,42,37,0,0,0,0,0,0,0,0,0
0,0,0,0,0,0,0,39,0,0,38,0,19,0,38,0,0,0,0,0,0,39,0,0,0
0,0,0,0,41,41,41,0,0,0,0,0,0,0,0,0,0,0,41,41,41,0,0,0,0
39,41,41,41,0,0,0,0,0,0,0,0,0,0,39,41,41,41,0,0,0,0,0,0,0
:endlayer
layer: 11
0,0,0,0,0,0,0,0,0,0,0,0,0,0,0,0,0,0,0,0,0,0,0,0,0
0,0,0,0,0,0,0,0,0,0,0,0,0,0,0,0,0,0,0,0,0,0,0,0,0
0,0,0,0,0,0,0,0,0,0,0,0,35,0,0,0,0,0,0,0,0,0,0,0,0
0,0,0,0,0,0,0,0,0,0,42,3,42,3,42,0,0,0,0,0,0,0,0,0,0
0,0,0,0,0,0,0,0,0,3,0,0,0,0,0,3,0,0,0,0,0,0,0,0,0
0,0,0,0,0,0,0,0,42,0,0,0,0,0,0,0,42,0,0,0,0,0,0,0,0
0,0,0,0,0,0,0,0,3,0,0,0,0,0,0,0,3,0,0,0,0,0,0,0,0
0,0,0,0,0,0,0,36,42,0,0,0,19,0,0,0,42,37,0,0,0,0,0,0,0
0,0,0,0,0,0,0,0,3,0,0,0,0,0,0,33,3,0,0,0,0,0,0,0,0
0,0,0,0,0,0,0,0,42,0,0,0,0,0,0,0,42,0,0,0,0,0,0,0,0
0,0,0,0,0,0,0,0,0,3,0,0,0,0,0,3,0,0,0,0,0,0,0,0,0
0,0,0,0,0,0,0,0,0,0,42,3,42,3,42,0,0,0,0,0,0,0,0,0,0
0,0,0,0,0,0,0,0,39,0,0,0,38,0,0,0,0,0,0,0,39,0,0,0,0
0,0,0,0,0,41,41,41,0,0,0,0,0,0,0,0,0,41,41,41,0,0,0,0,0
39,41,41,41,41,0,0,0,0,0,0,0,0,39,41,41,41,0,0,0,0,0,0,0,0
:endlayer
layer: 12
0,0,0,0,0,0,0,0,0,0,0,0,0,0,0,0,0,0,0,0,0,0,0,0,0
0,0,0,0,0,0,0,0,0,0,0,0,0,0,0,0,0,0,0,0,0,0,0,0,0
0,0,0,0,0,0,0,0,0,0,0,0,0,0,0,0,0,0,0,0,0,0,0,0,0
0,0,0,0,0,0,0,0,0,0,42,3,42,3,42,0,0,0,0,0,0,0,0,0,0
0,0,0,0,0,0,0,0,0,3,0,0,0,0,0,3,0,0,0,0,0,0,0,0,0
0,0,0,0,0,0,0,0,42,0,0,0,0,0,0,0,42,0,0,0,0,0,0,0,0
0,0,0,0,0,0,0,0,3,0,0,0,0,0,0,0,3,0,0,0,0,0,0,0,0
0,0,0,0,0,0,0,0,42,0,0,0,19,0,0,0,42,0,0,0,0,0,0,0,0
0,0,0,0,0,0,0,0,3,0,0,0,0,0,0,33,3,0,0,0,0,0,0,0,0
0,0,0,0,0,0,0,0,42,0,0,0,0,0,0,0,42,0,0,0,0,0,0,0,0
0,0,0,0,0,0,0,0,0,3,0,0,0,0,0,3,0,0,0,0,0,0,0,0,0
0,0,0,0,0,0,0,0,0,0,42,3,42,3,42,0,0,0,0,0,0,0,0,0,0
0,0,0,0,0,0,0,0,39,0,0,0,0,0,0,0,0,0,0,39,0,0,0,0,0
0,0,0,0,0,0,41,41,0,0,0,0,0,0,0,0,41,41,41,0,0,0,0,0,0
0,39,41,41,41,41,0,0,0,0,0,0,0,39,41,41,0,0,0,0,0,0,0,0,0
:endlayer
layer: 13
0,0,0,0,0,0,0,0,0,0,0,0,0,0,0,0,0,0,0,0,0,0,0,0,0
0,0,0,0,0,0,0,0,0,0,0,0,0,0,0,0,0,0,0,0,0,0,0,0,0
0,0,0,0,0,0,0,0,0,0,0,0,0,0,0,0,0,0,0,0,0,0,0,0,0
0,0,0,0,0,0,0,0,0,0,42,3,42,3,42,0,0,0,0,0,0,0,0,0,0
0,0,0,0,0,0,0,0,0,3,25,25,25,25,25,3,0,0,0,0,0,0,0,0,0
0,0,0,0,0,0,0,0,42,25,25,25,25,25,25,25,42,0,0,0,0,0,0,0,0
0,0,0,0,0,0,0,0,3,25,25,25,0,25,25,25,3,0,0,0,0,0,0,0,0
0,0,0,0,0,0,0,0,42,25,25,0,19,0,25,25,42,0,0,0,0,0,0,0,0
0,0,0,0,0,0,0,0,3,25,25,0,0,0,0,33,3,0,0,0,0,0,0,0,0
0,0,0,0,0,0,0,0,42,25,25,25,0,0,0,0,42,0,0,0,0,0,0,0,0
0,0,0,0,0,0,0,0,0,3,25,25,25,0,0,3,0,0,0,0,0,0,0,0,0
0,0,0,0,0,0,0,0,0,0,42,3,42,3,42,0,0,0,0,0,0,0,0,0,0
0,0,0,0,0,0,0,0,0,39,0,0,0,0,0,0,0,39,39,0,0,0,0,0,0
0,0,0,0,0,0,0,41,41,0,0,0,0,0,0,41,41,0,0,0,0,0,0,0,0
0,0,39,41,41,41,41,0,0,0,0,0,39,41,41,0,0,0,0,0,0,0,0,0,0
:endlayer
layer: 14
0,0,0,0,0,0,0,0,0,0,0,0,0,0,0,0,0,0,0,0,0,0,0,0,0
0,0,0,0,0,0,0,0,0,0,0,0,0,0,0,0,0,0,0,0,0,0,0,0,0
0,0,0,0,0,0,0,0,0,0,0,0,0,0,0,0,0,0,0,0,0,0,0,0,0
0,0,0,0,0,0,0,0,0,0,42,3,43,3,42,0,0,0,0,0,0,0,0,0,0
0,0,0,0,0,0,0,0,0,3,0,0,0,0,0,3,0,0,0,0,0,0,0,0,0
0,0,0,0,0,0,0,0,42,0,0,0,0,0,0,0,42,0,0,0,0,0,0,0,0
0,0,0,0,0,0,0,0,3,0,0,0,0,0,0,0,3,0,0,0,0,0,0,0,0
0,0,0,0,0,0,0,0,43,0,0,0,19,0,0,0,43,0,0,0,0,0,0,0,0
0,0,0,0,0,0,0,0,3,0,0,0,0,0,0,0,3,0,0,0,0,0,0,0,0
0,0,0,0,0,0,0,0,42,0,0,0,0,0,0,0,42,0,0,0,0,0,0,0,0
0,0,0,0,0,0,0,0,0,3,0,0,0,0,0,3,0,0,0,0,0,0,0,0,0
0,0,0,0,0,0,0,0,0,0,42,3,43,3,42,0,0,0,0,0,0,0,0,0,0
0,0,0,0,0,0,0,0,0,0,0,0,0,0,0,0,39,0,0,0,0,0,0,0,0
0,0,0,0,0,0,0,0,41,41,39,0,0,0,41,41,0,0,0,0,0,0,0,0,0
0,0,0,39,41,41,41,41,0,0,0,0,39,41,0,0,0,0,0,0,0,0,0,0,0
:endlayer
layer: 15
0,0,0,0,0,0,0,0,0,0,0,0,0,0,0,0,0,0,0,0,0,0,0,0,0
0,0,0,0,0,0,0,0,0,0,0,0,0,0,0,0,0,0,0,0,0,0,0,0,0
0,0,0,0,0,0,0,0,0,0,0,0,0,0,0,0,0,0,0,0,0,0,0,0,0
0,0,0,0,0,0,0,0,0,0,42,3,43,3,42,0,0,0,0,0,0,0,0,0,0
0,0,0,0,0,0,0,0,0,3,0,0,0,0,0,3,0,0,0,0,0,0,0,0,0
0,0,0,0,0,0,0,0,42,0,0,0,0,0,0,0,42,0,0,0,0,0,0,0,0
0,0,0,0,0,0,0,0,3,0,0,0,0,0,0,0,3,0,0,0,0,0,0,0,0
0,0,0,0,0,0,0,0,43,0,0,0,19,0,0,0,43,0,0,0,0,0,0,0,0
0,0,0,0,0,0,0,0,3,0,0,0,0,0,0,0,3,0,0,0,0,0,0,0,0
0,0,0,0,0,0,0,0,42,0,0,0,0,0,0,0,42,0,0,0,0,0,0,0,0
0,0,0,0,0,0,0,0,0,3,0,0,0,0,0,3,0,0,0,0,0,0,0,0,0
0,0,0,0,0,0,0,0,0,0,42,3,43,3,42,0,0,0,0,0,0,0,0,0,0
0,0,0,0,0,0,0,0,0,0,0,0,0,0,0,0,0,0,0,0,0,0,0,0,0
0,0,0,0,0,0,0,0,0,41,39,0,0,0,39,39,0,0,0,0,0,0,0,0,0
0,0,0,0,39,39,41,41,41,0,0,0,39,41,0,0,0,0,0,0,0,0,0,0,0
:endlayer
layer: 16
0,0,0,0,0,0,0,0,0,0,0,0,0,0,0,0,0,0,0,0,0,0,0,0,0
0,0,0,0,0,0,0,0,0,0,0,0,0,0,0,0,0,0,0,0,0,0,0,0,0
0,0,0,0,0,0,0,0,0,0,0,0,0,0,0,0,0,0,0,0,0,0,0,0,0
0,0,0,0,0,0,0,0,0,0,42,3,42,3,42,0,0,0,0,0,0,0,0,0,0
0,0,0,0,0,0,0,0,0,3,0,0,17,0,0,3,0,0,0,0,0,0,0,0,0
0,0,0,0,0,0,0,0,42,0,0,0,0,0,0,0,42,0,0,0,0,0,0,0,0
0,0,0,0,0,0,0,0,3,0,0,0,0,0,0,0,3,0,0,0,0,0,0,0,0
0,0,0,0,0,0,0,0,42,15,0,0,18,0,0,16,42,0,0,0,0,0,0,0,0
0,0,0,0,0,0,0,0,3,0,0,0,0,0,0,0,3,0,0,0,0,0,0,0,0
0,0,0,0,0,0,0,0,42,0,0,0,0,0,0,0,42,0,0,0,0,0,0,0,0
0,0,0,0,0,0,0,0,0,3,0,0,20,0,0,3,0,0,0,0,0,0,0,0,0
0,0,0,0,0,0,0,0,0,0,42,3,2,3,42,0,0,0,0,0,0,0,0,0,0
0,0,0,0,0,0,0,0,0,0,0,0,0,0,0,0,0,0,0,0,0,0,0,0,0
0,0,0,0,0,0,0,0,0,0,0,0,0,0,0,0,0,0,0,0,0,0,0,0,0
0,0,0,0,0,0,39,39,41,41,41,0,39,0,0,0,0,0,0,0,0,0,0,0,0
:endlayer
layer: 17
0,0,0,0,0,0,0,0,0,0,0,0,0,0,0,0,0,0,0,0,0,0,0,0,0
0,0,0,0,0,0,0,0,0,0,0,0,0,0,0,0,0,0,0,0,0,0,0,0,0
0,0,0,0,0,0,0,0,0,0,0,0,0,0,0,0,0,0,0,0,0,0,0,0,0
0,0,0,0,0,0,0,0,0,0,42,3,42,3,42,0,0,0,0,0,0,0,0,0,0
0,0,0,0,0,0,0,0,0,3,0,0,0,0,0,3,0,0,0,0,0,0,0,0,0
0,0,0,0,0,0,0,0,42,0,0,0,0,0,0,0,42,0,0,0,0,0,0,0,0
0,0,0,0,0,0,0,0,3,0,0,0,0,0,0,0,3,0,0,0,0,0,0,0,0
0,0,0,0,0,0,0,0,42,0,0,0,19,0,0,0,42,0,0,0,0,0,0,0,0
0,0,0,0,0,0,0,0,3,0,0,0,18,0,0,0,3,0,0,0,0,0,0,0,0
0,0,0,0,0,0,0,0,42,0,0,0,44,0,0,0,42,0,0,0,0,0,0,0,0
0,0,0,0,0,0,0,0,0,3,0,0,44,0,0,3,0,0,0,0,0,0,0,0,0
0,0,0,0,0,0,0,0,0,0,42,2,44,2,42,0,0,0,0,0,0,0,0,0,0
0,0,0,0,0,0,0,0,0,0,0,0,44,0,0,0,0,0,0,0,0,0,0,0,0
0,0,0,0,0,0,0,0,0,0,0,0,44,0,0,0,0,0,0,0,0,0,0,0,0
0,0,0,0,0,0,0,0,39,39,39,39,44,39,39,39,39,0,0,0,0,0,0,0,0
:endlayer
layer: 18
0,0,0,0,0,0,0,0,0,0,0,0,0,0,0,0,0,0,0,0,0,0,0,0,0
0,0,0,0,0,0,0,0,0,0,0,0,0,0,0,0,0,0,0,0,0,0,0,0,0
0,0,0,0,0,0,0,0,0,0,0,0,0,0,0,0,0,0,0,0,0,0,0,0,0
0,0,0,0,0,0,0,0,0,0,42,3,42,3,42,0,0,0,0,0,0,0,0,0,0
0,0,0,0,0,0,0,0,0,3,0,0,0,0,0,3,0,0,0,0,0,0,0,0,0
0,0,0,0,0,0,0,0,42,0,0,0,0,0,0,0,42,0,0,0,0,0,0,0,0
0,0,0,0,0,0,0,0,3,0,0,0,0,0,0,0,3,0,0,0,0,0,0,0,0
0,0,0,0,0,0,0,0,42,0,0,0,0,0,0,0,42,0,0,0,0,0,0,0,0
0,0,0,0,0,0,0,0,3,0,0,0,0,0,0,0,3,0,0,0,0,0,0,0,0
0,0,0,0,0,0,0,0,42,0,0,0,0,0,0,0,42,0,0,0,0,0,0,0,0
0,0,0,0,0,0,0,0,0,3,0,0,0,0,0,3,0,0,0,0,0,0,0,0,0
0,0,0,0,0,0,0,0,0,0,42,3,2,3,42,0,0,0,0,0,0,0,0,0,0
0,0,0,0,0,0,0,0,0,0,0,0,0,0,0,0,0,0,0,0,0,0,0,0,0
0,0,0,0,0,0,0,0,0,0,0,0,0,0,0,0,0,0,0,0,0,0,0,0,0
0,0,0,0,0,0,0,0,0,0,0,0,39,0,41,41,41,39,39,0,0,0,0,0,0
:endlayer
layer: 19
0,0,0,0,0,0,0,0,0,0,0,0,0,0,0,0,0,0,0,0,0,0,0,0,0
0,0,0,0,0,0,0,0,0,0,0,0,0,0,0,0,0,0,0,0,0,0,0,0,0
0,0,0,0,0,0,0,0,0,0,0,0,0,0,0,0,0,0,0,0,0,0,0,0,0
0,0,0,0,0,0,0,0,0,19,42,3,42,3,42,19,0,0,0,0,0,0,0,0,0
0,0,0,0,0,0,0,0,19,3,15,0,0,0,16,3,19,0,0,0,0,0,0,0,0
0,0,0,0,0,0,0,0,42,17,0,0,0,0,0,17,42,0,0,0,0,0,0,0,0
0,0,0,0,0,0,0,0,3,0,0,0,0,0,0,0,3,0,0,0,0,0,0,0,0
0,0,0,0,0,0,0,0,42,0,0,0,0,0,0,0,42,0,0,0,0,0,0,0,0
0,0,0,0,0,0,0,0,3,0,0,0,0,0,0,0,3,0,0,0,0,0,0,0,0
0,0,0,0,0,0,0,0,42,20,0,0,0,0,0,20,42,0,0,0,0,0,0,0,0
0,0,0,0,0,0,0,0,19,3,15,0,0,0,16,3,19,0,0,0,0,0,0,0,0
0,0,0,0,0,0,0,0,0,19,42,3,42,3,42,19,0,0,0,0,0,0,0,0,0
0,0,0,0,0,0,0,0,0,0,0,0,0,0,0,0,0,0,0,0,0,0,0,0,0
0,0,0,0,0,0,0,0,0,39,39,0,0,0,39,41,0,0,0,0,0,0,0,0,0
0,0,0,0,0,0,0,0,0,0,0,41,39,0,0,0,41,41,41,39,39,0,0,0,0
:endlayer
layer: 20
0,0,0,0,0,0,0,0,0,0,0,0,0,0,0,0,0,0,0,0,0,0,0,0,0
0,0,0,0,0,0,0,0,0,0,0,0,0,0,0,0,0,0,0,0,0,0,0,0,0
0,0,0,0,0,0,0,0,0,0,35,35,35,35,35,0,0,0,0,0,0,0,0,0,0
0,0,0,0,0,0,0,0,0,36,45,45,45,45,45,35,0,0,0,0,0,0,0,0,0
0,0,0,0,0,0,0,0,36,45,2,2,2,2,2,45,37,0,0,0,0,0,0,0,0
0,0,0,0,0,0,0,36,45,2,0,0,0,0,0,2,45,37,0,0,0,0,0,0,0
0,0,0,0,0,0,0,36,45,2,0,0,0,0,0,2,45,37,0,0,0,0,0,0,0
0,0,0,0,0,0,0,36,45,2,0,0,0,0,0,2,45,37,0,0,0,0,0,0,0
0,0,0,0,0,0,0,36,45,2,0,0,0,0,0,2,45,37,0,0,0,0,0,0,0
0,0,0,0,0,0,0,36,45,2,0,0,0,0,0,2,45,37,0,0,0,0,0,0,0
0,0,0,0,0,0,0,0,36,45,2,2,2,2,2,45,37,0,0,0,0,0,0,0,0
0,0,0,0,0,0,0,0,0,38,45,45,45,45,45,38,0,0,0,0,0,0,0,0,0
0,0,0,0,0,0,0,0,39,0,38,38,38,38,38,0,0,0,0,0,0,0,0,0,0
0,0,0,0,0,0,0,0,0,41,41,0,0,0,39,41,41,0,0,0,0,0,0,0,0
0,0,0,0,0,0,0,0,0,0,0,41,39,0,0,0,0,41,41,41,41,39,0,0,0
:endlayer
layer: 21
0,0,0,0,0,0,0,0,0,0,0,0,0,0,0,0,0,0,0,0,0,0,0,0,0
0,0,0,0,0,0,0,0,0,0,0,0,0,0,0,0,0,0,0,0,0,0,0,0,0
0,0,0,0,0,0,0,0,0,0,0,0,0,0,0,0,0,0,0,0,0,0,0,0,0
0,0,0,0,0,0,0,0,0,0,46,46,46,46,46,0,0,0,0,0,0,0,0,0,0
0,0,0,0,0,0,0,0,0,35,45,45,45,45,45,35,0,0,0,0,0,0,0,0,0
0,0,0,0,0,0,0,0,46,45,2,2,2,2,2,45,46,0,0,0,0,0,0,0,0
0,0,0,0,0,0,0,0,46,45,2,0,0,0,2,45,46,0,0,0,0,0,0,0,0
0,0,0,0,0,0,0,0,46,45,2,0,0,0,2,45,46,0,0,0,0,0,0,0,0
0,0,0,0,0,0,0,0,46,45,2,0,0,0,2,45,46,0,0,0,0,0,0,0,0
0,0,0,0,0,0,0,0,46,45,2,2,2,2,2,45,46,0,0,0,0,0,0,0,0
0,0,0,0,0,0,0,0,0,38,45,45,45,45,45,38,0,0,0,0,0,0,0,0,0
0,0,0,0,0,0,0,0,0,0,46,46,46,46,46,0,0,0,0,0,0,0,0,0,0
0,0,0,0,0,0,39,39,0,0,0,0,0,0,0,39,0,0,0,0,0,0,0,0,0
0,0,0,0,0,0,0,0,41,41,0,0,0,0,0,0,41,41,0,0,0,0,0,0,0
0,0,0,0,0,0,0,0,0,0,41,41,39,0,0,0,0,0,41,41,41,41,39,0,0
:endlayer
layer: 22
0,0,0,0,0,0,0,0,0,0,0,0,0,0,0,0,0,0,0,0,0,0,0,0,0
0,0,0,0,0,0,0,0,0,0,0,0,0,0,0,0,0,0,0,0,0,0,0,0,0
0,0,0,0,0,0,0,0,0,0,0,0,0,0,0,0,0,0,0,0,0,0,0,0,0
0,0,0,0,0,0,0,0,0,0,0,0,0,0,0,0,0,0,0,0,0,0,0,0,0
0,0,0,0,0,0,0,0,0,0,35,35,35,35,35,0,0,0,0,0,0,0,0,0,0
0,0,0,0,0,0,0,0,0,36,45,45,45,45,45,37,0,0,0,0,0,0,0,0,0
0,0,0,0,0,0,0,0,0,36,45,0,0,0,45,37,0,0,0,0,0,0,0,0,0
0,0,0,0,0,0,0,0,0,36,45,0,0,0,45,37,0,0,0,0,0,0,0,0,0
0,0,0,0,0,0,0,0,0,36,45,0,0,0,45,37,0,0,0,0,0,0,0,0,0
0,0,0,0,0,0,0,0,0,36,45,45,45,45,45,37,0,0,0,0,0,0,0,0,0
0,0,0,0,0,0,0,0,0,0,38,38,38,38,38,0,0,0,0,0,0,0,0,0,0
0,0,0,0,0,0,0,0,0,0,0,0,0,0,0,0,0,0,0,0,0,0,0,0,0
0,0,0,0,0,39,0,0,0,0,0,0,0,0,0,0,39,0,0,0,0,0,0,0,0
0,0,0,0,0,0,41,41,41,0,0,0,0,0,0,0,0,41,41,0,0,0,0,0,0
0,0,0,0,0,0,0,0,0,41,41,39,0,0,0,0,0,0,0,41,41,41,41,39,0
:endlayer
layer: 23
0,0,0,0,0,0,0,0,0,0,0,0,0,0,0,0,0,0,0,0,0,0,0,0,0
0,0,0,0,0,0,0,0,0,0,0,0,0,0,0,0,0,0,0,0,0,0,0,0,0
0,0,0,0,0,0,0,0,0,0,0,0,0,0,0,0,0,0,0,0,0,0,0,0,0
0,0,0,0,0,0,0,0,0,0,0,0,0,0,0,0,0,0,0,0,0,0,0,0,0
0,0,0,0,0,0,0,0,0,0,0,0,0,0,0,0,0,0,0,0,0,0,0,0,0
0,0,0,0,0,0,0,0,0,0,46,35,35,35,0,0,0,0,0,0,0,0,0,0,0
0,0,0,0,0,0,0,0,0,0,36,45,45,45,37,0,0,0,0,0,0,0,0,0,0
0,0,0,0,0,0,0,0,0,0,36,45,0,45,37,0,0,0,0,0,0,0,0,0,0
0,0,0,0,0,0,0,0,0,0,36,45,45,45,37,0,0,0,0,0,0,0,0,0,0
0,0,0,0,0,0,0,0,0,0,0,38,38,38,46,0,0,0,0,0,0,0,0,0,0
0,0,0,0,0,0,0,0,0,0,0,0,0,0,0,0,0,0,0,0,0,0,0,0,0
0,0,0,0,0,0,0,0,0,0,0,0,0,0,0,0,0,0,0,0,0,0,0,0,0
0,0,0,0,39,0,0,0,0,0,0,0,0,0,0,0,39,0,0,0,0,0,0,0,0
0,0,0,0,0,41,41,41,0,0,0,0,0,0,0,0,0,41,41,41,0,0,0,0,0
0,0,0,0,0,0,0,0,41,41,41,39,0,0,0,0,0,0,0,0,41,41,41,41,39
:endlayer
layer: 24
0,0,0,0,0,0,0,0,0,0,0,0,0,0,0,0,0,0,0,0,0,0,0,0,0
0,0,0,0,0,0,0,0,0,0,0,0,0,0,0,0,0,0,0,0,0,0,0,0,0
0,0,0,0,0,0,0,0,0,0,0,0,0,0,0,0,0,0,0,0,0,0,0,0,0
0,0,0,0,0,0,0,0,0,0,0,0,0,0,0,0,0,0,0,0,0,0,0,0,0
0,0,0,0,0,0,0,0,0,0,0,0,0,0,0,0,0,0,0,0,0,0,0,0,0
0,0,0,0,0,0,0,0,0,0,0,0,0,0,0,0,0,0,0,0,0,0,0,0,0
0,0,0,0,0,0,0,0,0,0,0,35,35,37,0,0,0,0,0,0,0,0,0,0,0
0,0,0,0,0,0,0,0,0,0,0,36,2,37,0,0,0,0,0,0,0,0,0,0,0
0,0,0,0,0,0,0,0,0,0,0,36,38,37,0,0,0,0,0,0,0,0,0,0,0
0,0,0,0,0,0,0,0,0,0,0,0,0,0,0,0,0,0,0,0,0,0,0,0,0
0,0,0,0,0,0,0,0,0,0,0,0,0,0,0,0,0,0,0,0,0,0,0,0,0
0,0,0,0,0,0,0,0,0,0,0,0,0,0,0,0,0,0,0,0,0,0,0,0,0
0,0,0,39,0,0,0,0,0,0,0,0,0,0,0,0,0,39,0,0,0,0,0,0,0
0,0,0,0,41,41,41,0,0,0,0,0,0,0,0,0,0,0,41,41,41,0,0,0,0
0,0,0,0,0,0,0,41,41,41,39,0,0,0,0,0,0,0,0,0,0,41,41,41,39
:endlayer
layer: 25
0,0,0,0,0,0,0,0,0,0,0,0,0,0,0,0,0,0,0,0,0,0,0,0,0
0,0,0,0,0,0,0,0,0,0,0,0,0,0,0,0,0,0,0,0,0,0,0,0,0
0,0,0,0,0,0,0,0,0,0,0,0,0,0,0,0,0,0,0,0,0,0,0,0,0
0,0,0,0,0,0,0,0,0,0,0,0,0,0,0,0,0,0,0,0,0,0,0,0,0
0,0,0,0,0,0,0,0,0,0,0,0,0,0,0,0,0,0,0,0,0,0,0,0,0
0,0,0,0,0,0,0,0,0,0,0,0,0,0,0,0,0,0,0,0,0,0,0,0,0
0,0,0,0,0,0,0,0,0,0,0,0,0,0,0,0,0,0,0,0,0,0,0,0,0
0,0,0,0,0,0,0,0,0,0,0,0,46,0,0,0,0,0,0,0,0,0,0,0,0
0,0,0,0,0,0,0,0,0,0,0,0,0,0,0,0,0,0,0,0,0,0,0,0,0
0,0,0,0,0,0,0,0,0,0,0,0,0,0,0,0,0,0,0,0,0,0,0,0,0
0,0,0,0,0,0,0,0,0,0,0,0,0,0,0,0,0,0,0,0,0,0,0,0,0
0,0,0,0,0,0,0,0,0,0,0,0,0,0,0,0,0,0,0,0,0,0,0,0,0
0,0,39,0,0,0,0,0,0,0,0,0,0,0,0,0,0,0,39,0,0,0,0,0,0
0,0,0,41,41,41,0,0,0,0,0,0,0,0,0,0,0,0,0,41,41,0,0,0,0
0,0,0,0,0,0,41,41,41,41,39,0,0,0,0,0,0,0,0,0,0,41,41,41,39
:endlayer
layer: 26
0,0,0,0,0,0,0,0,0,0,0,0,0,0,0,0,0,0,0,0,0,0,0,0,0
0,0,0,0,0,0,0,0,0,0,0,0,0,0,0,0,0,0,0,0,0,0,0,0,0
0,0,0,0,0,0,0,0,0,0,0,0,0,0,0,0,0,0,0,0,0,0,0,0,0
0,0,0,0,0,0,0,0,0,0,0,0,0,0,0,0,0,0,0,0,0,0,0,0,0
0,0,0,0,0,0,0,0,0,0,0,0,0,0,0,0,0,0,0,0,0,0,0,0,0
0,0,0,0,0,0,0,0,0,0,0,0,0,0,0,0,0,0,0,0,0,0,0,0,0
0,0,0,0,0,0,0,0,0,0,0,0,0,0,0,0,0,0,0,0,0,0,0,0,0
0,0,0,0,0,0,0,0,0,0,0,0,0,0,0,0,0,0,0,0,0,0,0,0,0
0,0,0,0,0,0,0,0,0,0,0,0,0,0,0,0,0,0,0,0,0,0,0,0,0
0,0,0,0,0,0,0,0,0,0,0,0,0,0,0,0,0,0,0,0,0,0,0,0,0
0,0,0,0,0,0,0,0,0,0,0,0,0,0,0,0,0,0,0,0,0,0,0,0,0
0,0,0,0,0,0,0,0,0,0,0,0,0,0,0,0,0,0,0,0,0,0,0,0,0
0,0,0,0,0,0,0,0,0,0,0,0,0,0,0,0,0,0,0,39,0,0,0,0,0
0,39,41,41,41,0,0,0,0,0,0,0,0,0,0,0,0,0,0,0,41,41,0,0,0
0,0,0,0,0,41,41,41,41,39,0,0,0,0,0,0,0,0,0,0,0,0,41,41,39
:endlayer
layer: 27
0,0,0,0,0,0,0,0,0,0,0,0,0,0,0,0,0,0,0,0,0,0,0,0,0
0,0,0,0,0,0,0,0,0,0,0,0,0,0,0,0,0,0,0,0,0,0,0,0,0
0,0,0,0,0,0,0,0,0,0,0,0,0,0,0,0,0,0,0,0,0,0,0,0,0
0,0,0,0,0,0,0,0,0,0,0,0,0,0,0,0,0,0,0,0,0,0,0,0,0
0,0,0,0,0,0,0,0,0,0,0,0,0,0,0,0,0,0,0,0,0,0,0,0,0
0,0,0,0,0,0,0,0,0,0,0,0,0,0,0,0,0,0,0,0,0,0,0,0,0
0,0,0,0,0,0,0,0,0,0,0,0,0,0,0,0,0,0,0,0,0,0,0,0,0
0,0,0,0,0,0,0,0,0,0,0,0,0,0,0,0,0,0,0,0,0,0,0,0,0
0,0,0,0,0,0,0,0,0,0,0,0,0,0,0,0,0,0,0,0,0,0,0,0,0
0,0,0,0,0,0,0,0,0,0,0,0,0,0,0,0,0,0,0,0,0,0,0,0,0
0,0,0,0,0,0,0,0,0,0,0,0,0,0,0,0,0,0,0,0,0,0,0,0,0
0,0,0,0,0,0,0,0,0,0,0,0,0,0,0,0,0,0,0,0,0,0,0,0,0
0,0,0,0,0,0,0,0,0,0,0,0,0,0,0,0,0,0,0,0,39,0,0,0,0
0,39,41,0,0,0,0,0,0,0,0,0,0,0,0,0,0,0,0,0,0,41,41,0,0
0,0,0,41,41,41,41,41,39,0,0,0,0,0,0,0,0,0,0,0,0,0,0,41,39
:endlayer
layer: 28
0,0,0,0,0,0,0,0,0,0,0,0,0,0,0,0,0,0,0,0,0,0,0,0,0
0,0,0,0,0,0,0,0,0,0,0,0,0,0,0,0,0,0,0,0,0,0,0,0,0
0,0,0,0,0,0,0,0,0,0,0,0,0,0,0,0,0,0,0,0,0,0,0,0,0
0,0,0,0,0,0,0,0,0,0,0,0,0,0,0,0,0,0,0,0,0,0,0,0,0
0,0,0,0,0,0,0,0,0,0,0,0,0,0,0,0,0,0,0,0,0,0,0,0,0
0,0,0,0,0,0,0,0,0,0,0,0,0,0,0,0,0,0,0,0,0,0,0,0,0
0,0,0,0,0,0,0,0,0,0,0,0,0,0,0,0,0,0,0,0,0,0,0,0,0
0,0,0,0,0,0,0,0,0,0,0,0,0,0,0,0,0,0,0,0,0,0,0,0,0
0,0,0,0,0,0,0,0,0,0,0,0,0,0,0,0,0,0,0,0,0,0,0,0,0
0,0,0,0,0,0,0,0,0,0,0,0,0,0,0,0,0,0,0,0,0,0,0,0,0
0,0,0,0,0,0,0,0,0,0,0,0,0,0,0,0,0,0,0,0,0,0,0,0,0
0,0,0,0,0,0,0,0,0,0,0,0,0,0,0,0,0,0,0,0,0,0,0,0,0
0,0,0,0,0,0,0,0,0,0,0,0,0,0,0,0,0,0,0,0,0,0,0,0,0
0,0,0,0,0,0,0,0,0,0,0,0,0,0,0,0,0,0,0,0,0,39,39,0,0
0,39,41,41,41,41,41,39,0,0,0,0,0,0,0,0,0,0,0,0,0,0,0,39,0
:endlayer

#### RULES ####
rule:
plugin=vanillaBlocks
number=1
data:
tag:
TAG=10={
TAG=8=blockName{stone_slab}
TAG=3=meta{3}
TAG=3=buildPass{0}
}
:endtag
:enddata
:endrule

rule:
plugin=vanillaBlocks
number=2
data:
tag:
TAG=10={
TAG=8=blockName{cobblestone}
TAG=3=meta{0}
TAG=3=buildPass{0}
}
:endtag
:enddata
:endrule

rule:
plugin=vanillaBlocks
number=3
data:
tag:
TAG=10={
TAG=8=blockName{log}
TAG=3=meta{0}
TAG=3=buildPass{0}
}
:endtag
:enddata
:endrule

rule:
plugin=vanillaBlocks
number=4
data:
tag:
TAG=10={
TAG=8=blockName{stone_stairs}
TAG=3=meta{2}
TAG=3=buildPass{0}
}
:endtag
:enddata
:endrule

rule:
plugin=vanillaBlocks
number=5
data:
tag:
TAG=10={
TAG=8=blockName{stained_hardened_clay}
TAG=3=meta{12}
TAG=3=buildPass{0}
}
:endtag
:enddata
:endrule

rule:
plugin=vanillaBlocks
number=6
data:
tag:
TAG=10={
TAG=8=blockName{hardened_clay}
TAG=3=meta{0}
TAG=3=buildPass{0}
}
:endtag
:enddata
:endrule

rule:
plugin=vanillaBlocks
number=7
data:
tag:
TAG=10={
TAG=8=blockName{stone_stairs}
TAG=3=meta{0}
TAG=3=buildPass{0}
}
:endtag
:enddata
:endrule

rule:
plugin=vanillaBlocks
number=8
data:
tag:
TAG=10={
TAG=8=blockName{stone_stairs}
TAG=3=meta{1}
TAG=3=buildPass{0}
}
:endtag
:enddata
:endrule

rule:
plugin=vanillaBlocks
number=9
data:
tag:
TAG=10={
TAG=8=blockName{stone}
TAG=3=meta{0}
TAG=3=buildPass{0}
}
:endtag
:enddata
:endrule

rule:
plugin=vanillaBlocks
number=10
data:
tag:
TAG=10={
TAG=8=blockName{stained_hardened_clay}
TAG=3=meta{4}
TAG=3=buildPass{0}
}
:endtag
:enddata
:endrule

rule:
plugin=vanillaBlocks
number=11
data:
tag:
TAG=10={
TAG=8=blockName{ladder}
TAG=3=meta{5}
TAG=3=buildPass{1}
}
:endtag
:enddata
:endrule

rule:
plugin=vanillaBlocks
number=12
data:
tag:
TAG=10={
TAG=8=blockName{stone_stairs}
TAG=3=meta{3}
TAG=3=buildPass{0}
}
:endtag
:enddata
:endrule

rule:
plugin=vanillaBlocks
number=13
data:
tag:
TAG=10={
TAG=8=blockName{stonebrick}
TAG=3=meta{2}
TAG=3=buildPass{0}
}
:endtag
:enddata
:endrule

rule:
plugin=vanillaBlocks
number=14
data:
tag:
TAG=10={
TAG=8=blockName{stonebrick}
TAG=3=meta{0}
TAG=3=buildPass{0}
}
:endtag
:enddata
:endrule

rule:
plugin=vanillaBlocks
number=15
data:
tag:
TAG=10={
TAG=8=blockName{torch}
TAG=3=meta{1}
TAG=3=buildPass{1}
}
:endtag
:enddata
:endrule

rule:
plugin=vanillaBlocks
number=16
data:
tag:
TAG=10={
TAG=8=blockName{torch}
TAG=3=meta{2}
TAG=3=buildPass{1}
}
:endtag
:enddata
:endrule

rule:
plugin=vanillaBlocks
number=17
data:
tag:
TAG=10={
TAG=8=blockName{torch}
TAG=3=meta{3}
TAG=3=buildPass{1}
}
:endtag
:enddata
:endrule

rule:
plugin=vanillaBlocks
number=18
data:
tag:
TAG=10={
TAG=8=blockName{stonebrick}
TAG=3=meta{3}
TAG=3=buildPass{0}
}
:endtag
:enddata
:endrule

rule:
plugin=vanillaBlocks
number=19
data:
tag:
TAG=10={
TAG=8=blockName{fence}
TAG=3=meta{0}
TAG=3=buildPass{0}
}
:endtag
:enddata
:endrule

rule:
plugin=vanillaBlocks
number=20
data:
tag:
TAG=10={
TAG=8=blockName{torch}
TAG=3=meta{4}
TAG=3=buildPass{1}
}
:endtag
:enddata
:endrule

rule:
plugin=vanillaBlocks
number=21
data:
tag:
TAG=10={
TAG=8=blockName{stone_brick_stairs}
TAG=3=meta{6}
TAG=3=buildPass{0}
}
:endtag
:enddata
:endrule

rule:
plugin=vanillaBlocks
number=22
data:
tag:
TAG=10={
TAG=8=blockName{stone_brick_stairs}
TAG=3=meta{3}
TAG=3=buildPass{0}
}
:endtag
:enddata
:endrule

rule:
plugin=vanillaBlocks
number=23
data:
tag:
TAG=10={
TAG=8=blockName{oak_stairs}
TAG=3=meta{2}
TAG=3=buildPass{0}
}
:endtag
:enddata
:endrule

rule:
plugin=vanillaBlocks
number=24
data:
tag:
TAG=10={
TAG=8=blockName{oak_stairs}
TAG=3=meta{0}
TAG=3=buildPass{0}
}
:endtag
:enddata
:endrule

rule:
plugin=vanillaBlocks
number=25
data:
tag:
TAG=10={
TAG=8=blockName{wooden_slab}
TAG=3=meta{8}
TAG=3=buildPass{0}
}
:endtag
:enddata
:endrule

rule:
plugin=vanillaBlocks
number=26
data:
tag:
TAG=10={
TAG=8=blockName{oak_stairs}
TAG=3=meta{1}
TAG=3=buildPass{0}
}
:endtag
:enddata
:endrule

rule:
plugin=vanillaBlocks
number=27
data:
tag:
TAG=10={
TAG=8=blockName{oak_stairs}
TAG=3=meta{3}
TAG=3=buildPass{0}
}
:endtag
:enddata
:endrule

rule:
plugin=vanillaBlocks
number=28
data:
tag:
TAG=10={
TAG=8=blockName{hay_block}
TAG=3=meta{8}
TAG=3=buildPass{0}
}
:endtag
:enddata
:endrule

rule:
plugin=vanillaBlocks
number=29
data:
tag:
TAG=10={
TAG=8=blockName{rail}
TAG=3=meta{2}
TAG=3=buildPass{1}
}
:endtag
:enddata
:endrule

rule:
plugin=vanillaBlocks
number=30
data:
tag:
TAG=10={
TAG=8=blockName{rail}
TAG=3=meta{3}
TAG=3=buildPass{1}
}
:endtag
:enddata
:endrule

rule:
plugin=vanillaBlocks
number=31
data:
tag:
TAG=10={
TAG=8=blockName{hay_block}
TAG=3=meta{4}
TAG=3=buildPass{0}
}
:endtag
:enddata
:endrule

rule:
plugin=vanillaBlocks
number=32
data:
tag:
TAG=10={
TAG=8=blockName{torch}
TAG=3=meta{5}
TAG=3=buildPass{1}
}
:endtag
:enddata
:endrule

rule:
plugin=vanillaBlocks
number=33
data:
tag:
TAG=10={
TAG=8=blockName{ladder}
TAG=3=meta{4}
TAG=3=buildPass{1}
}
:endtag
:enddata
:endrule

rule:
plugin=vanillaBlocks
number=34
data:
tag:
TAG=10={
TAG=8=blockName{hay_block}
TAG=3=meta{0}
TAG=3=buildPass{0}
}
:endtag
:enddata
:endrule

rule:
plugin=vanillaBlocks
number=35
data:
tag:
TAG=10={
TAG=8=blockName{spruce_stairs}
TAG=3=meta{2}
TAG=3=buildPass{0}
}
:endtag
:enddata
:endrule

rule:
plugin=vanillaBlocks
number=36
data:
tag:
TAG=10={
TAG=8=blockName{spruce_stairs}
TAG=3=meta{0}
TAG=3=buildPass{0}
}
:endtag
:enddata
:endrule

rule:
plugin=vanillaBlocks
number=37
data:
tag:
TAG=10={
TAG=8=blockName{spruce_stairs}
TAG=3=meta{1}
TAG=3=buildPass{0}
}
:endtag
:enddata
:endrule

rule:
plugin=vanillaBlocks
number=38
data:
tag:
TAG=10={
TAG=8=blockName{spruce_stairs}
TAG=3=meta{3}
TAG=3=buildPass{0}
}
:endtag
:enddata
:endrule

rule:
plugin=vanillaBlocks
number=39
data:
tag:
TAG=10={
TAG=8=blockName{wool}
TAG=3=meta{14}
TAG=3=buildPass{0}
}
:endtag
:enddata
:endrule

rule:
plugin=vanillaBlocks
number=40
data:
tag:
TAG=10={
TAG=8=blockName{rail}
TAG=3=meta{1}
TAG=3=buildPass{1}
}
:endtag
:enddata
:endrule

rule:
plugin=vanillaBlocks
number=41
data:
tag:
TAG=10={
TAG=8=blockName{wool}
TAG=3=meta{0}
TAG=3=buildPass{0}
}
:endtag
:enddata
:endrule

rule:
plugin=vanillaBlocks
number=42
data:
tag:
TAG=10={
TAG=8=blockName{planks}
TAG=3=meta{0}
TAG=3=buildPass{0}
}
:endtag
:enddata
:endrule

rule:
plugin=vanillaBlocks
number=43
data:
tag:
TAG=10={
TAG=8=blockName{glass_pane}
TAG=3=meta{0}
TAG=3=buildPass{0}
}
:endtag
:enddata
:endrule

rule:
plugin=vanillaBlocks
number=44
data:
tag:
TAG=10={
TAG=8=blockName{log}
TAG=3=meta{8}
TAG=3=buildPass{0}
}
:endtag
:enddata
:endrule

rule:
plugin=vanillaBlocks
number=45
data:
tag:
TAG=10={
TAG=8=blockName{planks}
TAG=3=meta{1}
TAG=3=buildPass{0}
}
:endtag
:enddata
:endrule

rule:
plugin=vanillaBlocks
number=46
data:
tag:
TAG=10={
TAG=8=blockName{wooden_slab}
TAG=3=meta{1}
TAG=3=buildPass{0}
}
:endtag
:enddata
:endrule

#### ENTITIES ####
